{
 "cells": [
  {
   "cell_type": "code",
   "execution_count": 1,
   "metadata": {
    "collapsed": false
   },
   "outputs": [
    {
     "name": "stderr",
     "output_type": "stream",
     "text": [
      "ERROR:root:An unknown error occurred! Returning tweets gathered so far.\n",
      "Traceback (most recent call last):\n",
      "  File \"C:\\ProgramData\\Anaconda2\\lib\\site-packages\\twitterscraper\\query.py\", line 93, in query_tweets_once\n",
      "    pos is None\n",
      "  File \"C:\\ProgramData\\Anaconda2\\lib\\site-packages\\twitterscraper\\query.py\", line 53, in query_single_page\n",
      "    except requests.exception.ConnectionError as e:\n",
      "AttributeError: 'module' object has no attribute 'exception'\n",
      "ERROR:root:An unknown error occurred! Returning tweets gathered so far.\n",
      "Traceback (most recent call last):\n",
      "  File \"C:\\ProgramData\\Anaconda2\\lib\\site-packages\\twitterscraper\\query.py\", line 93, in query_tweets_once\n",
      "    pos is None\n",
      "  File \"C:\\ProgramData\\Anaconda2\\lib\\site-packages\\twitterscraper\\query.py\", line 53, in query_single_page\n",
      "    except requests.exception.ConnectionError as e:\n",
      "AttributeError: 'module' object has no attribute 'exception'\n",
      "ERROR:root:An unknown error occurred! Returning tweets gathered so far.\n",
      "Traceback (most recent call last):\n",
      "  File \"C:\\ProgramData\\Anaconda2\\lib\\site-packages\\twitterscraper\\query.py\", line 93, in query_tweets_once\n",
      "    pos is None\n",
      "  File \"C:\\ProgramData\\Anaconda2\\lib\\site-packages\\twitterscraper\\query.py\", line 53, in query_single_page\n",
      "    except requests.exception.ConnectionError as e:\n",
      "AttributeError: 'module' object has no attribute 'exception'\n",
      "ERROR:root:An unknown error occurred! Returning tweets gathered so far.\n",
      "Traceback (most recent call last):\n",
      "  File \"C:\\ProgramData\\Anaconda2\\lib\\site-packages\\twitterscraper\\query.py\", line 93, in query_tweets_once\n",
      "    pos is None\n",
      "  File \"C:\\ProgramData\\Anaconda2\\lib\\site-packages\\twitterscraper\\query.py\", line 53, in query_single_page\n",
      "    except requests.exception.ConnectionError as e:\n",
      "AttributeError: 'module' object has no attribute 'exception'\n",
      "ERROR:root:An unknown error occurred! Returning tweets gathered so far.\n",
      "Traceback (most recent call last):\n",
      "  File \"C:\\ProgramData\\Anaconda2\\lib\\site-packages\\twitterscraper\\query.py\", line 93, in query_tweets_once\n",
      "    pos is None\n",
      "  File \"C:\\ProgramData\\Anaconda2\\lib\\site-packages\\twitterscraper\\query.py\", line 53, in query_single_page\n",
      "    except requests.exception.ConnectionError as e:\n",
      "AttributeError: 'module' object has no attribute 'exception'\n",
      "ERROR:root:An unknown error occurred! Returning tweets gathered so far.\n",
      "Traceback (most recent call last):\n",
      "  File \"C:\\ProgramData\\Anaconda2\\lib\\site-packages\\twitterscraper\\query.py\", line 93, in query_tweets_once\n",
      "    pos is None\n",
      "  File \"C:\\ProgramData\\Anaconda2\\lib\\site-packages\\twitterscraper\\query.py\", line 53, in query_single_page\n",
      "    except requests.exception.ConnectionError as e:\n",
      "AttributeError: 'module' object has no attribute 'exception'\n",
      "ERROR:root:An unknown error occurred! Returning tweets gathered so far.\n",
      "Traceback (most recent call last):\n",
      "  File \"C:\\ProgramData\\Anaconda2\\lib\\site-packages\\twitterscraper\\query.py\", line 93, in query_tweets_once\n",
      "    pos is None\n",
      "  File \"C:\\ProgramData\\Anaconda2\\lib\\site-packages\\twitterscraper\\query.py\", line 53, in query_single_page\n",
      "    except requests.exception.ConnectionError as e:\n",
      "AttributeError: 'module' object has no attribute 'exception'\n",
      "ERROR:root:An unknown error occurred! Returning tweets gathered so far.\n",
      "Traceback (most recent call last):\n",
      "  File \"C:\\ProgramData\\Anaconda2\\lib\\site-packages\\twitterscraper\\query.py\", line 93, in query_tweets_once\n",
      "    pos is None\n",
      "  File \"C:\\ProgramData\\Anaconda2\\lib\\site-packages\\twitterscraper\\query.py\", line 53, in query_single_page\n",
      "    except requests.exception.ConnectionError as e:\n",
      "AttributeError: 'module' object has no attribute 'exception'\n",
      "ERROR:root:An unknown error occurred! Returning tweets gathered so far.\n",
      "Traceback (most recent call last):\n",
      "  File \"C:\\ProgramData\\Anaconda2\\lib\\site-packages\\twitterscraper\\query.py\", line 93, in query_tweets_once\n",
      "    pos is None\n",
      "  File \"C:\\ProgramData\\Anaconda2\\lib\\site-packages\\twitterscraper\\query.py\", line 53, in query_single_page\n",
      "    except requests.exception.ConnectionError as e:\n",
      "AttributeError: 'module' object has no attribute 'exception'\n",
      "ERROR:root:An unknown error occurred! Returning tweets gathered so far.\n",
      "Traceback (most recent call last):\n",
      "  File \"C:\\ProgramData\\Anaconda2\\lib\\site-packages\\twitterscraper\\query.py\", line 93, in query_tweets_once\n",
      "    pos is None\n",
      "  File \"C:\\ProgramData\\Anaconda2\\lib\\site-packages\\twitterscraper\\query.py\", line 53, in query_single_page\n",
      "    except requests.exception.ConnectionError as e:\n",
      "AttributeError: 'module' object has no attribute 'exception'\n",
      "ERROR:root:An unknown error occurred! Returning tweets gathered so far.\n",
      "Traceback (most recent call last):\n",
      "  File \"C:\\ProgramData\\Anaconda2\\lib\\site-packages\\twitterscraper\\query.py\", line 93, in query_tweets_once\n",
      "    pos is None\n",
      "  File \"C:\\ProgramData\\Anaconda2\\lib\\site-packages\\twitterscraper\\query.py\", line 53, in query_single_page\n",
      "    except requests.exception.ConnectionError as e:\n",
      "AttributeError: 'module' object has no attribute 'exception'\n",
      "ERROR:root:An unknown error occurred! Returning tweets gathered so far.\n",
      "Traceback (most recent call last):\n",
      "  File \"C:\\ProgramData\\Anaconda2\\lib\\site-packages\\twitterscraper\\query.py\", line 93, in query_tweets_once\n",
      "    pos is None\n",
      "  File \"C:\\ProgramData\\Anaconda2\\lib\\site-packages\\twitterscraper\\query.py\", line 53, in query_single_page\n",
      "    except requests.exception.ConnectionError as e:\n",
      "AttributeError: 'module' object has no attribute 'exception'\n",
      "ERROR:root:An unknown error occurred! Returning tweets gathered so far.\n",
      "Traceback (most recent call last):\n",
      "  File \"C:\\ProgramData\\Anaconda2\\lib\\site-packages\\twitterscraper\\query.py\", line 93, in query_tweets_once\n",
      "    pos is None\n",
      "  File \"C:\\ProgramData\\Anaconda2\\lib\\site-packages\\twitterscraper\\query.py\", line 53, in query_single_page\n",
      "    except requests.exception.ConnectionError as e:\n",
      "AttributeError: 'module' object has no attribute 'exception'\n",
      "ERROR:root:An unknown error occurred! Returning tweets gathered so far.\n",
      "Traceback (most recent call last):\n",
      "  File \"C:\\ProgramData\\Anaconda2\\lib\\site-packages\\twitterscraper\\query.py\", line 93, in query_tweets_once\n",
      "    pos is None\n",
      "  File \"C:\\ProgramData\\Anaconda2\\lib\\site-packages\\twitterscraper\\query.py\", line 53, in query_single_page\n",
      "    except requests.exception.ConnectionError as e:\n",
      "AttributeError: 'module' object has no attribute 'exception'\n",
      "ERROR:root:An unknown error occurred! Returning tweets gathered so far.\n",
      "Traceback (most recent call last):\n",
      "  File \"C:\\ProgramData\\Anaconda2\\lib\\site-packages\\twitterscraper\\query.py\", line 93, in query_tweets_once\n",
      "    pos is None\n",
      "  File \"C:\\ProgramData\\Anaconda2\\lib\\site-packages\\twitterscraper\\query.py\", line 53, in query_single_page\n",
      "    except requests.exception.ConnectionError as e:\n",
      "AttributeError: 'module' object has no attribute 'exception'\n",
      "ERROR:root:An unknown error occurred! Returning tweets gathered so far.\n",
      "Traceback (most recent call last):\n",
      "  File \"C:\\ProgramData\\Anaconda2\\lib\\site-packages\\twitterscraper\\query.py\", line 93, in query_tweets_once\n",
      "    pos is None\n",
      "  File \"C:\\ProgramData\\Anaconda2\\lib\\site-packages\\twitterscraper\\query.py\", line 53, in query_single_page\n",
      "    except requests.exception.ConnectionError as e:\n",
      "AttributeError: 'module' object has no attribute 'exception'\n",
      "ERROR:root:An unknown error occurred! Returning tweets gathered so far.\n",
      "Traceback (most recent call last):\n",
      "  File \"C:\\ProgramData\\Anaconda2\\lib\\site-packages\\twitterscraper\\query.py\", line 93, in query_tweets_once\n",
      "    pos is None\n",
      "  File \"C:\\ProgramData\\Anaconda2\\lib\\site-packages\\twitterscraper\\query.py\", line 53, in query_single_page\n",
      "    except requests.exception.ConnectionError as e:\n",
      "AttributeError: 'module' object has no attribute 'exception'\n",
      "ERROR:root:An unknown error occurred! Returning tweets gathered so far.\n",
      "Traceback (most recent call last):\n",
      "  File \"C:\\ProgramData\\Anaconda2\\lib\\site-packages\\twitterscraper\\query.py\", line 93, in query_tweets_once\n",
      "    pos is None\n",
      "  File \"C:\\ProgramData\\Anaconda2\\lib\\site-packages\\twitterscraper\\query.py\", line 53, in query_single_page\n",
      "    except requests.exception.ConnectionError as e:\n",
      "AttributeError: 'module' object has no attribute 'exception'\n",
      "ERROR:root:An unknown error occurred! Returning tweets gathered so far.\n",
      "Traceback (most recent call last):\n",
      "  File \"C:\\ProgramData\\Anaconda2\\lib\\site-packages\\twitterscraper\\query.py\", line 93, in query_tweets_once\n",
      "    pos is None\n",
      "  File \"C:\\ProgramData\\Anaconda2\\lib\\site-packages\\twitterscraper\\query.py\", line 53, in query_single_page\n",
      "    except requests.exception.ConnectionError as e:\n",
      "AttributeError: 'module' object has no attribute 'exception'\n",
      "ERROR:root:An unknown error occurred! Returning tweets gathered so far.\n",
      "Traceback (most recent call last):\n",
      "  File \"C:\\ProgramData\\Anaconda2\\lib\\site-packages\\twitterscraper\\query.py\", line 93, in query_tweets_once\n",
      "    pos is None\n",
      "  File \"C:\\ProgramData\\Anaconda2\\lib\\site-packages\\twitterscraper\\query.py\", line 53, in query_single_page\n",
      "    except requests.exception.ConnectionError as e:\n",
      "AttributeError: 'module' object has no attribute 'exception'\n",
      "ERROR:root:An unknown error occurred! Returning tweets gathered so far.\n",
      "Traceback (most recent call last):\n",
      "  File \"C:\\ProgramData\\Anaconda2\\lib\\site-packages\\twitterscraper\\query.py\", line 93, in query_tweets_once\n",
      "    pos is None\n",
      "  File \"C:\\ProgramData\\Anaconda2\\lib\\site-packages\\twitterscraper\\query.py\", line 53, in query_single_page\n",
      "    except requests.exception.ConnectionError as e:\n",
      "AttributeError: 'module' object has no attribute 'exception'\n",
      "ERROR:root:An unknown error occurred! Returning tweets gathered so far.\n",
      "Traceback (most recent call last):\n",
      "  File \"C:\\ProgramData\\Anaconda2\\lib\\site-packages\\twitterscraper\\query.py\", line 93, in query_tweets_once\n",
      "    pos is None\n",
      "  File \"C:\\ProgramData\\Anaconda2\\lib\\site-packages\\twitterscraper\\query.py\", line 53, in query_single_page\n",
      "    except requests.exception.ConnectionError as e:\n",
      "AttributeError: 'module' object has no attribute 'exception'\n",
      "ERROR:root:An unknown error occurred! Returning tweets gathered so far.\n",
      "Traceback (most recent call last):\n",
      "  File \"C:\\ProgramData\\Anaconda2\\lib\\site-packages\\twitterscraper\\query.py\", line 93, in query_tweets_once\n",
      "    pos is None\n",
      "  File \"C:\\ProgramData\\Anaconda2\\lib\\site-packages\\twitterscraper\\query.py\", line 53, in query_single_page\n",
      "    except requests.exception.ConnectionError as e:\n",
      "AttributeError: 'module' object has no attribute 'exception'\n",
      "ERROR:root:An unknown error occurred! Returning tweets gathered so far.\n",
      "Traceback (most recent call last):\n",
      "  File \"C:\\ProgramData\\Anaconda2\\lib\\site-packages\\twitterscraper\\query.py\", line 93, in query_tweets_once\n",
      "    pos is None\n",
      "  File \"C:\\ProgramData\\Anaconda2\\lib\\site-packages\\twitterscraper\\query.py\", line 53, in query_single_page\n",
      "    except requests.exception.ConnectionError as e:\n",
      "AttributeError: 'module' object has no attribute 'exception'\n",
      "ERROR:root:An unknown error occurred! Returning tweets gathered so far.\n",
      "Traceback (most recent call last):\n",
      "  File \"C:\\ProgramData\\Anaconda2\\lib\\site-packages\\twitterscraper\\query.py\", line 93, in query_tweets_once\n",
      "    pos is None\n",
      "  File \"C:\\ProgramData\\Anaconda2\\lib\\site-packages\\twitterscraper\\query.py\", line 53, in query_single_page\n",
      "    except requests.exception.ConnectionError as e:\n",
      "AttributeError: 'module' object has no attribute 'exception'\n",
      "ERROR:root:An unknown error occurred! Returning tweets gathered so far.\n",
      "Traceback (most recent call last):\n",
      "  File \"C:\\ProgramData\\Anaconda2\\lib\\site-packages\\twitterscraper\\query.py\", line 93, in query_tweets_once\n",
      "    pos is None\n",
      "  File \"C:\\ProgramData\\Anaconda2\\lib\\site-packages\\twitterscraper\\query.py\", line 53, in query_single_page\n",
      "    except requests.exception.ConnectionError as e:\n",
      "AttributeError: 'module' object has no attribute 'exception'\n",
      "ERROR:root:An unknown error occurred! Returning tweets gathered so far.\n",
      "Traceback (most recent call last):\n",
      "  File \"C:\\ProgramData\\Anaconda2\\lib\\site-packages\\twitterscraper\\query.py\", line 93, in query_tweets_once\n",
      "    pos is None\n",
      "  File \"C:\\ProgramData\\Anaconda2\\lib\\site-packages\\twitterscraper\\query.py\", line 53, in query_single_page\n",
      "    except requests.exception.ConnectionError as e:\n",
      "AttributeError: 'module' object has no attribute 'exception'\n",
      "ERROR:root:An unknown error occurred! Returning tweets gathered so far.\n",
      "Traceback (most recent call last):\n",
      "  File \"C:\\ProgramData\\Anaconda2\\lib\\site-packages\\twitterscraper\\query.py\", line 93, in query_tweets_once\n",
      "    pos is None\n",
      "  File \"C:\\ProgramData\\Anaconda2\\lib\\site-packages\\twitterscraper\\query.py\", line 53, in query_single_page\n",
      "    except requests.exception.ConnectionError as e:\n",
      "AttributeError: 'module' object has no attribute 'exception'\n",
      "ERROR:root:An unknown error occurred! Returning tweets gathered so far.\n",
      "Traceback (most recent call last):\n",
      "  File \"C:\\ProgramData\\Anaconda2\\lib\\site-packages\\twitterscraper\\query.py\", line 93, in query_tweets_once\n",
      "    pos is None\n",
      "  File \"C:\\ProgramData\\Anaconda2\\lib\\site-packages\\twitterscraper\\query.py\", line 53, in query_single_page\n",
      "    except requests.exception.ConnectionError as e:\n",
      "AttributeError: 'module' object has no attribute 'exception'\n",
      "ERROR:root:An unknown error occurred! Returning tweets gathered so far.\n",
      "Traceback (most recent call last):\n",
      "  File \"C:\\ProgramData\\Anaconda2\\lib\\site-packages\\twitterscraper\\query.py\", line 93, in query_tweets_once\n",
      "    pos is None\n",
      "  File \"C:\\ProgramData\\Anaconda2\\lib\\site-packages\\twitterscraper\\query.py\", line 53, in query_single_page\n",
      "    except requests.exception.ConnectionError as e:\n",
      "AttributeError: 'module' object has no attribute 'exception'\n",
      "ERROR:root:An unknown error occurred! Returning tweets gathered so far.\n",
      "Traceback (most recent call last):\n",
      "  File \"C:\\ProgramData\\Anaconda2\\lib\\site-packages\\twitterscraper\\query.py\", line 93, in query_tweets_once\n",
      "    pos is None\n",
      "  File \"C:\\ProgramData\\Anaconda2\\lib\\site-packages\\twitterscraper\\query.py\", line 53, in query_single_page\n",
      "    except requests.exception.ConnectionError as e:\n",
      "AttributeError: 'module' object has no attribute 'exception'\n",
      "ERROR:root:An unknown error occurred! Returning tweets gathered so far.\n",
      "Traceback (most recent call last):\n",
      "  File \"C:\\ProgramData\\Anaconda2\\lib\\site-packages\\twitterscraper\\query.py\", line 93, in query_tweets_once\n",
      "    pos is None\n",
      "  File \"C:\\ProgramData\\Anaconda2\\lib\\site-packages\\twitterscraper\\query.py\", line 53, in query_single_page\n",
      "    except requests.exception.ConnectionError as e:\n",
      "AttributeError: 'module' object has no attribute 'exception'\n",
      "ERROR:root:An unknown error occurred! Returning tweets gathered so far.\n",
      "Traceback (most recent call last):\n",
      "  File \"C:\\ProgramData\\Anaconda2\\lib\\site-packages\\twitterscraper\\query.py\", line 93, in query_tweets_once\n",
      "    pos is None\n",
      "  File \"C:\\ProgramData\\Anaconda2\\lib\\site-packages\\twitterscraper\\query.py\", line 53, in query_single_page\n",
      "    except requests.exception.ConnectionError as e:\n",
      "AttributeError: 'module' object has no attribute 'exception'\n",
      "ERROR:root:An unknown error occurred! Returning tweets gathered so far.\n",
      "Traceback (most recent call last):\n",
      "  File \"C:\\ProgramData\\Anaconda2\\lib\\site-packages\\twitterscraper\\query.py\", line 93, in query_tweets_once\n",
      "    pos is None\n",
      "  File \"C:\\ProgramData\\Anaconda2\\lib\\site-packages\\twitterscraper\\query.py\", line 53, in query_single_page\n",
      "    except requests.exception.ConnectionError as e:\n",
      "AttributeError: 'module' object has no attribute 'exception'\n",
      "ERROR:root:An unknown error occurred! Returning tweets gathered so far.\n",
      "Traceback (most recent call last):\n",
      "  File \"C:\\ProgramData\\Anaconda2\\lib\\site-packages\\twitterscraper\\query.py\", line 93, in query_tweets_once\n",
      "    pos is None\n",
      "  File \"C:\\ProgramData\\Anaconda2\\lib\\site-packages\\twitterscraper\\query.py\", line 53, in query_single_page\n",
      "    except requests.exception.ConnectionError as e:\n",
      "AttributeError: 'module' object has no attribute 'exception'\n",
      "ERROR:root:An unknown error occurred! Returning tweets gathered so far.\n",
      "Traceback (most recent call last):\n",
      "  File \"C:\\ProgramData\\Anaconda2\\lib\\site-packages\\twitterscraper\\query.py\", line 93, in query_tweets_once\n",
      "    pos is None\n",
      "  File \"C:\\ProgramData\\Anaconda2\\lib\\site-packages\\twitterscraper\\query.py\", line 53, in query_single_page\n",
      "    except requests.exception.ConnectionError as e:\n",
      "AttributeError: 'module' object has no attribute 'exception'\n",
      "ERROR:root:An unknown error occurred! Returning tweets gathered so far.\n",
      "Traceback (most recent call last):\n",
      "  File \"C:\\ProgramData\\Anaconda2\\lib\\site-packages\\twitterscraper\\query.py\", line 93, in query_tweets_once\n",
      "    pos is None\n",
      "  File \"C:\\ProgramData\\Anaconda2\\lib\\site-packages\\twitterscraper\\query.py\", line 53, in query_single_page\n",
      "    except requests.exception.ConnectionError as e:\n",
      "AttributeError: 'module' object has no attribute 'exception'\n",
      "ERROR:root:An unknown error occurred! Returning tweets gathered so far.\n",
      "Traceback (most recent call last):\n",
      "  File \"C:\\ProgramData\\Anaconda2\\lib\\site-packages\\twitterscraper\\query.py\", line 93, in query_tweets_once\n",
      "    pos is None\n",
      "  File \"C:\\ProgramData\\Anaconda2\\lib\\site-packages\\twitterscraper\\query.py\", line 53, in query_single_page\n",
      "    except requests.exception.ConnectionError as e:\n",
      "AttributeError: 'module' object has no attribute 'exception'\n",
      "ERROR:root:An unknown error occurred! Returning tweets gathered so far.\n",
      "Traceback (most recent call last):\n",
      "  File \"C:\\ProgramData\\Anaconda2\\lib\\site-packages\\twitterscraper\\query.py\", line 93, in query_tweets_once\n",
      "    pos is None\n",
      "  File \"C:\\ProgramData\\Anaconda2\\lib\\site-packages\\twitterscraper\\query.py\", line 53, in query_single_page\n",
      "    except requests.exception.ConnectionError as e:\n",
      "AttributeError: 'module' object has no attribute 'exception'\n",
      "ERROR:root:An unknown error occurred! Returning tweets gathered so far.\n",
      "Traceback (most recent call last):\n",
      "  File \"C:\\ProgramData\\Anaconda2\\lib\\site-packages\\twitterscraper\\query.py\", line 93, in query_tweets_once\n",
      "    pos is None\n",
      "  File \"C:\\ProgramData\\Anaconda2\\lib\\site-packages\\twitterscraper\\query.py\", line 53, in query_single_page\n",
      "    except requests.exception.ConnectionError as e:\n",
      "AttributeError: 'module' object has no attribute 'exception'\n",
      "ERROR:root:An unknown error occurred! Returning tweets gathered so far.\n",
      "Traceback (most recent call last):\n",
      "  File \"C:\\ProgramData\\Anaconda2\\lib\\site-packages\\twitterscraper\\query.py\", line 93, in query_tweets_once\n",
      "    pos is None\n",
      "  File \"C:\\ProgramData\\Anaconda2\\lib\\site-packages\\twitterscraper\\query.py\", line 53, in query_single_page\n",
      "    except requests.exception.ConnectionError as e:\n",
      "AttributeError: 'module' object has no attribute 'exception'\n",
      "ERROR:root:An unknown error occurred! Returning tweets gathered so far.\n",
      "Traceback (most recent call last):\n",
      "  File \"C:\\ProgramData\\Anaconda2\\lib\\site-packages\\twitterscraper\\query.py\", line 93, in query_tweets_once\n",
      "    pos is None\n",
      "  File \"C:\\ProgramData\\Anaconda2\\lib\\site-packages\\twitterscraper\\query.py\", line 53, in query_single_page\n",
      "    except requests.exception.ConnectionError as e:\n",
      "AttributeError: 'module' object has no attribute 'exception'\n",
      "ERROR:root:An unknown error occurred! Returning tweets gathered so far.\n",
      "Traceback (most recent call last):\n",
      "  File \"C:\\ProgramData\\Anaconda2\\lib\\site-packages\\twitterscraper\\query.py\", line 93, in query_tweets_once\n",
      "    pos is None\n",
      "  File \"C:\\ProgramData\\Anaconda2\\lib\\site-packages\\twitterscraper\\query.py\", line 53, in query_single_page\n",
      "    except requests.exception.ConnectionError as e:\n",
      "AttributeError: 'module' object has no attribute 'exception'\n",
      "ERROR:root:An unknown error occurred! Returning tweets gathered so far.\n",
      "Traceback (most recent call last):\n",
      "  File \"C:\\ProgramData\\Anaconda2\\lib\\site-packages\\twitterscraper\\query.py\", line 93, in query_tweets_once\n",
      "    pos is None\n",
      "  File \"C:\\ProgramData\\Anaconda2\\lib\\site-packages\\twitterscraper\\query.py\", line 53, in query_single_page\n",
      "    except requests.exception.ConnectionError as e:\n",
      "AttributeError: 'module' object has no attribute 'exception'\n",
      "ERROR:root:An unknown error occurred! Returning tweets gathered so far.\n",
      "Traceback (most recent call last):\n",
      "  File \"C:\\ProgramData\\Anaconda2\\lib\\site-packages\\twitterscraper\\query.py\", line 93, in query_tweets_once\n",
      "    pos is None\n",
      "  File \"C:\\ProgramData\\Anaconda2\\lib\\site-packages\\twitterscraper\\query.py\", line 53, in query_single_page\n",
      "    except requests.exception.ConnectionError as e:\n",
      "AttributeError: 'module' object has no attribute 'exception'\n",
      "ERROR:root:An unknown error occurred! Returning tweets gathered so far.\n",
      "Traceback (most recent call last):\n",
      "  File \"C:\\ProgramData\\Anaconda2\\lib\\site-packages\\twitterscraper\\query.py\", line 93, in query_tweets_once\n",
      "    pos is None\n",
      "  File \"C:\\ProgramData\\Anaconda2\\lib\\site-packages\\twitterscraper\\query.py\", line 53, in query_single_page\n",
      "    except requests.exception.ConnectionError as e:\n",
      "AttributeError: 'module' object has no attribute 'exception'\n",
      "ERROR:root:An unknown error occurred! Returning tweets gathered so far.\n",
      "Traceback (most recent call last):\n",
      "  File \"C:\\ProgramData\\Anaconda2\\lib\\site-packages\\twitterscraper\\query.py\", line 93, in query_tweets_once\n",
      "    pos is None\n",
      "  File \"C:\\ProgramData\\Anaconda2\\lib\\site-packages\\twitterscraper\\query.py\", line 53, in query_single_page\n",
      "    except requests.exception.ConnectionError as e:\n",
      "AttributeError: 'module' object has no attribute 'exception'\n",
      "ERROR:root:An unknown error occurred! Returning tweets gathered so far.\n",
      "Traceback (most recent call last):\n",
      "  File \"C:\\ProgramData\\Anaconda2\\lib\\site-packages\\twitterscraper\\query.py\", line 93, in query_tweets_once\n",
      "    pos is None\n",
      "  File \"C:\\ProgramData\\Anaconda2\\lib\\site-packages\\twitterscraper\\query.py\", line 53, in query_single_page\n",
      "    except requests.exception.ConnectionError as e:\n",
      "AttributeError: 'module' object has no attribute 'exception'\n",
      "ERROR:root:An unknown error occurred! Returning tweets gathered so far.\n",
      "Traceback (most recent call last):\n",
      "  File \"C:\\ProgramData\\Anaconda2\\lib\\site-packages\\twitterscraper\\query.py\", line 93, in query_tweets_once\n",
      "    pos is None\n",
      "  File \"C:\\ProgramData\\Anaconda2\\lib\\site-packages\\twitterscraper\\query.py\", line 53, in query_single_page\n",
      "    except requests.exception.ConnectionError as e:\n",
      "AttributeError: 'module' object has no attribute 'exception'\n",
      "ERROR:root:An unknown error occurred! Returning tweets gathered so far.\n",
      "Traceback (most recent call last):\n",
      "  File \"C:\\ProgramData\\Anaconda2\\lib\\site-packages\\twitterscraper\\query.py\", line 93, in query_tweets_once\n",
      "    pos is None\n",
      "  File \"C:\\ProgramData\\Anaconda2\\lib\\site-packages\\twitterscraper\\query.py\", line 53, in query_single_page\n",
      "    except requests.exception.ConnectionError as e:\n",
      "AttributeError: 'module' object has no attribute 'exception'\n",
      "ERROR:root:An unknown error occurred! Returning tweets gathered so far.\n",
      "Traceback (most recent call last):\n",
      "  File \"C:\\ProgramData\\Anaconda2\\lib\\site-packages\\twitterscraper\\query.py\", line 93, in query_tweets_once\n",
      "    pos is None\n",
      "  File \"C:\\ProgramData\\Anaconda2\\lib\\site-packages\\twitterscraper\\query.py\", line 53, in query_single_page\n",
      "    except requests.exception.ConnectionError as e:\n",
      "AttributeError: 'module' object has no attribute 'exception'\n",
      "ERROR:root:An unknown error occurred! Returning tweets gathered so far.\n",
      "Traceback (most recent call last):\n",
      "  File \"C:\\ProgramData\\Anaconda2\\lib\\site-packages\\twitterscraper\\query.py\", line 93, in query_tweets_once\n",
      "    pos is None\n",
      "  File \"C:\\ProgramData\\Anaconda2\\lib\\site-packages\\twitterscraper\\query.py\", line 53, in query_single_page\n",
      "    except requests.exception.ConnectionError as e:\n",
      "AttributeError: 'module' object has no attribute 'exception'\n",
      "ERROR:root:An unknown error occurred! Returning tweets gathered so far.\n",
      "Traceback (most recent call last):\n",
      "  File \"C:\\ProgramData\\Anaconda2\\lib\\site-packages\\twitterscraper\\query.py\", line 93, in query_tweets_once\n",
      "    pos is None\n",
      "  File \"C:\\ProgramData\\Anaconda2\\lib\\site-packages\\twitterscraper\\query.py\", line 53, in query_single_page\n",
      "    except requests.exception.ConnectionError as e:\n",
      "AttributeError: 'module' object has no attribute 'exception'\n",
      "ERROR:root:An unknown error occurred! Returning tweets gathered so far.\n",
      "Traceback (most recent call last):\n",
      "  File \"C:\\ProgramData\\Anaconda2\\lib\\site-packages\\twitterscraper\\query.py\", line 93, in query_tweets_once\n",
      "    pos is None\n",
      "  File \"C:\\ProgramData\\Anaconda2\\lib\\site-packages\\twitterscraper\\query.py\", line 53, in query_single_page\n",
      "    except requests.exception.ConnectionError as e:\n",
      "AttributeError: 'module' object has no attribute 'exception'\n",
      "ERROR:root:An unknown error occurred! Returning tweets gathered so far.\n",
      "Traceback (most recent call last):\n",
      "  File \"C:\\ProgramData\\Anaconda2\\lib\\site-packages\\twitterscraper\\query.py\", line 93, in query_tweets_once\n",
      "    pos is None\n",
      "  File \"C:\\ProgramData\\Anaconda2\\lib\\site-packages\\twitterscraper\\query.py\", line 53, in query_single_page\n",
      "    except requests.exception.ConnectionError as e:\n",
      "AttributeError: 'module' object has no attribute 'exception'\n",
      "ERROR:root:An unknown error occurred! Returning tweets gathered so far.\n",
      "Traceback (most recent call last):\n",
      "  File \"C:\\ProgramData\\Anaconda2\\lib\\site-packages\\twitterscraper\\query.py\", line 93, in query_tweets_once\n",
      "    pos is None\n",
      "  File \"C:\\ProgramData\\Anaconda2\\lib\\site-packages\\twitterscraper\\query.py\", line 53, in query_single_page\n",
      "    except requests.exception.ConnectionError as e:\n",
      "AttributeError: 'module' object has no attribute 'exception'\n",
      "ERROR:root:An unknown error occurred! Returning tweets gathered so far.\n",
      "Traceback (most recent call last):\n",
      "  File \"C:\\ProgramData\\Anaconda2\\lib\\site-packages\\twitterscraper\\query.py\", line 93, in query_tweets_once\n",
      "    pos is None\n",
      "  File \"C:\\ProgramData\\Anaconda2\\lib\\site-packages\\twitterscraper\\query.py\", line 53, in query_single_page\n",
      "    except requests.exception.ConnectionError as e:\n",
      "AttributeError: 'module' object has no attribute 'exception'\n",
      "ERROR:root:An unknown error occurred! Returning tweets gathered so far.\n",
      "Traceback (most recent call last):\n",
      "  File \"C:\\ProgramData\\Anaconda2\\lib\\site-packages\\twitterscraper\\query.py\", line 93, in query_tweets_once\n",
      "    pos is None\n",
      "  File \"C:\\ProgramData\\Anaconda2\\lib\\site-packages\\twitterscraper\\query.py\", line 53, in query_single_page\n",
      "    except requests.exception.ConnectionError as e:\n",
      "AttributeError: 'module' object has no attribute 'exception'\n",
      "ERROR:root:An unknown error occurred! Returning tweets gathered so far.\n",
      "Traceback (most recent call last):\n",
      "  File \"C:\\ProgramData\\Anaconda2\\lib\\site-packages\\twitterscraper\\query.py\", line 93, in query_tweets_once\n",
      "    pos is None\n",
      "  File \"C:\\ProgramData\\Anaconda2\\lib\\site-packages\\twitterscraper\\query.py\", line 53, in query_single_page\n",
      "    except requests.exception.ConnectionError as e:\n",
      "AttributeError: 'module' object has no attribute 'exception'\n",
      "ERROR:root:An unknown error occurred! Returning tweets gathered so far.\n",
      "Traceback (most recent call last):\n",
      "  File \"C:\\ProgramData\\Anaconda2\\lib\\site-packages\\twitterscraper\\query.py\", line 93, in query_tweets_once\n",
      "    pos is None\n",
      "  File \"C:\\ProgramData\\Anaconda2\\lib\\site-packages\\twitterscraper\\query.py\", line 53, in query_single_page\n",
      "    except requests.exception.ConnectionError as e:\n",
      "AttributeError: 'module' object has no attribute 'exception'\n",
      "ERROR:root:An unknown error occurred! Returning tweets gathered so far.\n",
      "Traceback (most recent call last):\n",
      "  File \"C:\\ProgramData\\Anaconda2\\lib\\site-packages\\twitterscraper\\query.py\", line 93, in query_tweets_once\n",
      "    pos is None\n",
      "  File \"C:\\ProgramData\\Anaconda2\\lib\\site-packages\\twitterscraper\\query.py\", line 53, in query_single_page\n",
      "    except requests.exception.ConnectionError as e:\n",
      "AttributeError: 'module' object has no attribute 'exception'\n",
      "ERROR:root:An unknown error occurred! Returning tweets gathered so far.\n",
      "Traceback (most recent call last):\n",
      "  File \"C:\\ProgramData\\Anaconda2\\lib\\site-packages\\twitterscraper\\query.py\", line 93, in query_tweets_once\n",
      "    pos is None\n",
      "  File \"C:\\ProgramData\\Anaconda2\\lib\\site-packages\\twitterscraper\\query.py\", line 53, in query_single_page\n",
      "    except requests.exception.ConnectionError as e:\n",
      "AttributeError: 'module' object has no attribute 'exception'\n",
      "ERROR:root:An unknown error occurred! Returning tweets gathered so far.\n",
      "Traceback (most recent call last):\n",
      "  File \"C:\\ProgramData\\Anaconda2\\lib\\site-packages\\twitterscraper\\query.py\", line 93, in query_tweets_once\n",
      "    pos is None\n",
      "  File \"C:\\ProgramData\\Anaconda2\\lib\\site-packages\\twitterscraper\\query.py\", line 53, in query_single_page\n",
      "    except requests.exception.ConnectionError as e:\n",
      "AttributeError: 'module' object has no attribute 'exception'\n",
      "ERROR:root:An unknown error occurred! Returning tweets gathered so far.\n",
      "Traceback (most recent call last):\n",
      "  File \"C:\\ProgramData\\Anaconda2\\lib\\site-packages\\twitterscraper\\query.py\", line 93, in query_tweets_once\n",
      "    pos is None\n",
      "  File \"C:\\ProgramData\\Anaconda2\\lib\\site-packages\\twitterscraper\\query.py\", line 53, in query_single_page\n",
      "    except requests.exception.ConnectionError as e:\n",
      "AttributeError: 'module' object has no attribute 'exception'\n",
      "ERROR:root:An unknown error occurred! Returning tweets gathered so far.\n",
      "Traceback (most recent call last):\n",
      "  File \"C:\\ProgramData\\Anaconda2\\lib\\site-packages\\twitterscraper\\query.py\", line 93, in query_tweets_once\n",
      "    pos is None\n",
      "  File \"C:\\ProgramData\\Anaconda2\\lib\\site-packages\\twitterscraper\\query.py\", line 53, in query_single_page\n",
      "    except requests.exception.ConnectionError as e:\n",
      "AttributeError: 'module' object has no attribute 'exception'\n",
      "ERROR:root:An unknown error occurred! Returning tweets gathered so far.\n",
      "Traceback (most recent call last):\n",
      "  File \"C:\\ProgramData\\Anaconda2\\lib\\site-packages\\twitterscraper\\query.py\", line 93, in query_tweets_once\n",
      "    pos is None\n",
      "  File \"C:\\ProgramData\\Anaconda2\\lib\\site-packages\\twitterscraper\\query.py\", line 53, in query_single_page\n",
      "    except requests.exception.ConnectionError as e:\n",
      "AttributeError: 'module' object has no attribute 'exception'\n",
      "ERROR:root:An unknown error occurred! Returning tweets gathered so far.\n",
      "Traceback (most recent call last):\n",
      "  File \"C:\\ProgramData\\Anaconda2\\lib\\site-packages\\twitterscraper\\query.py\", line 93, in query_tweets_once\n",
      "    pos is None\n",
      "  File \"C:\\ProgramData\\Anaconda2\\lib\\site-packages\\twitterscraper\\query.py\", line 53, in query_single_page\n",
      "    except requests.exception.ConnectionError as e:\n",
      "AttributeError: 'module' object has no attribute 'exception'\n",
      "ERROR:root:An unknown error occurred! Returning tweets gathered so far.\n",
      "Traceback (most recent call last):\n",
      "  File \"C:\\ProgramData\\Anaconda2\\lib\\site-packages\\twitterscraper\\query.py\", line 93, in query_tweets_once\n",
      "    pos is None\n",
      "  File \"C:\\ProgramData\\Anaconda2\\lib\\site-packages\\twitterscraper\\query.py\", line 53, in query_single_page\n",
      "    except requests.exception.ConnectionError as e:\n",
      "AttributeError: 'module' object has no attribute 'exception'\n",
      "ERROR:root:An unknown error occurred! Returning tweets gathered so far.\n",
      "Traceback (most recent call last):\n",
      "  File \"C:\\ProgramData\\Anaconda2\\lib\\site-packages\\twitterscraper\\query.py\", line 93, in query_tweets_once\n",
      "    pos is None\n",
      "  File \"C:\\ProgramData\\Anaconda2\\lib\\site-packages\\twitterscraper\\query.py\", line 53, in query_single_page\n",
      "    except requests.exception.ConnectionError as e:\n",
      "AttributeError: 'module' object has no attribute 'exception'\n",
      "ERROR:root:An unknown error occurred! Returning tweets gathered so far.\n",
      "Traceback (most recent call last):\n",
      "  File \"C:\\ProgramData\\Anaconda2\\lib\\site-packages\\twitterscraper\\query.py\", line 93, in query_tweets_once\n",
      "    pos is None\n",
      "  File \"C:\\ProgramData\\Anaconda2\\lib\\site-packages\\twitterscraper\\query.py\", line 53, in query_single_page\n",
      "    except requests.exception.ConnectionError as e:\n",
      "AttributeError: 'module' object has no attribute 'exception'\n",
      "ERROR:root:An unknown error occurred! Returning tweets gathered so far.\n",
      "Traceback (most recent call last):\n",
      "  File \"C:\\ProgramData\\Anaconda2\\lib\\site-packages\\twitterscraper\\query.py\", line 93, in query_tweets_once\n",
      "    pos is None\n",
      "  File \"C:\\ProgramData\\Anaconda2\\lib\\site-packages\\twitterscraper\\query.py\", line 53, in query_single_page\n",
      "    except requests.exception.ConnectionError as e:\n",
      "AttributeError: 'module' object has no attribute 'exception'\n",
      "ERROR:root:An unknown error occurred! Returning tweets gathered so far.\n",
      "Traceback (most recent call last):\n",
      "  File \"C:\\ProgramData\\Anaconda2\\lib\\site-packages\\twitterscraper\\query.py\", line 93, in query_tweets_once\n",
      "    pos is None\n",
      "  File \"C:\\ProgramData\\Anaconda2\\lib\\site-packages\\twitterscraper\\query.py\", line 53, in query_single_page\n",
      "    except requests.exception.ConnectionError as e:\n",
      "AttributeError: 'module' object has no attribute 'exception'\n",
      "ERROR:root:An unknown error occurred! Returning tweets gathered so far.\n",
      "Traceback (most recent call last):\n",
      "  File \"C:\\ProgramData\\Anaconda2\\lib\\site-packages\\twitterscraper\\query.py\", line 93, in query_tweets_once\n",
      "    pos is None\n",
      "  File \"C:\\ProgramData\\Anaconda2\\lib\\site-packages\\twitterscraper\\query.py\", line 53, in query_single_page\n",
      "    except requests.exception.ConnectionError as e:\n",
      "AttributeError: 'module' object has no attribute 'exception'\n",
      "ERROR:root:An unknown error occurred! Returning tweets gathered so far.\n",
      "Traceback (most recent call last):\n",
      "  File \"C:\\ProgramData\\Anaconda2\\lib\\site-packages\\twitterscraper\\query.py\", line 93, in query_tweets_once\n",
      "    pos is None\n",
      "  File \"C:\\ProgramData\\Anaconda2\\lib\\site-packages\\twitterscraper\\query.py\", line 53, in query_single_page\n",
      "    except requests.exception.ConnectionError as e:\n",
      "AttributeError: 'module' object has no attribute 'exception'\n",
      "ERROR:root:An unknown error occurred! Returning tweets gathered so far.\n",
      "Traceback (most recent call last):\n",
      "  File \"C:\\ProgramData\\Anaconda2\\lib\\site-packages\\twitterscraper\\query.py\", line 93, in query_tweets_once\n",
      "    pos is None\n",
      "  File \"C:\\ProgramData\\Anaconda2\\lib\\site-packages\\twitterscraper\\query.py\", line 53, in query_single_page\n",
      "    except requests.exception.ConnectionError as e:\n",
      "AttributeError: 'module' object has no attribute 'exception'\n",
      "ERROR:root:An unknown error occurred! Returning tweets gathered so far.\n",
      "Traceback (most recent call last):\n",
      "  File \"C:\\ProgramData\\Anaconda2\\lib\\site-packages\\twitterscraper\\query.py\", line 93, in query_tweets_once\n",
      "    pos is None\n",
      "  File \"C:\\ProgramData\\Anaconda2\\lib\\site-packages\\twitterscraper\\query.py\", line 53, in query_single_page\n",
      "    except requests.exception.ConnectionError as e:\n",
      "AttributeError: 'module' object has no attribute 'exception'\n",
      "ERROR:root:An unknown error occurred! Returning tweets gathered so far.\n",
      "Traceback (most recent call last):\n",
      "  File \"C:\\ProgramData\\Anaconda2\\lib\\site-packages\\twitterscraper\\query.py\", line 93, in query_tweets_once\n",
      "    pos is None\n",
      "  File \"C:\\ProgramData\\Anaconda2\\lib\\site-packages\\twitterscraper\\query.py\", line 53, in query_single_page\n",
      "    except requests.exception.ConnectionError as e:\n",
      "AttributeError: 'module' object has no attribute 'exception'\n",
      "ERROR:root:An unknown error occurred! Returning tweets gathered so far.\n",
      "Traceback (most recent call last):\n",
      "  File \"C:\\ProgramData\\Anaconda2\\lib\\site-packages\\twitterscraper\\query.py\", line 93, in query_tweets_once\n",
      "    pos is None\n",
      "  File \"C:\\ProgramData\\Anaconda2\\lib\\site-packages\\twitterscraper\\query.py\", line 53, in query_single_page\n",
      "    except requests.exception.ConnectionError as e:\n",
      "AttributeError: 'module' object has no attribute 'exception'\n",
      "ERROR:root:An unknown error occurred! Returning tweets gathered so far.\n",
      "Traceback (most recent call last):\n",
      "  File \"C:\\ProgramData\\Anaconda2\\lib\\site-packages\\twitterscraper\\query.py\", line 93, in query_tweets_once\n",
      "    pos is None\n",
      "  File \"C:\\ProgramData\\Anaconda2\\lib\\site-packages\\twitterscraper\\query.py\", line 53, in query_single_page\n",
      "    except requests.exception.ConnectionError as e:\n",
      "AttributeError: 'module' object has no attribute 'exception'\n",
      "ERROR:root:An unknown error occurred! Returning tweets gathered so far.\n",
      "Traceback (most recent call last):\n",
      "  File \"C:\\ProgramData\\Anaconda2\\lib\\site-packages\\twitterscraper\\query.py\", line 93, in query_tweets_once\n",
      "    pos is None\n",
      "  File \"C:\\ProgramData\\Anaconda2\\lib\\site-packages\\twitterscraper\\query.py\", line 53, in query_single_page\n",
      "    except requests.exception.ConnectionError as e:\n",
      "AttributeError: 'module' object has no attribute 'exception'\n",
      "ERROR:root:An unknown error occurred! Returning tweets gathered so far.\n",
      "Traceback (most recent call last):\n",
      "  File \"C:\\ProgramData\\Anaconda2\\lib\\site-packages\\twitterscraper\\query.py\", line 93, in query_tweets_once\n",
      "    pos is None\n",
      "  File \"C:\\ProgramData\\Anaconda2\\lib\\site-packages\\twitterscraper\\query.py\", line 53, in query_single_page\n",
      "    except requests.exception.ConnectionError as e:\n",
      "AttributeError: 'module' object has no attribute 'exception'\n",
      "ERROR:root:An unknown error occurred! Returning tweets gathered so far.\n",
      "Traceback (most recent call last):\n",
      "  File \"C:\\ProgramData\\Anaconda2\\lib\\site-packages\\twitterscraper\\query.py\", line 93, in query_tweets_once\n",
      "    pos is None\n",
      "  File \"C:\\ProgramData\\Anaconda2\\lib\\site-packages\\twitterscraper\\query.py\", line 53, in query_single_page\n",
      "    except requests.exception.ConnectionError as e:\n",
      "AttributeError: 'module' object has no attribute 'exception'\n",
      "ERROR:root:An unknown error occurred! Returning tweets gathered so far.\n",
      "Traceback (most recent call last):\n",
      "  File \"C:\\ProgramData\\Anaconda2\\lib\\site-packages\\twitterscraper\\query.py\", line 93, in query_tweets_once\n",
      "    pos is None\n",
      "  File \"C:\\ProgramData\\Anaconda2\\lib\\site-packages\\twitterscraper\\query.py\", line 53, in query_single_page\n",
      "    except requests.exception.ConnectionError as e:\n",
      "AttributeError: 'module' object has no attribute 'exception'\n",
      "ERROR:root:An unknown error occurred! Returning tweets gathered so far.\n",
      "Traceback (most recent call last):\n",
      "  File \"C:\\ProgramData\\Anaconda2\\lib\\site-packages\\twitterscraper\\query.py\", line 93, in query_tweets_once\n",
      "    pos is None\n",
      "  File \"C:\\ProgramData\\Anaconda2\\lib\\site-packages\\twitterscraper\\query.py\", line 53, in query_single_page\n",
      "    except requests.exception.ConnectionError as e:\n",
      "AttributeError: 'module' object has no attribute 'exception'\n",
      "ERROR:root:An unknown error occurred! Returning tweets gathered so far.\n",
      "Traceback (most recent call last):\n",
      "  File \"C:\\ProgramData\\Anaconda2\\lib\\site-packages\\twitterscraper\\query.py\", line 93, in query_tweets_once\n",
      "    pos is None\n",
      "  File \"C:\\ProgramData\\Anaconda2\\lib\\site-packages\\twitterscraper\\query.py\", line 53, in query_single_page\n",
      "    except requests.exception.ConnectionError as e:\n",
      "AttributeError: 'module' object has no attribute 'exception'\n",
      "ERROR:root:An unknown error occurred! Returning tweets gathered so far.\n",
      "Traceback (most recent call last):\n",
      "  File \"C:\\ProgramData\\Anaconda2\\lib\\site-packages\\twitterscraper\\query.py\", line 93, in query_tweets_once\n",
      "    pos is None\n",
      "  File \"C:\\ProgramData\\Anaconda2\\lib\\site-packages\\twitterscraper\\query.py\", line 53, in query_single_page\n",
      "    except requests.exception.ConnectionError as e:\n",
      "AttributeError: 'module' object has no attribute 'exception'\n",
      "ERROR:root:An unknown error occurred! Returning tweets gathered so far.\n",
      "Traceback (most recent call last):\n",
      "  File \"C:\\ProgramData\\Anaconda2\\lib\\site-packages\\twitterscraper\\query.py\", line 93, in query_tweets_once\n",
      "    pos is None\n",
      "  File \"C:\\ProgramData\\Anaconda2\\lib\\site-packages\\twitterscraper\\query.py\", line 53, in query_single_page\n",
      "    except requests.exception.ConnectionError as e:\n",
      "AttributeError: 'module' object has no attribute 'exception'\n",
      "ERROR:root:An unknown error occurred! Returning tweets gathered so far.\n",
      "Traceback (most recent call last):\n",
      "  File \"C:\\ProgramData\\Anaconda2\\lib\\site-packages\\twitterscraper\\query.py\", line 93, in query_tweets_once\n",
      "    pos is None\n",
      "  File \"C:\\ProgramData\\Anaconda2\\lib\\site-packages\\twitterscraper\\query.py\", line 53, in query_single_page\n",
      "    except requests.exception.ConnectionError as e:\n",
      "AttributeError: 'module' object has no attribute 'exception'\n",
      "ERROR:root:An unknown error occurred! Returning tweets gathered so far.\n",
      "Traceback (most recent call last):\n",
      "  File \"C:\\ProgramData\\Anaconda2\\lib\\site-packages\\twitterscraper\\query.py\", line 93, in query_tweets_once\n",
      "    pos is None\n",
      "  File \"C:\\ProgramData\\Anaconda2\\lib\\site-packages\\twitterscraper\\query.py\", line 53, in query_single_page\n",
      "    except requests.exception.ConnectionError as e:\n",
      "AttributeError: 'module' object has no attribute 'exception'\n",
      "ERROR:root:An unknown error occurred! Returning tweets gathered so far.\n",
      "Traceback (most recent call last):\n",
      "  File \"C:\\ProgramData\\Anaconda2\\lib\\site-packages\\twitterscraper\\query.py\", line 93, in query_tweets_once\n",
      "    pos is None\n",
      "  File \"C:\\ProgramData\\Anaconda2\\lib\\site-packages\\twitterscraper\\query.py\", line 53, in query_single_page\n",
      "    except requests.exception.ConnectionError as e:\n",
      "AttributeError: 'module' object has no attribute 'exception'\n",
      "ERROR:root:An unknown error occurred! Returning tweets gathered so far.\n",
      "Traceback (most recent call last):\n",
      "  File \"C:\\ProgramData\\Anaconda2\\lib\\site-packages\\twitterscraper\\query.py\", line 93, in query_tweets_once\n",
      "    pos is None\n",
      "  File \"C:\\ProgramData\\Anaconda2\\lib\\site-packages\\twitterscraper\\query.py\", line 53, in query_single_page\n",
      "    except requests.exception.ConnectionError as e:\n",
      "AttributeError: 'module' object has no attribute 'exception'\n",
      "ERROR:root:An unknown error occurred! Returning tweets gathered so far.\n",
      "Traceback (most recent call last):\n",
      "  File \"C:\\ProgramData\\Anaconda2\\lib\\site-packages\\twitterscraper\\query.py\", line 93, in query_tweets_once\n",
      "    pos is None\n",
      "  File \"C:\\ProgramData\\Anaconda2\\lib\\site-packages\\twitterscraper\\query.py\", line 53, in query_single_page\n",
      "    except requests.exception.ConnectionError as e:\n",
      "AttributeError: 'module' object has no attribute 'exception'\n",
      "ERROR:root:An unknown error occurred! Returning tweets gathered so far.\n",
      "Traceback (most recent call last):\n",
      "  File \"C:\\ProgramData\\Anaconda2\\lib\\site-packages\\twitterscraper\\query.py\", line 93, in query_tweets_once\n",
      "    pos is None\n",
      "  File \"C:\\ProgramData\\Anaconda2\\lib\\site-packages\\twitterscraper\\query.py\", line 53, in query_single_page\n",
      "    except requests.exception.ConnectionError as e:\n",
      "AttributeError: 'module' object has no attribute 'exception'\n",
      "ERROR:root:An unknown error occurred! Returning tweets gathered so far.\n",
      "Traceback (most recent call last):\n",
      "  File \"C:\\ProgramData\\Anaconda2\\lib\\site-packages\\twitterscraper\\query.py\", line 93, in query_tweets_once\n",
      "    pos is None\n",
      "  File \"C:\\ProgramData\\Anaconda2\\lib\\site-packages\\twitterscraper\\query.py\", line 53, in query_single_page\n",
      "    except requests.exception.ConnectionError as e:\n",
      "AttributeError: 'module' object has no attribute 'exception'\n",
      "ERROR:root:An unknown error occurred! Returning tweets gathered so far.\n",
      "Traceback (most recent call last):\n",
      "  File \"C:\\ProgramData\\Anaconda2\\lib\\site-packages\\twitterscraper\\query.py\", line 93, in query_tweets_once\n",
      "    pos is None\n",
      "  File \"C:\\ProgramData\\Anaconda2\\lib\\site-packages\\twitterscraper\\query.py\", line 53, in query_single_page\n",
      "    except requests.exception.ConnectionError as e:\n",
      "AttributeError: 'module' object has no attribute 'exception'\n",
      "ERROR:root:An unknown error occurred! Returning tweets gathered so far.\n",
      "Traceback (most recent call last):\n",
      "  File \"C:\\ProgramData\\Anaconda2\\lib\\site-packages\\twitterscraper\\query.py\", line 93, in query_tweets_once\n",
      "    pos is None\n",
      "  File \"C:\\ProgramData\\Anaconda2\\lib\\site-packages\\twitterscraper\\query.py\", line 53, in query_single_page\n",
      "    except requests.exception.ConnectionError as e:\n",
      "AttributeError: 'module' object has no attribute 'exception'\n",
      "ERROR:root:An unknown error occurred! Returning tweets gathered so far.\n",
      "Traceback (most recent call last):\n",
      "  File \"C:\\ProgramData\\Anaconda2\\lib\\site-packages\\twitterscraper\\query.py\", line 93, in query_tweets_once\n",
      "    pos is None\n",
      "  File \"C:\\ProgramData\\Anaconda2\\lib\\site-packages\\twitterscraper\\query.py\", line 53, in query_single_page\n",
      "    except requests.exception.ConnectionError as e:\n",
      "AttributeError: 'module' object has no attribute 'exception'\n",
      "ERROR:root:An unknown error occurred! Returning tweets gathered so far.\n",
      "Traceback (most recent call last):\n",
      "  File \"C:\\ProgramData\\Anaconda2\\lib\\site-packages\\twitterscraper\\query.py\", line 93, in query_tweets_once\n",
      "    pos is None\n",
      "  File \"C:\\ProgramData\\Anaconda2\\lib\\site-packages\\twitterscraper\\query.py\", line 53, in query_single_page\n",
      "    except requests.exception.ConnectionError as e:\n",
      "AttributeError: 'module' object has no attribute 'exception'\n",
      "ERROR:root:An unknown error occurred! Returning tweets gathered so far.\n",
      "Traceback (most recent call last):\n",
      "  File \"C:\\ProgramData\\Anaconda2\\lib\\site-packages\\twitterscraper\\query.py\", line 93, in query_tweets_once\n",
      "    pos is None\n",
      "  File \"C:\\ProgramData\\Anaconda2\\lib\\site-packages\\twitterscraper\\query.py\", line 53, in query_single_page\n",
      "    except requests.exception.ConnectionError as e:\n",
      "AttributeError: 'module' object has no attribute 'exception'\n",
      "ERROR:root:An unknown error occurred! Returning tweets gathered so far.\n",
      "Traceback (most recent call last):\n",
      "  File \"C:\\ProgramData\\Anaconda2\\lib\\site-packages\\twitterscraper\\query.py\", line 93, in query_tweets_once\n",
      "    pos is None\n",
      "  File \"C:\\ProgramData\\Anaconda2\\lib\\site-packages\\twitterscraper\\query.py\", line 53, in query_single_page\n",
      "    except requests.exception.ConnectionError as e:\n",
      "AttributeError: 'module' object has no attribute 'exception'\n",
      "ERROR:root:An unknown error occurred! Returning tweets gathered so far.\n",
      "Traceback (most recent call last):\n",
      "  File \"C:\\ProgramData\\Anaconda2\\lib\\site-packages\\twitterscraper\\query.py\", line 93, in query_tweets_once\n",
      "    pos is None\n",
      "  File \"C:\\ProgramData\\Anaconda2\\lib\\site-packages\\twitterscraper\\query.py\", line 53, in query_single_page\n",
      "    except requests.exception.ConnectionError as e:\n",
      "AttributeError: 'module' object has no attribute 'exception'\n",
      "ERROR:root:An unknown error occurred! Returning tweets gathered so far.\n",
      "Traceback (most recent call last):\n",
      "  File \"C:\\ProgramData\\Anaconda2\\lib\\site-packages\\twitterscraper\\query.py\", line 93, in query_tweets_once\n",
      "    pos is None\n",
      "  File \"C:\\ProgramData\\Anaconda2\\lib\\site-packages\\twitterscraper\\query.py\", line 53, in query_single_page\n",
      "    except requests.exception.ConnectionError as e:\n",
      "AttributeError: 'module' object has no attribute 'exception'\n",
      "ERROR:root:An unknown error occurred! Returning tweets gathered so far.\n",
      "Traceback (most recent call last):\n",
      "  File \"C:\\ProgramData\\Anaconda2\\lib\\site-packages\\twitterscraper\\query.py\", line 93, in query_tweets_once\n",
      "    pos is None\n",
      "  File \"C:\\ProgramData\\Anaconda2\\lib\\site-packages\\twitterscraper\\query.py\", line 53, in query_single_page\n",
      "    except requests.exception.ConnectionError as e:\n",
      "AttributeError: 'module' object has no attribute 'exception'\n",
      "ERROR:root:An unknown error occurred! Returning tweets gathered so far.\n",
      "Traceback (most recent call last):\n",
      "  File \"C:\\ProgramData\\Anaconda2\\lib\\site-packages\\twitterscraper\\query.py\", line 93, in query_tweets_once\n",
      "    pos is None\n",
      "  File \"C:\\ProgramData\\Anaconda2\\lib\\site-packages\\twitterscraper\\query.py\", line 53, in query_single_page\n",
      "    except requests.exception.ConnectionError as e:\n",
      "AttributeError: 'module' object has no attribute 'exception'\n",
      "ERROR:root:An unknown error occurred! Returning tweets gathered so far.\n",
      "Traceback (most recent call last):\n",
      "  File \"C:\\ProgramData\\Anaconda2\\lib\\site-packages\\twitterscraper\\query.py\", line 93, in query_tweets_once\n",
      "    pos is None\n",
      "  File \"C:\\ProgramData\\Anaconda2\\lib\\site-packages\\twitterscraper\\query.py\", line 53, in query_single_page\n",
      "    except requests.exception.ConnectionError as e:\n",
      "AttributeError: 'module' object has no attribute 'exception'\n",
      "ERROR:root:An unknown error occurred! Returning tweets gathered so far.\n",
      "Traceback (most recent call last):\n",
      "  File \"C:\\ProgramData\\Anaconda2\\lib\\site-packages\\twitterscraper\\query.py\", line 93, in query_tweets_once\n",
      "    pos is None\n",
      "  File \"C:\\ProgramData\\Anaconda2\\lib\\site-packages\\twitterscraper\\query.py\", line 53, in query_single_page\n",
      "    except requests.exception.ConnectionError as e:\n",
      "AttributeError: 'module' object has no attribute 'exception'\n",
      "ERROR:root:An unknown error occurred! Returning tweets gathered so far.\n",
      "Traceback (most recent call last):\n",
      "  File \"C:\\ProgramData\\Anaconda2\\lib\\site-packages\\twitterscraper\\query.py\", line 93, in query_tweets_once\n",
      "    pos is None\n",
      "  File \"C:\\ProgramData\\Anaconda2\\lib\\site-packages\\twitterscraper\\query.py\", line 53, in query_single_page\n",
      "    except requests.exception.ConnectionError as e:\n",
      "AttributeError: 'module' object has no attribute 'exception'\n",
      "ERROR:root:An unknown error occurred! Returning tweets gathered so far.\n",
      "Traceback (most recent call last):\n",
      "  File \"C:\\ProgramData\\Anaconda2\\lib\\site-packages\\twitterscraper\\query.py\", line 93, in query_tweets_once\n",
      "    pos is None\n",
      "  File \"C:\\ProgramData\\Anaconda2\\lib\\site-packages\\twitterscraper\\query.py\", line 53, in query_single_page\n",
      "    except requests.exception.ConnectionError as e:\n",
      "AttributeError: 'module' object has no attribute 'exception'\n",
      "ERROR:root:An unknown error occurred! Returning tweets gathered so far.\n",
      "Traceback (most recent call last):\n",
      "  File \"C:\\ProgramData\\Anaconda2\\lib\\site-packages\\twitterscraper\\query.py\", line 93, in query_tweets_once\n",
      "    pos is None\n",
      "  File \"C:\\ProgramData\\Anaconda2\\lib\\site-packages\\twitterscraper\\query.py\", line 53, in query_single_page\n",
      "    except requests.exception.ConnectionError as e:\n",
      "AttributeError: 'module' object has no attribute 'exception'\n",
      "ERROR:root:An unknown error occurred! Returning tweets gathered so far.\n",
      "Traceback (most recent call last):\n",
      "  File \"C:\\ProgramData\\Anaconda2\\lib\\site-packages\\twitterscraper\\query.py\", line 93, in query_tweets_once\n",
      "    pos is None\n",
      "  File \"C:\\ProgramData\\Anaconda2\\lib\\site-packages\\twitterscraper\\query.py\", line 53, in query_single_page\n",
      "    except requests.exception.ConnectionError as e:\n",
      "AttributeError: 'module' object has no attribute 'exception'\n",
      "ERROR:root:An unknown error occurred! Returning tweets gathered so far.\n",
      "Traceback (most recent call last):\n",
      "  File \"C:\\ProgramData\\Anaconda2\\lib\\site-packages\\twitterscraper\\query.py\", line 93, in query_tweets_once\n",
      "    pos is None\n",
      "  File \"C:\\ProgramData\\Anaconda2\\lib\\site-packages\\twitterscraper\\query.py\", line 53, in query_single_page\n",
      "    except requests.exception.ConnectionError as e:\n",
      "AttributeError: 'module' object has no attribute 'exception'\n",
      "ERROR:root:An unknown error occurred! Returning tweets gathered so far.\n",
      "Traceback (most recent call last):\n",
      "  File \"C:\\ProgramData\\Anaconda2\\lib\\site-packages\\twitterscraper\\query.py\", line 93, in query_tweets_once\n",
      "    pos is None\n",
      "  File \"C:\\ProgramData\\Anaconda2\\lib\\site-packages\\twitterscraper\\query.py\", line 53, in query_single_page\n",
      "    except requests.exception.ConnectionError as e:\n",
      "AttributeError: 'module' object has no attribute 'exception'\n",
      "ERROR:root:An unknown error occurred! Returning tweets gathered so far.\n",
      "Traceback (most recent call last):\n",
      "  File \"C:\\ProgramData\\Anaconda2\\lib\\site-packages\\twitterscraper\\query.py\", line 93, in query_tweets_once\n",
      "    pos is None\n",
      "  File \"C:\\ProgramData\\Anaconda2\\lib\\site-packages\\twitterscraper\\query.py\", line 53, in query_single_page\n",
      "    except requests.exception.ConnectionError as e:\n",
      "AttributeError: 'module' object has no attribute 'exception'\n",
      "ERROR:root:An unknown error occurred! Returning tweets gathered so far.\n",
      "Traceback (most recent call last):\n",
      "  File \"C:\\ProgramData\\Anaconda2\\lib\\site-packages\\twitterscraper\\query.py\", line 93, in query_tweets_once\n",
      "    pos is None\n",
      "  File \"C:\\ProgramData\\Anaconda2\\lib\\site-packages\\twitterscraper\\query.py\", line 53, in query_single_page\n",
      "    except requests.exception.ConnectionError as e:\n",
      "AttributeError: 'module' object has no attribute 'exception'\n",
      "ERROR:root:An unknown error occurred! Returning tweets gathered so far.\n",
      "Traceback (most recent call last):\n",
      "  File \"C:\\ProgramData\\Anaconda2\\lib\\site-packages\\twitterscraper\\query.py\", line 93, in query_tweets_once\n",
      "    pos is None\n",
      "  File \"C:\\ProgramData\\Anaconda2\\lib\\site-packages\\twitterscraper\\query.py\", line 53, in query_single_page\n",
      "    except requests.exception.ConnectionError as e:\n",
      "AttributeError: 'module' object has no attribute 'exception'\n",
      "ERROR:root:An unknown error occurred! Returning tweets gathered so far.\n",
      "Traceback (most recent call last):\n",
      "  File \"C:\\ProgramData\\Anaconda2\\lib\\site-packages\\twitterscraper\\query.py\", line 93, in query_tweets_once\n",
      "    pos is None\n",
      "  File \"C:\\ProgramData\\Anaconda2\\lib\\site-packages\\twitterscraper\\query.py\", line 53, in query_single_page\n",
      "    except requests.exception.ConnectionError as e:\n",
      "AttributeError: 'module' object has no attribute 'exception'\n",
      "ERROR:root:An unknown error occurred! Returning tweets gathered so far.\n",
      "Traceback (most recent call last):\n",
      "  File \"C:\\ProgramData\\Anaconda2\\lib\\site-packages\\twitterscraper\\query.py\", line 93, in query_tweets_once\n",
      "    pos is None\n",
      "  File \"C:\\ProgramData\\Anaconda2\\lib\\site-packages\\twitterscraper\\query.py\", line 53, in query_single_page\n",
      "    except requests.exception.ConnectionError as e:\n",
      "AttributeError: 'module' object has no attribute 'exception'\n",
      "ERROR:root:An unknown error occurred! Returning tweets gathered so far.\n",
      "Traceback (most recent call last):\n",
      "  File \"C:\\ProgramData\\Anaconda2\\lib\\site-packages\\twitterscraper\\query.py\", line 93, in query_tweets_once\n",
      "    pos is None\n",
      "  File \"C:\\ProgramData\\Anaconda2\\lib\\site-packages\\twitterscraper\\query.py\", line 53, in query_single_page\n",
      "    except requests.exception.ConnectionError as e:\n",
      "AttributeError: 'module' object has no attribute 'exception'\n",
      "ERROR:root:An unknown error occurred! Returning tweets gathered so far.\n",
      "Traceback (most recent call last):\n",
      "  File \"C:\\ProgramData\\Anaconda2\\lib\\site-packages\\twitterscraper\\query.py\", line 93, in query_tweets_once\n",
      "    pos is None\n",
      "  File \"C:\\ProgramData\\Anaconda2\\lib\\site-packages\\twitterscraper\\query.py\", line 53, in query_single_page\n",
      "    except requests.exception.ConnectionError as e:\n",
      "AttributeError: 'module' object has no attribute 'exception'\n",
      "ERROR:root:An unknown error occurred! Returning tweets gathered so far.\n",
      "Traceback (most recent call last):\n",
      "  File \"C:\\ProgramData\\Anaconda2\\lib\\site-packages\\twitterscraper\\query.py\", line 93, in query_tweets_once\n",
      "    pos is None\n",
      "  File \"C:\\ProgramData\\Anaconda2\\lib\\site-packages\\twitterscraper\\query.py\", line 53, in query_single_page\n",
      "    except requests.exception.ConnectionError as e:\n",
      "AttributeError: 'module' object has no attribute 'exception'\n",
      "ERROR:root:An unknown error occurred! Returning tweets gathered so far.\n",
      "Traceback (most recent call last):\n",
      "  File \"C:\\ProgramData\\Anaconda2\\lib\\site-packages\\twitterscraper\\query.py\", line 93, in query_tweets_once\n",
      "    pos is None\n",
      "  File \"C:\\ProgramData\\Anaconda2\\lib\\site-packages\\twitterscraper\\query.py\", line 53, in query_single_page\n",
      "    except requests.exception.ConnectionError as e:\n",
      "AttributeError: 'module' object has no attribute 'exception'\n",
      "ERROR:root:An unknown error occurred! Returning tweets gathered so far.\n",
      "Traceback (most recent call last):\n",
      "  File \"C:\\ProgramData\\Anaconda2\\lib\\site-packages\\twitterscraper\\query.py\", line 93, in query_tweets_once\n",
      "    pos is None\n",
      "  File \"C:\\ProgramData\\Anaconda2\\lib\\site-packages\\twitterscraper\\query.py\", line 53, in query_single_page\n",
      "    except requests.exception.ConnectionError as e:\n",
      "AttributeError: 'module' object has no attribute 'exception'\n",
      "ERROR:root:An unknown error occurred! Returning tweets gathered so far.\n",
      "Traceback (most recent call last):\n",
      "  File \"C:\\ProgramData\\Anaconda2\\lib\\site-packages\\twitterscraper\\query.py\", line 93, in query_tweets_once\n",
      "    pos is None\n",
      "  File \"C:\\ProgramData\\Anaconda2\\lib\\site-packages\\twitterscraper\\query.py\", line 53, in query_single_page\n",
      "    except requests.exception.ConnectionError as e:\n",
      "AttributeError: 'module' object has no attribute 'exception'\n",
      "ERROR:root:An unknown error occurred! Returning tweets gathered so far.\n",
      "Traceback (most recent call last):\n",
      "  File \"C:\\ProgramData\\Anaconda2\\lib\\site-packages\\twitterscraper\\query.py\", line 93, in query_tweets_once\n",
      "    pos is None\n",
      "  File \"C:\\ProgramData\\Anaconda2\\lib\\site-packages\\twitterscraper\\query.py\", line 53, in query_single_page\n",
      "    except requests.exception.ConnectionError as e:\n",
      "AttributeError: 'module' object has no attribute 'exception'\n",
      "ERROR:root:An unknown error occurred! Returning tweets gathered so far.\n",
      "Traceback (most recent call last):\n",
      "  File \"C:\\ProgramData\\Anaconda2\\lib\\site-packages\\twitterscraper\\query.py\", line 93, in query_tweets_once\n",
      "    pos is None\n",
      "  File \"C:\\ProgramData\\Anaconda2\\lib\\site-packages\\twitterscraper\\query.py\", line 53, in query_single_page\n",
      "    except requests.exception.ConnectionError as e:\n",
      "AttributeError: 'module' object has no attribute 'exception'\n",
      "ERROR:root:An unknown error occurred! Returning tweets gathered so far.\n",
      "Traceback (most recent call last):\n",
      "  File \"C:\\ProgramData\\Anaconda2\\lib\\site-packages\\twitterscraper\\query.py\", line 93, in query_tweets_once\n",
      "    pos is None\n",
      "  File \"C:\\ProgramData\\Anaconda2\\lib\\site-packages\\twitterscraper\\query.py\", line 53, in query_single_page\n",
      "    except requests.exception.ConnectionError as e:\n",
      "AttributeError: 'module' object has no attribute 'exception'\n",
      "ERROR:root:An unknown error occurred! Returning tweets gathered so far.\n",
      "Traceback (most recent call last):\n",
      "  File \"C:\\ProgramData\\Anaconda2\\lib\\site-packages\\twitterscraper\\query.py\", line 93, in query_tweets_once\n",
      "    pos is None\n",
      "  File \"C:\\ProgramData\\Anaconda2\\lib\\site-packages\\twitterscraper\\query.py\", line 53, in query_single_page\n",
      "    except requests.exception.ConnectionError as e:\n",
      "AttributeError: 'module' object has no attribute 'exception'\n",
      "ERROR:root:An unknown error occurred! Returning tweets gathered so far.\n",
      "Traceback (most recent call last):\n",
      "  File \"C:\\ProgramData\\Anaconda2\\lib\\site-packages\\twitterscraper\\query.py\", line 93, in query_tweets_once\n",
      "    pos is None\n",
      "  File \"C:\\ProgramData\\Anaconda2\\lib\\site-packages\\twitterscraper\\query.py\", line 53, in query_single_page\n",
      "    except requests.exception.ConnectionError as e:\n",
      "AttributeError: 'module' object has no attribute 'exception'\n",
      "ERROR:root:An unknown error occurred! Returning tweets gathered so far.\n",
      "Traceback (most recent call last):\n",
      "  File \"C:\\ProgramData\\Anaconda2\\lib\\site-packages\\twitterscraper\\query.py\", line 93, in query_tweets_once\n",
      "    pos is None\n",
      "  File \"C:\\ProgramData\\Anaconda2\\lib\\site-packages\\twitterscraper\\query.py\", line 53, in query_single_page\n",
      "    except requests.exception.ConnectionError as e:\n",
      "AttributeError: 'module' object has no attribute 'exception'\n",
      "ERROR:root:An unknown error occurred! Returning tweets gathered so far.\n",
      "Traceback (most recent call last):\n",
      "  File \"C:\\ProgramData\\Anaconda2\\lib\\site-packages\\twitterscraper\\query.py\", line 93, in query_tweets_once\n",
      "    pos is None\n",
      "  File \"C:\\ProgramData\\Anaconda2\\lib\\site-packages\\twitterscraper\\query.py\", line 53, in query_single_page\n",
      "    except requests.exception.ConnectionError as e:\n",
      "AttributeError: 'module' object has no attribute 'exception'\n",
      "ERROR:root:An unknown error occurred! Returning tweets gathered so far.\n",
      "Traceback (most recent call last):\n",
      "  File \"C:\\ProgramData\\Anaconda2\\lib\\site-packages\\twitterscraper\\query.py\", line 93, in query_tweets_once\n",
      "    pos is None\n",
      "  File \"C:\\ProgramData\\Anaconda2\\lib\\site-packages\\twitterscraper\\query.py\", line 53, in query_single_page\n",
      "    except requests.exception.ConnectionError as e:\n",
      "AttributeError: 'module' object has no attribute 'exception'\n",
      "ERROR:root:An unknown error occurred! Returning tweets gathered so far.\n",
      "Traceback (most recent call last):\n",
      "  File \"C:\\ProgramData\\Anaconda2\\lib\\site-packages\\twitterscraper\\query.py\", line 93, in query_tweets_once\n",
      "    pos is None\n",
      "  File \"C:\\ProgramData\\Anaconda2\\lib\\site-packages\\twitterscraper\\query.py\", line 53, in query_single_page\n",
      "    except requests.exception.ConnectionError as e:\n",
      "AttributeError: 'module' object has no attribute 'exception'\n",
      "ERROR:root:An unknown error occurred! Returning tweets gathered so far.\n",
      "Traceback (most recent call last):\n",
      "  File \"C:\\ProgramData\\Anaconda2\\lib\\site-packages\\twitterscraper\\query.py\", line 93, in query_tweets_once\n",
      "    pos is None\n",
      "  File \"C:\\ProgramData\\Anaconda2\\lib\\site-packages\\twitterscraper\\query.py\", line 53, in query_single_page\n",
      "    except requests.exception.ConnectionError as e:\n",
      "AttributeError: 'module' object has no attribute 'exception'\n",
      "ERROR:root:An unknown error occurred! Returning tweets gathered so far.\n",
      "Traceback (most recent call last):\n",
      "  File \"C:\\ProgramData\\Anaconda2\\lib\\site-packages\\twitterscraper\\query.py\", line 93, in query_tweets_once\n",
      "    pos is None\n",
      "  File \"C:\\ProgramData\\Anaconda2\\lib\\site-packages\\twitterscraper\\query.py\", line 53, in query_single_page\n",
      "    except requests.exception.ConnectionError as e:\n",
      "AttributeError: 'module' object has no attribute 'exception'\n",
      "ERROR:root:An unknown error occurred! Returning tweets gathered so far.\n",
      "Traceback (most recent call last):\n",
      "  File \"C:\\ProgramData\\Anaconda2\\lib\\site-packages\\twitterscraper\\query.py\", line 93, in query_tweets_once\n",
      "    pos is None\n",
      "  File \"C:\\ProgramData\\Anaconda2\\lib\\site-packages\\twitterscraper\\query.py\", line 53, in query_single_page\n",
      "    except requests.exception.ConnectionError as e:\n",
      "AttributeError: 'module' object has no attribute 'exception'\n",
      "ERROR:root:An unknown error occurred! Returning tweets gathered so far.\n",
      "Traceback (most recent call last):\n",
      "  File \"C:\\ProgramData\\Anaconda2\\lib\\site-packages\\twitterscraper\\query.py\", line 93, in query_tweets_once\n",
      "    pos is None\n",
      "  File \"C:\\ProgramData\\Anaconda2\\lib\\site-packages\\twitterscraper\\query.py\", line 53, in query_single_page\n",
      "    except requests.exception.ConnectionError as e:\n",
      "AttributeError: 'module' object has no attribute 'exception'\n",
      "ERROR:root:An unknown error occurred! Returning tweets gathered so far.\n",
      "Traceback (most recent call last):\n",
      "  File \"C:\\ProgramData\\Anaconda2\\lib\\site-packages\\twitterscraper\\query.py\", line 93, in query_tweets_once\n",
      "    pos is None\n",
      "  File \"C:\\ProgramData\\Anaconda2\\lib\\site-packages\\twitterscraper\\query.py\", line 53, in query_single_page\n",
      "    except requests.exception.ConnectionError as e:\n",
      "AttributeError: 'module' object has no attribute 'exception'\n",
      "ERROR:root:An unknown error occurred! Returning tweets gathered so far.\n",
      "Traceback (most recent call last):\n",
      "  File \"C:\\ProgramData\\Anaconda2\\lib\\site-packages\\twitterscraper\\query.py\", line 93, in query_tweets_once\n",
      "    pos is None\n",
      "  File \"C:\\ProgramData\\Anaconda2\\lib\\site-packages\\twitterscraper\\query.py\", line 53, in query_single_page\n",
      "    except requests.exception.ConnectionError as e:\n",
      "AttributeError: 'module' object has no attribute 'exception'\n",
      "ERROR:root:An unknown error occurred! Returning tweets gathered so far.\n",
      "Traceback (most recent call last):\n",
      "  File \"C:\\ProgramData\\Anaconda2\\lib\\site-packages\\twitterscraper\\query.py\", line 93, in query_tweets_once\n",
      "    pos is None\n",
      "  File \"C:\\ProgramData\\Anaconda2\\lib\\site-packages\\twitterscraper\\query.py\", line 53, in query_single_page\n",
      "    except requests.exception.ConnectionError as e:\n",
      "AttributeError: 'module' object has no attribute 'exception'\n",
      "ERROR:root:An unknown error occurred! Returning tweets gathered so far.\n",
      "Traceback (most recent call last):\n",
      "  File \"C:\\ProgramData\\Anaconda2\\lib\\site-packages\\twitterscraper\\query.py\", line 93, in query_tweets_once\n",
      "    pos is None\n",
      "  File \"C:\\ProgramData\\Anaconda2\\lib\\site-packages\\twitterscraper\\query.py\", line 53, in query_single_page\n",
      "    except requests.exception.ConnectionError as e:\n",
      "AttributeError: 'module' object has no attribute 'exception'\n",
      "ERROR:root:An unknown error occurred! Returning tweets gathered so far.\n",
      "Traceback (most recent call last):\n",
      "  File \"C:\\ProgramData\\Anaconda2\\lib\\site-packages\\twitterscraper\\query.py\", line 93, in query_tweets_once\n",
      "    pos is None\n",
      "  File \"C:\\ProgramData\\Anaconda2\\lib\\site-packages\\twitterscraper\\query.py\", line 53, in query_single_page\n",
      "    except requests.exception.ConnectionError as e:\n",
      "AttributeError: 'module' object has no attribute 'exception'\n",
      "ERROR:root:An unknown error occurred! Returning tweets gathered so far.\n",
      "Traceback (most recent call last):\n",
      "  File \"C:\\ProgramData\\Anaconda2\\lib\\site-packages\\twitterscraper\\query.py\", line 93, in query_tweets_once\n",
      "    pos is None\n",
      "  File \"C:\\ProgramData\\Anaconda2\\lib\\site-packages\\twitterscraper\\query.py\", line 53, in query_single_page\n",
      "    except requests.exception.ConnectionError as e:\n",
      "AttributeError: 'module' object has no attribute 'exception'\n",
      "ERROR:root:An unknown error occurred! Returning tweets gathered so far.\n",
      "Traceback (most recent call last):\n",
      "  File \"C:\\ProgramData\\Anaconda2\\lib\\site-packages\\twitterscraper\\query.py\", line 93, in query_tweets_once\n",
      "    pos is None\n",
      "  File \"C:\\ProgramData\\Anaconda2\\lib\\site-packages\\twitterscraper\\query.py\", line 53, in query_single_page\n",
      "    except requests.exception.ConnectionError as e:\n",
      "AttributeError: 'module' object has no attribute 'exception'\n",
      "ERROR:root:An unknown error occurred! Returning tweets gathered so far.\n",
      "Traceback (most recent call last):\n",
      "  File \"C:\\ProgramData\\Anaconda2\\lib\\site-packages\\twitterscraper\\query.py\", line 93, in query_tweets_once\n",
      "    pos is None\n",
      "  File \"C:\\ProgramData\\Anaconda2\\lib\\site-packages\\twitterscraper\\query.py\", line 53, in query_single_page\n",
      "    except requests.exception.ConnectionError as e:\n",
      "AttributeError: 'module' object has no attribute 'exception'\n",
      "ERROR:root:An unknown error occurred! Returning tweets gathered so far.\n",
      "Traceback (most recent call last):\n",
      "  File \"C:\\ProgramData\\Anaconda2\\lib\\site-packages\\twitterscraper\\query.py\", line 93, in query_tweets_once\n",
      "    pos is None\n",
      "  File \"C:\\ProgramData\\Anaconda2\\lib\\site-packages\\twitterscraper\\query.py\", line 53, in query_single_page\n",
      "    except requests.exception.ConnectionError as e:\n",
      "AttributeError: 'module' object has no attribute 'exception'\n",
      "ERROR:root:An unknown error occurred! Returning tweets gathered so far.\n",
      "Traceback (most recent call last):\n",
      "  File \"C:\\ProgramData\\Anaconda2\\lib\\site-packages\\twitterscraper\\query.py\", line 93, in query_tweets_once\n",
      "    pos is None\n",
      "  File \"C:\\ProgramData\\Anaconda2\\lib\\site-packages\\twitterscraper\\query.py\", line 53, in query_single_page\n",
      "    except requests.exception.ConnectionError as e:\n",
      "AttributeError: 'module' object has no attribute 'exception'\n",
      "ERROR:root:An unknown error occurred! Returning tweets gathered so far.\n",
      "Traceback (most recent call last):\n",
      "  File \"C:\\ProgramData\\Anaconda2\\lib\\site-packages\\twitterscraper\\query.py\", line 93, in query_tweets_once\n",
      "    pos is None\n",
      "  File \"C:\\ProgramData\\Anaconda2\\lib\\site-packages\\twitterscraper\\query.py\", line 53, in query_single_page\n",
      "    except requests.exception.ConnectionError as e:\n",
      "AttributeError: 'module' object has no attribute 'exception'\n",
      "ERROR:root:An unknown error occurred! Returning tweets gathered so far.\n",
      "Traceback (most recent call last):\n",
      "  File \"C:\\ProgramData\\Anaconda2\\lib\\site-packages\\twitterscraper\\query.py\", line 93, in query_tweets_once\n",
      "    pos is None\n",
      "  File \"C:\\ProgramData\\Anaconda2\\lib\\site-packages\\twitterscraper\\query.py\", line 53, in query_single_page\n",
      "    except requests.exception.ConnectionError as e:\n",
      "AttributeError: 'module' object has no attribute 'exception'\n",
      "ERROR:root:An unknown error occurred! Returning tweets gathered so far.\n",
      "Traceback (most recent call last):\n",
      "  File \"C:\\ProgramData\\Anaconda2\\lib\\site-packages\\twitterscraper\\query.py\", line 93, in query_tweets_once\n",
      "    pos is None\n",
      "  File \"C:\\ProgramData\\Anaconda2\\lib\\site-packages\\twitterscraper\\query.py\", line 53, in query_single_page\n",
      "    except requests.exception.ConnectionError as e:\n",
      "AttributeError: 'module' object has no attribute 'exception'\n",
      "ERROR:root:An unknown error occurred! Returning tweets gathered so far.\n",
      "Traceback (most recent call last):\n",
      "  File \"C:\\ProgramData\\Anaconda2\\lib\\site-packages\\twitterscraper\\query.py\", line 93, in query_tweets_once\n",
      "    pos is None\n",
      "  File \"C:\\ProgramData\\Anaconda2\\lib\\site-packages\\twitterscraper\\query.py\", line 53, in query_single_page\n",
      "    except requests.exception.ConnectionError as e:\n",
      "AttributeError: 'module' object has no attribute 'exception'\n",
      "ERROR:root:An unknown error occurred! Returning tweets gathered so far.\n",
      "Traceback (most recent call last):\n",
      "  File \"C:\\ProgramData\\Anaconda2\\lib\\site-packages\\twitterscraper\\query.py\", line 93, in query_tweets_once\n",
      "    pos is None\n",
      "  File \"C:\\ProgramData\\Anaconda2\\lib\\site-packages\\twitterscraper\\query.py\", line 53, in query_single_page\n",
      "    except requests.exception.ConnectionError as e:\n",
      "AttributeError: 'module' object has no attribute 'exception'\n",
      "ERROR:root:An unknown error occurred! Returning tweets gathered so far.\n",
      "Traceback (most recent call last):\n",
      "  File \"C:\\ProgramData\\Anaconda2\\lib\\site-packages\\twitterscraper\\query.py\", line 93, in query_tweets_once\n",
      "    pos is None\n",
      "  File \"C:\\ProgramData\\Anaconda2\\lib\\site-packages\\twitterscraper\\query.py\", line 53, in query_single_page\n",
      "    except requests.exception.ConnectionError as e:\n",
      "AttributeError: 'module' object has no attribute 'exception'\n",
      "ERROR:root:An unknown error occurred! Returning tweets gathered so far.\n",
      "Traceback (most recent call last):\n",
      "  File \"C:\\ProgramData\\Anaconda2\\lib\\site-packages\\twitterscraper\\query.py\", line 93, in query_tweets_once\n",
      "    pos is None\n",
      "  File \"C:\\ProgramData\\Anaconda2\\lib\\site-packages\\twitterscraper\\query.py\", line 53, in query_single_page\n",
      "    except requests.exception.ConnectionError as e:\n",
      "AttributeError: 'module' object has no attribute 'exception'\n",
      "ERROR:root:An unknown error occurred! Returning tweets gathered so far.\n",
      "Traceback (most recent call last):\n",
      "  File \"C:\\ProgramData\\Anaconda2\\lib\\site-packages\\twitterscraper\\query.py\", line 93, in query_tweets_once\n",
      "    pos is None\n",
      "  File \"C:\\ProgramData\\Anaconda2\\lib\\site-packages\\twitterscraper\\query.py\", line 53, in query_single_page\n",
      "    except requests.exception.ConnectionError as e:\n",
      "AttributeError: 'module' object has no attribute 'exception'\n",
      "ERROR:root:An unknown error occurred! Returning tweets gathered so far.\n",
      "Traceback (most recent call last):\n",
      "  File \"C:\\ProgramData\\Anaconda2\\lib\\site-packages\\twitterscraper\\query.py\", line 93, in query_tweets_once\n",
      "    pos is None\n",
      "  File \"C:\\ProgramData\\Anaconda2\\lib\\site-packages\\twitterscraper\\query.py\", line 53, in query_single_page\n",
      "    except requests.exception.ConnectionError as e:\n",
      "AttributeError: 'module' object has no attribute 'exception'\n",
      "ERROR:root:An unknown error occurred! Returning tweets gathered so far.\n",
      "Traceback (most recent call last):\n",
      "  File \"C:\\ProgramData\\Anaconda2\\lib\\site-packages\\twitterscraper\\query.py\", line 93, in query_tweets_once\n",
      "    pos is None\n",
      "  File \"C:\\ProgramData\\Anaconda2\\lib\\site-packages\\twitterscraper\\query.py\", line 53, in query_single_page\n",
      "    except requests.exception.ConnectionError as e:\n",
      "AttributeError: 'module' object has no attribute 'exception'\n",
      "ERROR:root:An unknown error occurred! Returning tweets gathered so far.\n",
      "Traceback (most recent call last):\n",
      "  File \"C:\\ProgramData\\Anaconda2\\lib\\site-packages\\twitterscraper\\query.py\", line 93, in query_tweets_once\n",
      "    pos is None\n",
      "  File \"C:\\ProgramData\\Anaconda2\\lib\\site-packages\\twitterscraper\\query.py\", line 53, in query_single_page\n",
      "    except requests.exception.ConnectionError as e:\n",
      "AttributeError: 'module' object has no attribute 'exception'\n",
      "ERROR:root:An unknown error occurred! Returning tweets gathered so far.\n",
      "Traceback (most recent call last):\n",
      "  File \"C:\\ProgramData\\Anaconda2\\lib\\site-packages\\twitterscraper\\query.py\", line 93, in query_tweets_once\n",
      "    pos is None\n",
      "  File \"C:\\ProgramData\\Anaconda2\\lib\\site-packages\\twitterscraper\\query.py\", line 53, in query_single_page\n",
      "    except requests.exception.ConnectionError as e:\n",
      "AttributeError: 'module' object has no attribute 'exception'\n",
      "ERROR:root:An unknown error occurred! Returning tweets gathered so far.\n",
      "Traceback (most recent call last):\n",
      "  File \"C:\\ProgramData\\Anaconda2\\lib\\site-packages\\twitterscraper\\query.py\", line 93, in query_tweets_once\n",
      "    pos is None\n",
      "  File \"C:\\ProgramData\\Anaconda2\\lib\\site-packages\\twitterscraper\\query.py\", line 53, in query_single_page\n",
      "    except requests.exception.ConnectionError as e:\n",
      "AttributeError: 'module' object has no attribute 'exception'\n",
      "ERROR:root:An unknown error occurred! Returning tweets gathered so far.\n",
      "Traceback (most recent call last):\n",
      "  File \"C:\\ProgramData\\Anaconda2\\lib\\site-packages\\twitterscraper\\query.py\", line 93, in query_tweets_once\n",
      "    pos is None\n",
      "  File \"C:\\ProgramData\\Anaconda2\\lib\\site-packages\\twitterscraper\\query.py\", line 53, in query_single_page\n",
      "    except requests.exception.ConnectionError as e:\n",
      "AttributeError: 'module' object has no attribute 'exception'\n",
      "ERROR:root:An unknown error occurred! Returning tweets gathered so far.\n",
      "Traceback (most recent call last):\n",
      "  File \"C:\\ProgramData\\Anaconda2\\lib\\site-packages\\twitterscraper\\query.py\", line 93, in query_tweets_once\n",
      "    pos is None\n",
      "  File \"C:\\ProgramData\\Anaconda2\\lib\\site-packages\\twitterscraper\\query.py\", line 53, in query_single_page\n",
      "    except requests.exception.ConnectionError as e:\n",
      "AttributeError: 'module' object has no attribute 'exception'\n",
      "ERROR:root:An unknown error occurred! Returning tweets gathered so far.\n",
      "Traceback (most recent call last):\n",
      "  File \"C:\\ProgramData\\Anaconda2\\lib\\site-packages\\twitterscraper\\query.py\", line 93, in query_tweets_once\n",
      "    pos is None\n",
      "  File \"C:\\ProgramData\\Anaconda2\\lib\\site-packages\\twitterscraper\\query.py\", line 53, in query_single_page\n",
      "    except requests.exception.ConnectionError as e:\n",
      "AttributeError: 'module' object has no attribute 'exception'\n",
      "ERROR:root:An unknown error occurred! Returning tweets gathered so far.\n",
      "Traceback (most recent call last):\n",
      "  File \"C:\\ProgramData\\Anaconda2\\lib\\site-packages\\twitterscraper\\query.py\", line 93, in query_tweets_once\n",
      "    pos is None\n",
      "  File \"C:\\ProgramData\\Anaconda2\\lib\\site-packages\\twitterscraper\\query.py\", line 53, in query_single_page\n",
      "    except requests.exception.ConnectionError as e:\n",
      "AttributeError: 'module' object has no attribute 'exception'\n",
      "ERROR:root:An unknown error occurred! Returning tweets gathered so far.\n",
      "Traceback (most recent call last):\n",
      "  File \"C:\\ProgramData\\Anaconda2\\lib\\site-packages\\twitterscraper\\query.py\", line 93, in query_tweets_once\n",
      "    pos is None\n",
      "  File \"C:\\ProgramData\\Anaconda2\\lib\\site-packages\\twitterscraper\\query.py\", line 53, in query_single_page\n",
      "    except requests.exception.ConnectionError as e:\n",
      "AttributeError: 'module' object has no attribute 'exception'\n",
      "ERROR:root:An unknown error occurred! Returning tweets gathered so far.\n",
      "Traceback (most recent call last):\n",
      "  File \"C:\\ProgramData\\Anaconda2\\lib\\site-packages\\twitterscraper\\query.py\", line 93, in query_tweets_once\n",
      "    pos is None\n",
      "  File \"C:\\ProgramData\\Anaconda2\\lib\\site-packages\\twitterscraper\\query.py\", line 53, in query_single_page\n",
      "    except requests.exception.ConnectionError as e:\n",
      "AttributeError: 'module' object has no attribute 'exception'\n",
      "ERROR:root:An unknown error occurred! Returning tweets gathered so far.\n",
      "Traceback (most recent call last):\n",
      "  File \"C:\\ProgramData\\Anaconda2\\lib\\site-packages\\twitterscraper\\query.py\", line 93, in query_tweets_once\n",
      "    pos is None\n",
      "  File \"C:\\ProgramData\\Anaconda2\\lib\\site-packages\\twitterscraper\\query.py\", line 53, in query_single_page\n",
      "    except requests.exception.ConnectionError as e:\n",
      "AttributeError: 'module' object has no attribute 'exception'\n",
      "ERROR:root:An unknown error occurred! Returning tweets gathered so far.\n",
      "Traceback (most recent call last):\n",
      "  File \"C:\\ProgramData\\Anaconda2\\lib\\site-packages\\twitterscraper\\query.py\", line 93, in query_tweets_once\n",
      "    pos is None\n",
      "  File \"C:\\ProgramData\\Anaconda2\\lib\\site-packages\\twitterscraper\\query.py\", line 53, in query_single_page\n",
      "    except requests.exception.ConnectionError as e:\n",
      "AttributeError: 'module' object has no attribute 'exception'\n",
      "ERROR:root:An unknown error occurred! Returning tweets gathered so far.\n",
      "Traceback (most recent call last):\n",
      "  File \"C:\\ProgramData\\Anaconda2\\lib\\site-packages\\twitterscraper\\query.py\", line 93, in query_tweets_once\n",
      "    pos is None\n",
      "  File \"C:\\ProgramData\\Anaconda2\\lib\\site-packages\\twitterscraper\\query.py\", line 53, in query_single_page\n",
      "    except requests.exception.ConnectionError as e:\n",
      "AttributeError: 'module' object has no attribute 'exception'\n",
      "ERROR:root:An unknown error occurred! Returning tweets gathered so far.\n",
      "Traceback (most recent call last):\n",
      "  File \"C:\\ProgramData\\Anaconda2\\lib\\site-packages\\twitterscraper\\query.py\", line 93, in query_tweets_once\n",
      "    pos is None\n",
      "  File \"C:\\ProgramData\\Anaconda2\\lib\\site-packages\\twitterscraper\\query.py\", line 53, in query_single_page\n",
      "    except requests.exception.ConnectionError as e:\n",
      "AttributeError: 'module' object has no attribute 'exception'\n",
      "ERROR:root:An unknown error occurred! Returning tweets gathered so far.\n",
      "Traceback (most recent call last):\n",
      "  File \"C:\\ProgramData\\Anaconda2\\lib\\site-packages\\twitterscraper\\query.py\", line 93, in query_tweets_once\n",
      "    pos is None\n",
      "  File \"C:\\ProgramData\\Anaconda2\\lib\\site-packages\\twitterscraper\\query.py\", line 53, in query_single_page\n",
      "    except requests.exception.ConnectionError as e:\n",
      "AttributeError: 'module' object has no attribute 'exception'\n",
      "ERROR:root:An unknown error occurred! Returning tweets gathered so far.\n",
      "Traceback (most recent call last):\n",
      "  File \"C:\\ProgramData\\Anaconda2\\lib\\site-packages\\twitterscraper\\query.py\", line 93, in query_tweets_once\n",
      "    pos is None\n",
      "  File \"C:\\ProgramData\\Anaconda2\\lib\\site-packages\\twitterscraper\\query.py\", line 53, in query_single_page\n",
      "    except requests.exception.ConnectionError as e:\n",
      "AttributeError: 'module' object has no attribute 'exception'\n",
      "ERROR:root:An unknown error occurred! Returning tweets gathered so far.\n",
      "Traceback (most recent call last):\n",
      "  File \"C:\\ProgramData\\Anaconda2\\lib\\site-packages\\twitterscraper\\query.py\", line 93, in query_tweets_once\n",
      "    pos is None\n",
      "  File \"C:\\ProgramData\\Anaconda2\\lib\\site-packages\\twitterscraper\\query.py\", line 53, in query_single_page\n",
      "    except requests.exception.ConnectionError as e:\n",
      "AttributeError: 'module' object has no attribute 'exception'\n",
      "ERROR:root:An unknown error occurred! Returning tweets gathered so far.\n",
      "Traceback (most recent call last):\n",
      "  File \"C:\\ProgramData\\Anaconda2\\lib\\site-packages\\twitterscraper\\query.py\", line 93, in query_tweets_once\n",
      "    pos is None\n",
      "  File \"C:\\ProgramData\\Anaconda2\\lib\\site-packages\\twitterscraper\\query.py\", line 53, in query_single_page\n",
      "    except requests.exception.ConnectionError as e:\n",
      "AttributeError: 'module' object has no attribute 'exception'\n",
      "ERROR:root:An unknown error occurred! Returning tweets gathered so far.\n",
      "Traceback (most recent call last):\n",
      "  File \"C:\\ProgramData\\Anaconda2\\lib\\site-packages\\twitterscraper\\query.py\", line 93, in query_tweets_once\n",
      "    pos is None\n",
      "  File \"C:\\ProgramData\\Anaconda2\\lib\\site-packages\\twitterscraper\\query.py\", line 53, in query_single_page\n",
      "    except requests.exception.ConnectionError as e:\n",
      "AttributeError: 'module' object has no attribute 'exception'\n",
      "ERROR:root:An unknown error occurred! Returning tweets gathered so far.\n",
      "Traceback (most recent call last):\n",
      "  File \"C:\\ProgramData\\Anaconda2\\lib\\site-packages\\twitterscraper\\query.py\", line 93, in query_tweets_once\n",
      "    pos is None\n",
      "  File \"C:\\ProgramData\\Anaconda2\\lib\\site-packages\\twitterscraper\\query.py\", line 53, in query_single_page\n",
      "    except requests.exception.ConnectionError as e:\n",
      "AttributeError: 'module' object has no attribute 'exception'\n",
      "ERROR:root:An unknown error occurred! Returning tweets gathered so far.\n",
      "Traceback (most recent call last):\n",
      "  File \"C:\\ProgramData\\Anaconda2\\lib\\site-packages\\twitterscraper\\query.py\", line 93, in query_tweets_once\n",
      "    pos is None\n",
      "  File \"C:\\ProgramData\\Anaconda2\\lib\\site-packages\\twitterscraper\\query.py\", line 53, in query_single_page\n",
      "    except requests.exception.ConnectionError as e:\n",
      "AttributeError: 'module' object has no attribute 'exception'\n",
      "ERROR:root:An unknown error occurred! Returning tweets gathered so far.\n",
      "Traceback (most recent call last):\n",
      "  File \"C:\\ProgramData\\Anaconda2\\lib\\site-packages\\twitterscraper\\query.py\", line 93, in query_tweets_once\n",
      "    pos is None\n",
      "  File \"C:\\ProgramData\\Anaconda2\\lib\\site-packages\\twitterscraper\\query.py\", line 53, in query_single_page\n",
      "    except requests.exception.ConnectionError as e:\n",
      "AttributeError: 'module' object has no attribute 'exception'\n",
      "ERROR:root:An unknown error occurred! Returning tweets gathered so far.\n",
      "Traceback (most recent call last):\n",
      "  File \"C:\\ProgramData\\Anaconda2\\lib\\site-packages\\twitterscraper\\query.py\", line 93, in query_tweets_once\n",
      "    pos is None\n",
      "  File \"C:\\ProgramData\\Anaconda2\\lib\\site-packages\\twitterscraper\\query.py\", line 53, in query_single_page\n",
      "    except requests.exception.ConnectionError as e:\n",
      "AttributeError: 'module' object has no attribute 'exception'\n",
      "ERROR:root:An unknown error occurred! Returning tweets gathered so far.\n",
      "Traceback (most recent call last):\n",
      "  File \"C:\\ProgramData\\Anaconda2\\lib\\site-packages\\twitterscraper\\query.py\", line 93, in query_tweets_once\n",
      "    pos is None\n",
      "  File \"C:\\ProgramData\\Anaconda2\\lib\\site-packages\\twitterscraper\\query.py\", line 53, in query_single_page\n",
      "    except requests.exception.ConnectionError as e:\n",
      "AttributeError: 'module' object has no attribute 'exception'\n",
      "ERROR:root:An unknown error occurred! Returning tweets gathered so far.\n",
      "Traceback (most recent call last):\n",
      "  File \"C:\\ProgramData\\Anaconda2\\lib\\site-packages\\twitterscraper\\query.py\", line 93, in query_tweets_once\n",
      "    pos is None\n",
      "  File \"C:\\ProgramData\\Anaconda2\\lib\\site-packages\\twitterscraper\\query.py\", line 53, in query_single_page\n",
      "    except requests.exception.ConnectionError as e:\n",
      "AttributeError: 'module' object has no attribute 'exception'\n",
      "ERROR:root:An unknown error occurred! Returning tweets gathered so far.\n",
      "Traceback (most recent call last):\n",
      "  File \"C:\\ProgramData\\Anaconda2\\lib\\site-packages\\twitterscraper\\query.py\", line 93, in query_tweets_once\n",
      "    pos is None\n",
      "  File \"C:\\ProgramData\\Anaconda2\\lib\\site-packages\\twitterscraper\\query.py\", line 53, in query_single_page\n",
      "    except requests.exception.ConnectionError as e:\n",
      "AttributeError: 'module' object has no attribute 'exception'\n",
      "ERROR:root:An unknown error occurred! Returning tweets gathered so far.\n",
      "Traceback (most recent call last):\n",
      "  File \"C:\\ProgramData\\Anaconda2\\lib\\site-packages\\twitterscraper\\query.py\", line 93, in query_tweets_once\n",
      "    pos is None\n",
      "  File \"C:\\ProgramData\\Anaconda2\\lib\\site-packages\\twitterscraper\\query.py\", line 53, in query_single_page\n",
      "    except requests.exception.ConnectionError as e:\n",
      "AttributeError: 'module' object has no attribute 'exception'\n",
      "ERROR:root:An unknown error occurred! Returning tweets gathered so far.\n",
      "Traceback (most recent call last):\n",
      "  File \"C:\\ProgramData\\Anaconda2\\lib\\site-packages\\twitterscraper\\query.py\", line 93, in query_tweets_once\n",
      "    pos is None\n",
      "  File \"C:\\ProgramData\\Anaconda2\\lib\\site-packages\\twitterscraper\\query.py\", line 53, in query_single_page\n",
      "    except requests.exception.ConnectionError as e:\n",
      "AttributeError: 'module' object has no attribute 'exception'\n",
      "ERROR:root:An unknown error occurred! Returning tweets gathered so far.\n",
      "Traceback (most recent call last):\n",
      "  File \"C:\\ProgramData\\Anaconda2\\lib\\site-packages\\twitterscraper\\query.py\", line 93, in query_tweets_once\n",
      "    pos is None\n",
      "  File \"C:\\ProgramData\\Anaconda2\\lib\\site-packages\\twitterscraper\\query.py\", line 53, in query_single_page\n",
      "    except requests.exception.ConnectionError as e:\n",
      "AttributeError: 'module' object has no attribute 'exception'\n",
      "ERROR:root:An unknown error occurred! Returning tweets gathered so far.\n",
      "Traceback (most recent call last):\n",
      "  File \"C:\\ProgramData\\Anaconda2\\lib\\site-packages\\twitterscraper\\query.py\", line 93, in query_tweets_once\n",
      "    pos is None\n",
      "  File \"C:\\ProgramData\\Anaconda2\\lib\\site-packages\\twitterscraper\\query.py\", line 53, in query_single_page\n",
      "    except requests.exception.ConnectionError as e:\n",
      "AttributeError: 'module' object has no attribute 'exception'\n",
      "ERROR:root:An unknown error occurred! Returning tweets gathered so far.\n",
      "Traceback (most recent call last):\n",
      "  File \"C:\\ProgramData\\Anaconda2\\lib\\site-packages\\twitterscraper\\query.py\", line 93, in query_tweets_once\n",
      "    pos is None\n",
      "  File \"C:\\ProgramData\\Anaconda2\\lib\\site-packages\\twitterscraper\\query.py\", line 53, in query_single_page\n",
      "    except requests.exception.ConnectionError as e:\n",
      "AttributeError: 'module' object has no attribute 'exception'\n",
      "ERROR:root:An unknown error occurred! Returning tweets gathered so far.\n",
      "Traceback (most recent call last):\n",
      "  File \"C:\\ProgramData\\Anaconda2\\lib\\site-packages\\twitterscraper\\query.py\", line 93, in query_tweets_once\n",
      "    pos is None\n",
      "  File \"C:\\ProgramData\\Anaconda2\\lib\\site-packages\\twitterscraper\\query.py\", line 53, in query_single_page\n",
      "    except requests.exception.ConnectionError as e:\n",
      "AttributeError: 'module' object has no attribute 'exception'\n",
      "ERROR:root:An unknown error occurred! Returning tweets gathered so far.\n",
      "Traceback (most recent call last):\n",
      "  File \"C:\\ProgramData\\Anaconda2\\lib\\site-packages\\twitterscraper\\query.py\", line 93, in query_tweets_once\n",
      "    pos is None\n",
      "  File \"C:\\ProgramData\\Anaconda2\\lib\\site-packages\\twitterscraper\\query.py\", line 53, in query_single_page\n",
      "    except requests.exception.ConnectionError as e:\n",
      "AttributeError: 'module' object has no attribute 'exception'\n",
      "ERROR:root:An unknown error occurred! Returning tweets gathered so far.\n",
      "Traceback (most recent call last):\n",
      "  File \"C:\\ProgramData\\Anaconda2\\lib\\site-packages\\twitterscraper\\query.py\", line 93, in query_tweets_once\n",
      "    pos is None\n",
      "  File \"C:\\ProgramData\\Anaconda2\\lib\\site-packages\\twitterscraper\\query.py\", line 53, in query_single_page\n",
      "    except requests.exception.ConnectionError as e:\n",
      "AttributeError: 'module' object has no attribute 'exception'\n",
      "ERROR:root:An unknown error occurred! Returning tweets gathered so far.\n",
      "Traceback (most recent call last):\n",
      "  File \"C:\\ProgramData\\Anaconda2\\lib\\site-packages\\twitterscraper\\query.py\", line 93, in query_tweets_once\n",
      "    pos is None\n",
      "  File \"C:\\ProgramData\\Anaconda2\\lib\\site-packages\\twitterscraper\\query.py\", line 53, in query_single_page\n",
      "    except requests.exception.ConnectionError as e:\n",
      "AttributeError: 'module' object has no attribute 'exception'\n",
      "ERROR:root:An unknown error occurred! Returning tweets gathered so far.\n",
      "Traceback (most recent call last):\n",
      "  File \"C:\\ProgramData\\Anaconda2\\lib\\site-packages\\twitterscraper\\query.py\", line 93, in query_tweets_once\n",
      "    pos is None\n",
      "  File \"C:\\ProgramData\\Anaconda2\\lib\\site-packages\\twitterscraper\\query.py\", line 53, in query_single_page\n",
      "    except requests.exception.ConnectionError as e:\n",
      "AttributeError: 'module' object has no attribute 'exception'\n",
      "ERROR:root:An unknown error occurred! Returning tweets gathered so far.\n",
      "Traceback (most recent call last):\n",
      "  File \"C:\\ProgramData\\Anaconda2\\lib\\site-packages\\twitterscraper\\query.py\", line 93, in query_tweets_once\n",
      "    pos is None\n",
      "  File \"C:\\ProgramData\\Anaconda2\\lib\\site-packages\\twitterscraper\\query.py\", line 53, in query_single_page\n",
      "    except requests.exception.ConnectionError as e:\n",
      "AttributeError: 'module' object has no attribute 'exception'\n",
      "ERROR:root:An unknown error occurred! Returning tweets gathered so far.\n",
      "Traceback (most recent call last):\n",
      "  File \"C:\\ProgramData\\Anaconda2\\lib\\site-packages\\twitterscraper\\query.py\", line 93, in query_tweets_once\n",
      "    pos is None\n",
      "  File \"C:\\ProgramData\\Anaconda2\\lib\\site-packages\\twitterscraper\\query.py\", line 53, in query_single_page\n",
      "    except requests.exception.ConnectionError as e:\n",
      "AttributeError: 'module' object has no attribute 'exception'\n",
      "ERROR:root:An unknown error occurred! Returning tweets gathered so far.\n",
      "Traceback (most recent call last):\n",
      "  File \"C:\\ProgramData\\Anaconda2\\lib\\site-packages\\twitterscraper\\query.py\", line 93, in query_tweets_once\n",
      "    pos is None\n",
      "  File \"C:\\ProgramData\\Anaconda2\\lib\\site-packages\\twitterscraper\\query.py\", line 53, in query_single_page\n",
      "    except requests.exception.ConnectionError as e:\n",
      "AttributeError: 'module' object has no attribute 'exception'\n",
      "ERROR:root:An unknown error occurred! Returning tweets gathered so far.\n",
      "Traceback (most recent call last):\n",
      "  File \"C:\\ProgramData\\Anaconda2\\lib\\site-packages\\twitterscraper\\query.py\", line 93, in query_tweets_once\n",
      "    pos is None\n",
      "  File \"C:\\ProgramData\\Anaconda2\\lib\\site-packages\\twitterscraper\\query.py\", line 53, in query_single_page\n",
      "    except requests.exception.ConnectionError as e:\n",
      "AttributeError: 'module' object has no attribute 'exception'\n",
      "ERROR:root:An unknown error occurred! Returning tweets gathered so far.\n",
      "Traceback (most recent call last):\n",
      "  File \"C:\\ProgramData\\Anaconda2\\lib\\site-packages\\twitterscraper\\query.py\", line 93, in query_tweets_once\n",
      "    pos is None\n",
      "  File \"C:\\ProgramData\\Anaconda2\\lib\\site-packages\\twitterscraper\\query.py\", line 53, in query_single_page\n",
      "    except requests.exception.ConnectionError as e:\n",
      "AttributeError: 'module' object has no attribute 'exception'\n",
      "ERROR:root:An unknown error occurred! Returning tweets gathered so far.\n",
      "Traceback (most recent call last):\n",
      "  File \"C:\\ProgramData\\Anaconda2\\lib\\site-packages\\twitterscraper\\query.py\", line 93, in query_tweets_once\n",
      "    pos is None\n",
      "  File \"C:\\ProgramData\\Anaconda2\\lib\\site-packages\\twitterscraper\\query.py\", line 53, in query_single_page\n",
      "    except requests.exception.ConnectionError as e:\n",
      "AttributeError: 'module' object has no attribute 'exception'\n",
      "ERROR:root:An unknown error occurred! Returning tweets gathered so far.\n",
      "Traceback (most recent call last):\n",
      "  File \"C:\\ProgramData\\Anaconda2\\lib\\site-packages\\twitterscraper\\query.py\", line 93, in query_tweets_once\n",
      "    pos is None\n",
      "  File \"C:\\ProgramData\\Anaconda2\\lib\\site-packages\\twitterscraper\\query.py\", line 53, in query_single_page\n",
      "    except requests.exception.ConnectionError as e:\n",
      "AttributeError: 'module' object has no attribute 'exception'\n",
      "ERROR:root:An unknown error occurred! Returning tweets gathered so far.\n",
      "Traceback (most recent call last):\n",
      "  File \"C:\\ProgramData\\Anaconda2\\lib\\site-packages\\twitterscraper\\query.py\", line 93, in query_tweets_once\n",
      "    pos is None\n",
      "  File \"C:\\ProgramData\\Anaconda2\\lib\\site-packages\\twitterscraper\\query.py\", line 53, in query_single_page\n",
      "    except requests.exception.ConnectionError as e:\n",
      "AttributeError: 'module' object has no attribute 'exception'\n",
      "ERROR:root:An unknown error occurred! Returning tweets gathered so far.\n",
      "Traceback (most recent call last):\n",
      "  File \"C:\\ProgramData\\Anaconda2\\lib\\site-packages\\twitterscraper\\query.py\", line 93, in query_tweets_once\n",
      "    pos is None\n",
      "  File \"C:\\ProgramData\\Anaconda2\\lib\\site-packages\\twitterscraper\\query.py\", line 53, in query_single_page\n",
      "    except requests.exception.ConnectionError as e:\n",
      "AttributeError: 'module' object has no attribute 'exception'\n",
      "ERROR:root:An unknown error occurred! Returning tweets gathered so far.\n",
      "Traceback (most recent call last):\n",
      "  File \"C:\\ProgramData\\Anaconda2\\lib\\site-packages\\twitterscraper\\query.py\", line 93, in query_tweets_once\n",
      "    pos is None\n",
      "  File \"C:\\ProgramData\\Anaconda2\\lib\\site-packages\\twitterscraper\\query.py\", line 53, in query_single_page\n",
      "    except requests.exception.ConnectionError as e:\n",
      "AttributeError: 'module' object has no attribute 'exception'\n",
      "ERROR:root:An unknown error occurred! Returning tweets gathered so far.\n",
      "Traceback (most recent call last):\n",
      "  File \"C:\\ProgramData\\Anaconda2\\lib\\site-packages\\twitterscraper\\query.py\", line 93, in query_tweets_once\n",
      "    pos is None\n",
      "  File \"C:\\ProgramData\\Anaconda2\\lib\\site-packages\\twitterscraper\\query.py\", line 53, in query_single_page\n",
      "    except requests.exception.ConnectionError as e:\n",
      "AttributeError: 'module' object has no attribute 'exception'\n",
      "ERROR:root:An unknown error occurred! Returning tweets gathered so far.\n",
      "Traceback (most recent call last):\n",
      "  File \"C:\\ProgramData\\Anaconda2\\lib\\site-packages\\twitterscraper\\query.py\", line 93, in query_tweets_once\n",
      "    pos is None\n",
      "  File \"C:\\ProgramData\\Anaconda2\\lib\\site-packages\\twitterscraper\\query.py\", line 53, in query_single_page\n",
      "    except requests.exception.ConnectionError as e:\n",
      "AttributeError: 'module' object has no attribute 'exception'\n",
      "ERROR:root:An unknown error occurred! Returning tweets gathered so far.\n",
      "Traceback (most recent call last):\n",
      "  File \"C:\\ProgramData\\Anaconda2\\lib\\site-packages\\twitterscraper\\query.py\", line 93, in query_tweets_once\n",
      "    pos is None\n",
      "  File \"C:\\ProgramData\\Anaconda2\\lib\\site-packages\\twitterscraper\\query.py\", line 53, in query_single_page\n",
      "    except requests.exception.ConnectionError as e:\n",
      "AttributeError: 'module' object has no attribute 'exception'\n",
      "ERROR:root:An unknown error occurred! Returning tweets gathered so far.\n",
      "Traceback (most recent call last):\n",
      "  File \"C:\\ProgramData\\Anaconda2\\lib\\site-packages\\twitterscraper\\query.py\", line 93, in query_tweets_once\n",
      "    pos is None\n",
      "  File \"C:\\ProgramData\\Anaconda2\\lib\\site-packages\\twitterscraper\\query.py\", line 53, in query_single_page\n",
      "    except requests.exception.ConnectionError as e:\n",
      "AttributeError: 'module' object has no attribute 'exception'\n",
      "ERROR:root:An unknown error occurred! Returning tweets gathered so far.\n",
      "Traceback (most recent call last):\n",
      "  File \"C:\\ProgramData\\Anaconda2\\lib\\site-packages\\twitterscraper\\query.py\", line 93, in query_tweets_once\n",
      "    pos is None\n",
      "  File \"C:\\ProgramData\\Anaconda2\\lib\\site-packages\\twitterscraper\\query.py\", line 53, in query_single_page\n",
      "    except requests.exception.ConnectionError as e:\n",
      "AttributeError: 'module' object has no attribute 'exception'\n",
      "ERROR:root:An unknown error occurred! Returning tweets gathered so far.\n",
      "Traceback (most recent call last):\n",
      "  File \"C:\\ProgramData\\Anaconda2\\lib\\site-packages\\twitterscraper\\query.py\", line 93, in query_tweets_once\n",
      "    pos is None\n",
      "  File \"C:\\ProgramData\\Anaconda2\\lib\\site-packages\\twitterscraper\\query.py\", line 53, in query_single_page\n",
      "    except requests.exception.ConnectionError as e:\n",
      "AttributeError: 'module' object has no attribute 'exception'\n",
      "ERROR:root:An unknown error occurred! Returning tweets gathered so far.\n",
      "Traceback (most recent call last):\n",
      "  File \"C:\\ProgramData\\Anaconda2\\lib\\site-packages\\twitterscraper\\query.py\", line 93, in query_tweets_once\n",
      "    pos is None\n",
      "  File \"C:\\ProgramData\\Anaconda2\\lib\\site-packages\\twitterscraper\\query.py\", line 53, in query_single_page\n",
      "    except requests.exception.ConnectionError as e:\n",
      "AttributeError: 'module' object has no attribute 'exception'\n",
      "ERROR:root:An unknown error occurred! Returning tweets gathered so far.\n",
      "Traceback (most recent call last):\n",
      "  File \"C:\\ProgramData\\Anaconda2\\lib\\site-packages\\twitterscraper\\query.py\", line 93, in query_tweets_once\n",
      "    pos is None\n",
      "  File \"C:\\ProgramData\\Anaconda2\\lib\\site-packages\\twitterscraper\\query.py\", line 53, in query_single_page\n",
      "    except requests.exception.ConnectionError as e:\n",
      "AttributeError: 'module' object has no attribute 'exception'\n",
      "ERROR:root:An unknown error occurred! Returning tweets gathered so far.\n",
      "Traceback (most recent call last):\n",
      "  File \"C:\\ProgramData\\Anaconda2\\lib\\site-packages\\twitterscraper\\query.py\", line 93, in query_tweets_once\n",
      "    pos is None\n",
      "  File \"C:\\ProgramData\\Anaconda2\\lib\\site-packages\\twitterscraper\\query.py\", line 53, in query_single_page\n",
      "    except requests.exception.ConnectionError as e:\n",
      "AttributeError: 'module' object has no attribute 'exception'\n",
      "ERROR:root:An unknown error occurred! Returning tweets gathered so far.\n",
      "Traceback (most recent call last):\n",
      "  File \"C:\\ProgramData\\Anaconda2\\lib\\site-packages\\twitterscraper\\query.py\", line 93, in query_tweets_once\n",
      "    pos is None\n",
      "  File \"C:\\ProgramData\\Anaconda2\\lib\\site-packages\\twitterscraper\\query.py\", line 53, in query_single_page\n",
      "    except requests.exception.ConnectionError as e:\n",
      "AttributeError: 'module' object has no attribute 'exception'\n",
      "ERROR:root:An unknown error occurred! Returning tweets gathered so far.\n",
      "Traceback (most recent call last):\n",
      "  File \"C:\\ProgramData\\Anaconda2\\lib\\site-packages\\twitterscraper\\query.py\", line 93, in query_tweets_once\n",
      "    pos is None\n",
      "  File \"C:\\ProgramData\\Anaconda2\\lib\\site-packages\\twitterscraper\\query.py\", line 53, in query_single_page\n",
      "    except requests.exception.ConnectionError as e:\n",
      "AttributeError: 'module' object has no attribute 'exception'\n",
      "ERROR:root:An unknown error occurred! Returning tweets gathered so far.\n",
      "Traceback (most recent call last):\n",
      "  File \"C:\\ProgramData\\Anaconda2\\lib\\site-packages\\twitterscraper\\query.py\", line 93, in query_tweets_once\n",
      "    pos is None\n",
      "  File \"C:\\ProgramData\\Anaconda2\\lib\\site-packages\\twitterscraper\\query.py\", line 53, in query_single_page\n",
      "    except requests.exception.ConnectionError as e:\n",
      "AttributeError: 'module' object has no attribute 'exception'\n",
      "ERROR:root:An unknown error occurred! Returning tweets gathered so far.\n",
      "Traceback (most recent call last):\n",
      "  File \"C:\\ProgramData\\Anaconda2\\lib\\site-packages\\twitterscraper\\query.py\", line 93, in query_tweets_once\n",
      "    pos is None\n",
      "  File \"C:\\ProgramData\\Anaconda2\\lib\\site-packages\\twitterscraper\\query.py\", line 53, in query_single_page\n",
      "    except requests.exception.ConnectionError as e:\n",
      "AttributeError: 'module' object has no attribute 'exception'\n",
      "ERROR:root:An unknown error occurred! Returning tweets gathered so far.\n",
      "Traceback (most recent call last):\n",
      "  File \"C:\\ProgramData\\Anaconda2\\lib\\site-packages\\twitterscraper\\query.py\", line 93, in query_tweets_once\n",
      "    pos is None\n",
      "  File \"C:\\ProgramData\\Anaconda2\\lib\\site-packages\\twitterscraper\\query.py\", line 53, in query_single_page\n",
      "    except requests.exception.ConnectionError as e:\n",
      "AttributeError: 'module' object has no attribute 'exception'\n",
      "ERROR:root:An unknown error occurred! Returning tweets gathered so far.\n",
      "Traceback (most recent call last):\n",
      "  File \"C:\\ProgramData\\Anaconda2\\lib\\site-packages\\twitterscraper\\query.py\", line 93, in query_tweets_once\n",
      "    pos is None\n",
      "  File \"C:\\ProgramData\\Anaconda2\\lib\\site-packages\\twitterscraper\\query.py\", line 53, in query_single_page\n",
      "    except requests.exception.ConnectionError as e:\n",
      "AttributeError: 'module' object has no attribute 'exception'\n",
      "ERROR:root:An unknown error occurred! Returning tweets gathered so far.\n",
      "Traceback (most recent call last):\n",
      "  File \"C:\\ProgramData\\Anaconda2\\lib\\site-packages\\twitterscraper\\query.py\", line 93, in query_tweets_once\n",
      "    pos is None\n",
      "  File \"C:\\ProgramData\\Anaconda2\\lib\\site-packages\\twitterscraper\\query.py\", line 53, in query_single_page\n",
      "    except requests.exception.ConnectionError as e:\n",
      "AttributeError: 'module' object has no attribute 'exception'\n",
      "ERROR:root:An unknown error occurred! Returning tweets gathered so far.\n",
      "Traceback (most recent call last):\n",
      "  File \"C:\\ProgramData\\Anaconda2\\lib\\site-packages\\twitterscraper\\query.py\", line 93, in query_tweets_once\n",
      "    pos is None\n",
      "  File \"C:\\ProgramData\\Anaconda2\\lib\\site-packages\\twitterscraper\\query.py\", line 53, in query_single_page\n",
      "    except requests.exception.ConnectionError as e:\n",
      "AttributeError: 'module' object has no attribute 'exception'\n",
      "ERROR:root:An unknown error occurred! Returning tweets gathered so far.\n",
      "Traceback (most recent call last):\n",
      "  File \"C:\\ProgramData\\Anaconda2\\lib\\site-packages\\twitterscraper\\query.py\", line 93, in query_tweets_once\n",
      "    pos is None\n",
      "  File \"C:\\ProgramData\\Anaconda2\\lib\\site-packages\\twitterscraper\\query.py\", line 53, in query_single_page\n",
      "    except requests.exception.ConnectionError as e:\n",
      "AttributeError: 'module' object has no attribute 'exception'\n",
      "ERROR:root:An unknown error occurred! Returning tweets gathered so far.\n",
      "Traceback (most recent call last):\n",
      "  File \"C:\\ProgramData\\Anaconda2\\lib\\site-packages\\twitterscraper\\query.py\", line 93, in query_tweets_once\n",
      "    pos is None\n",
      "  File \"C:\\ProgramData\\Anaconda2\\lib\\site-packages\\twitterscraper\\query.py\", line 53, in query_single_page\n",
      "    except requests.exception.ConnectionError as e:\n",
      "AttributeError: 'module' object has no attribute 'exception'\n",
      "ERROR:root:An unknown error occurred! Returning tweets gathered so far.\n",
      "Traceback (most recent call last):\n",
      "  File \"C:\\ProgramData\\Anaconda2\\lib\\site-packages\\twitterscraper\\query.py\", line 93, in query_tweets_once\n",
      "    pos is None\n",
      "  File \"C:\\ProgramData\\Anaconda2\\lib\\site-packages\\twitterscraper\\query.py\", line 53, in query_single_page\n",
      "    except requests.exception.ConnectionError as e:\n",
      "AttributeError: 'module' object has no attribute 'exception'\n",
      "ERROR:root:An unknown error occurred! Returning tweets gathered so far.\n",
      "Traceback (most recent call last):\n",
      "  File \"C:\\ProgramData\\Anaconda2\\lib\\site-packages\\twitterscraper\\query.py\", line 93, in query_tweets_once\n",
      "    pos is None\n",
      "  File \"C:\\ProgramData\\Anaconda2\\lib\\site-packages\\twitterscraper\\query.py\", line 53, in query_single_page\n",
      "    except requests.exception.ConnectionError as e:\n",
      "AttributeError: 'module' object has no attribute 'exception'\n",
      "ERROR:root:An unknown error occurred! Returning tweets gathered so far.\n",
      "Traceback (most recent call last):\n",
      "  File \"C:\\ProgramData\\Anaconda2\\lib\\site-packages\\twitterscraper\\query.py\", line 93, in query_tweets_once\n",
      "    pos is None\n",
      "  File \"C:\\ProgramData\\Anaconda2\\lib\\site-packages\\twitterscraper\\query.py\", line 53, in query_single_page\n",
      "    except requests.exception.ConnectionError as e:\n",
      "AttributeError: 'module' object has no attribute 'exception'\n",
      "ERROR:root:An unknown error occurred! Returning tweets gathered so far.\n",
      "Traceback (most recent call last):\n",
      "  File \"C:\\ProgramData\\Anaconda2\\lib\\site-packages\\twitterscraper\\query.py\", line 93, in query_tweets_once\n",
      "    pos is None\n",
      "  File \"C:\\ProgramData\\Anaconda2\\lib\\site-packages\\twitterscraper\\query.py\", line 53, in query_single_page\n",
      "    except requests.exception.ConnectionError as e:\n",
      "AttributeError: 'module' object has no attribute 'exception'\n",
      "ERROR:root:An unknown error occurred! Returning tweets gathered so far.\n",
      "Traceback (most recent call last):\n",
      "  File \"C:\\ProgramData\\Anaconda2\\lib\\site-packages\\twitterscraper\\query.py\", line 93, in query_tweets_once\n",
      "    pos is None\n",
      "  File \"C:\\ProgramData\\Anaconda2\\lib\\site-packages\\twitterscraper\\query.py\", line 53, in query_single_page\n",
      "    except requests.exception.ConnectionError as e:\n",
      "AttributeError: 'module' object has no attribute 'exception'\n",
      "ERROR:root:An unknown error occurred! Returning tweets gathered so far.\n",
      "Traceback (most recent call last):\n",
      "  File \"C:\\ProgramData\\Anaconda2\\lib\\site-packages\\twitterscraper\\query.py\", line 93, in query_tweets_once\n",
      "    pos is None\n",
      "  File \"C:\\ProgramData\\Anaconda2\\lib\\site-packages\\twitterscraper\\query.py\", line 53, in query_single_page\n",
      "    except requests.exception.ConnectionError as e:\n",
      "AttributeError: 'module' object has no attribute 'exception'\n",
      "ERROR:root:An unknown error occurred! Returning tweets gathered so far.\n",
      "Traceback (most recent call last):\n",
      "  File \"C:\\ProgramData\\Anaconda2\\lib\\site-packages\\twitterscraper\\query.py\", line 93, in query_tweets_once\n",
      "    pos is None\n",
      "  File \"C:\\ProgramData\\Anaconda2\\lib\\site-packages\\twitterscraper\\query.py\", line 53, in query_single_page\n",
      "    except requests.exception.ConnectionError as e:\n",
      "AttributeError: 'module' object has no attribute 'exception'\n",
      "ERROR:root:An unknown error occurred! Returning tweets gathered so far.\n",
      "Traceback (most recent call last):\n",
      "  File \"C:\\ProgramData\\Anaconda2\\lib\\site-packages\\twitterscraper\\query.py\", line 93, in query_tweets_once\n",
      "    pos is None\n",
      "  File \"C:\\ProgramData\\Anaconda2\\lib\\site-packages\\twitterscraper\\query.py\", line 53, in query_single_page\n",
      "    except requests.exception.ConnectionError as e:\n",
      "AttributeError: 'module' object has no attribute 'exception'\n",
      "ERROR:root:An unknown error occurred! Returning tweets gathered so far.\n",
      "Traceback (most recent call last):\n",
      "  File \"C:\\ProgramData\\Anaconda2\\lib\\site-packages\\twitterscraper\\query.py\", line 93, in query_tweets_once\n",
      "    pos is None\n",
      "  File \"C:\\ProgramData\\Anaconda2\\lib\\site-packages\\twitterscraper\\query.py\", line 53, in query_single_page\n",
      "    except requests.exception.ConnectionError as e:\n",
      "AttributeError: 'module' object has no attribute 'exception'\n",
      "ERROR:root:An unknown error occurred! Returning tweets gathered so far.\n",
      "Traceback (most recent call last):\n",
      "  File \"C:\\ProgramData\\Anaconda2\\lib\\site-packages\\twitterscraper\\query.py\", line 93, in query_tweets_once\n",
      "    pos is None\n",
      "  File \"C:\\ProgramData\\Anaconda2\\lib\\site-packages\\twitterscraper\\query.py\", line 53, in query_single_page\n",
      "    except requests.exception.ConnectionError as e:\n",
      "AttributeError: 'module' object has no attribute 'exception'\n",
      "ERROR:root:An unknown error occurred! Returning tweets gathered so far.\n",
      "Traceback (most recent call last):\n",
      "  File \"C:\\ProgramData\\Anaconda2\\lib\\site-packages\\twitterscraper\\query.py\", line 93, in query_tweets_once\n",
      "    pos is None\n",
      "  File \"C:\\ProgramData\\Anaconda2\\lib\\site-packages\\twitterscraper\\query.py\", line 53, in query_single_page\n",
      "    except requests.exception.ConnectionError as e:\n",
      "AttributeError: 'module' object has no attribute 'exception'\n",
      "ERROR:root:An unknown error occurred! Returning tweets gathered so far.\n",
      "Traceback (most recent call last):\n",
      "  File \"C:\\ProgramData\\Anaconda2\\lib\\site-packages\\twitterscraper\\query.py\", line 93, in query_tweets_once\n",
      "    pos is None\n",
      "  File \"C:\\ProgramData\\Anaconda2\\lib\\site-packages\\twitterscraper\\query.py\", line 53, in query_single_page\n",
      "    except requests.exception.ConnectionError as e:\n",
      "AttributeError: 'module' object has no attribute 'exception'\n",
      "ERROR:root:An unknown error occurred! Returning tweets gathered so far.\n",
      "Traceback (most recent call last):\n",
      "  File \"C:\\ProgramData\\Anaconda2\\lib\\site-packages\\twitterscraper\\query.py\", line 93, in query_tweets_once\n",
      "    pos is None\n",
      "  File \"C:\\ProgramData\\Anaconda2\\lib\\site-packages\\twitterscraper\\query.py\", line 53, in query_single_page\n",
      "    except requests.exception.ConnectionError as e:\n",
      "AttributeError: 'module' object has no attribute 'exception'\n",
      "ERROR:root:An unknown error occurred! Returning tweets gathered so far.\n",
      "Traceback (most recent call last):\n",
      "  File \"C:\\ProgramData\\Anaconda2\\lib\\site-packages\\twitterscraper\\query.py\", line 93, in query_tweets_once\n",
      "    pos is None\n",
      "  File \"C:\\ProgramData\\Anaconda2\\lib\\site-packages\\twitterscraper\\query.py\", line 53, in query_single_page\n",
      "    except requests.exception.ConnectionError as e:\n",
      "AttributeError: 'module' object has no attribute 'exception'\n",
      "ERROR:root:An unknown error occurred! Returning tweets gathered so far.\n",
      "Traceback (most recent call last):\n",
      "  File \"C:\\ProgramData\\Anaconda2\\lib\\site-packages\\twitterscraper\\query.py\", line 93, in query_tweets_once\n",
      "    pos is None\n",
      "  File \"C:\\ProgramData\\Anaconda2\\lib\\site-packages\\twitterscraper\\query.py\", line 53, in query_single_page\n",
      "    except requests.exception.ConnectionError as e:\n",
      "AttributeError: 'module' object has no attribute 'exception'\n",
      "ERROR:root:An unknown error occurred! Returning tweets gathered so far.\n",
      "Traceback (most recent call last):\n",
      "  File \"C:\\ProgramData\\Anaconda2\\lib\\site-packages\\twitterscraper\\query.py\", line 93, in query_tweets_once\n",
      "    pos is None\n",
      "  File \"C:\\ProgramData\\Anaconda2\\lib\\site-packages\\twitterscraper\\query.py\", line 53, in query_single_page\n",
      "    except requests.exception.ConnectionError as e:\n",
      "AttributeError: 'module' object has no attribute 'exception'\n",
      "ERROR:root:An unknown error occurred! Returning tweets gathered so far.\n",
      "Traceback (most recent call last):\n",
      "  File \"C:\\ProgramData\\Anaconda2\\lib\\site-packages\\twitterscraper\\query.py\", line 93, in query_tweets_once\n",
      "    pos is None\n",
      "  File \"C:\\ProgramData\\Anaconda2\\lib\\site-packages\\twitterscraper\\query.py\", line 53, in query_single_page\n",
      "    except requests.exception.ConnectionError as e:\n",
      "AttributeError: 'module' object has no attribute 'exception'\n",
      "ERROR:root:An unknown error occurred! Returning tweets gathered so far.\n",
      "Traceback (most recent call last):\n",
      "  File \"C:\\ProgramData\\Anaconda2\\lib\\site-packages\\twitterscraper\\query.py\", line 93, in query_tweets_once\n",
      "    pos is None\n",
      "  File \"C:\\ProgramData\\Anaconda2\\lib\\site-packages\\twitterscraper\\query.py\", line 53, in query_single_page\n",
      "    except requests.exception.ConnectionError as e:\n",
      "AttributeError: 'module' object has no attribute 'exception'\n",
      "ERROR:root:An unknown error occurred! Returning tweets gathered so far.\n",
      "Traceback (most recent call last):\n",
      "  File \"C:\\ProgramData\\Anaconda2\\lib\\site-packages\\twitterscraper\\query.py\", line 93, in query_tweets_once\n",
      "    pos is None\n",
      "  File \"C:\\ProgramData\\Anaconda2\\lib\\site-packages\\twitterscraper\\query.py\", line 53, in query_single_page\n",
      "    except requests.exception.ConnectionError as e:\n",
      "AttributeError: 'module' object has no attribute 'exception'\n",
      "ERROR:root:An unknown error occurred! Returning tweets gathered so far.\n",
      "Traceback (most recent call last):\n",
      "  File \"C:\\ProgramData\\Anaconda2\\lib\\site-packages\\twitterscraper\\query.py\", line 93, in query_tweets_once\n",
      "    pos is None\n",
      "  File \"C:\\ProgramData\\Anaconda2\\lib\\site-packages\\twitterscraper\\query.py\", line 53, in query_single_page\n",
      "    except requests.exception.ConnectionError as e:\n",
      "AttributeError: 'module' object has no attribute 'exception'\n",
      "ERROR:root:An unknown error occurred! Returning tweets gathered so far.\n",
      "Traceback (most recent call last):\n",
      "  File \"C:\\ProgramData\\Anaconda2\\lib\\site-packages\\twitterscraper\\query.py\", line 93, in query_tweets_once\n",
      "    pos is None\n",
      "  File \"C:\\ProgramData\\Anaconda2\\lib\\site-packages\\twitterscraper\\query.py\", line 53, in query_single_page\n",
      "    except requests.exception.ConnectionError as e:\n",
      "AttributeError: 'module' object has no attribute 'exception'\n",
      "ERROR:root:An unknown error occurred! Returning tweets gathered so far.\n",
      "Traceback (most recent call last):\n",
      "  File \"C:\\ProgramData\\Anaconda2\\lib\\site-packages\\twitterscraper\\query.py\", line 93, in query_tweets_once\n",
      "    pos is None\n",
      "  File \"C:\\ProgramData\\Anaconda2\\lib\\site-packages\\twitterscraper\\query.py\", line 53, in query_single_page\n",
      "    except requests.exception.ConnectionError as e:\n",
      "AttributeError: 'module' object has no attribute 'exception'\n",
      "ERROR:root:An unknown error occurred! Returning tweets gathered so far.\n",
      "Traceback (most recent call last):\n",
      "  File \"C:\\ProgramData\\Anaconda2\\lib\\site-packages\\twitterscraper\\query.py\", line 93, in query_tweets_once\n",
      "    pos is None\n",
      "  File \"C:\\ProgramData\\Anaconda2\\lib\\site-packages\\twitterscraper\\query.py\", line 53, in query_single_page\n",
      "    except requests.exception.ConnectionError as e:\n",
      "AttributeError: 'module' object has no attribute 'exception'\n",
      "ERROR:root:An unknown error occurred! Returning tweets gathered so far.\n",
      "Traceback (most recent call last):\n",
      "  File \"C:\\ProgramData\\Anaconda2\\lib\\site-packages\\twitterscraper\\query.py\", line 93, in query_tweets_once\n",
      "    pos is None\n",
      "  File \"C:\\ProgramData\\Anaconda2\\lib\\site-packages\\twitterscraper\\query.py\", line 53, in query_single_page\n",
      "    except requests.exception.ConnectionError as e:\n",
      "AttributeError: 'module' object has no attribute 'exception'\n",
      "ERROR:root:An unknown error occurred! Returning tweets gathered so far.\n",
      "Traceback (most recent call last):\n",
      "  File \"C:\\ProgramData\\Anaconda2\\lib\\site-packages\\twitterscraper\\query.py\", line 93, in query_tweets_once\n",
      "    pos is None\n",
      "  File \"C:\\ProgramData\\Anaconda2\\lib\\site-packages\\twitterscraper\\query.py\", line 53, in query_single_page\n",
      "    except requests.exception.ConnectionError as e:\n",
      "AttributeError: 'module' object has no attribute 'exception'\n",
      "ERROR:root:An unknown error occurred! Returning tweets gathered so far.\n",
      "Traceback (most recent call last):\n",
      "  File \"C:\\ProgramData\\Anaconda2\\lib\\site-packages\\twitterscraper\\query.py\", line 93, in query_tweets_once\n",
      "    pos is None\n",
      "  File \"C:\\ProgramData\\Anaconda2\\lib\\site-packages\\twitterscraper\\query.py\", line 53, in query_single_page\n",
      "    except requests.exception.ConnectionError as e:\n",
      "AttributeError: 'module' object has no attribute 'exception'\n",
      "ERROR:root:An unknown error occurred! Returning tweets gathered so far.\n",
      "Traceback (most recent call last):\n",
      "  File \"C:\\ProgramData\\Anaconda2\\lib\\site-packages\\twitterscraper\\query.py\", line 93, in query_tweets_once\n",
      "    pos is None\n",
      "  File \"C:\\ProgramData\\Anaconda2\\lib\\site-packages\\twitterscraper\\query.py\", line 53, in query_single_page\n",
      "    except requests.exception.ConnectionError as e:\n",
      "AttributeError: 'module' object has no attribute 'exception'\n",
      "ERROR:root:An unknown error occurred! Returning tweets gathered so far.\n",
      "Traceback (most recent call last):\n",
      "  File \"C:\\ProgramData\\Anaconda2\\lib\\site-packages\\twitterscraper\\query.py\", line 93, in query_tweets_once\n",
      "    pos is None\n",
      "  File \"C:\\ProgramData\\Anaconda2\\lib\\site-packages\\twitterscraper\\query.py\", line 53, in query_single_page\n",
      "    except requests.exception.ConnectionError as e:\n",
      "AttributeError: 'module' object has no attribute 'exception'\n",
      "ERROR:root:An unknown error occurred! Returning tweets gathered so far.\n",
      "Traceback (most recent call last):\n",
      "  File \"C:\\ProgramData\\Anaconda2\\lib\\site-packages\\twitterscraper\\query.py\", line 93, in query_tweets_once\n",
      "    pos is None\n",
      "  File \"C:\\ProgramData\\Anaconda2\\lib\\site-packages\\twitterscraper\\query.py\", line 53, in query_single_page\n",
      "    except requests.exception.ConnectionError as e:\n",
      "AttributeError: 'module' object has no attribute 'exception'\n",
      "ERROR:root:An unknown error occurred! Returning tweets gathered so far.\n",
      "Traceback (most recent call last):\n",
      "  File \"C:\\ProgramData\\Anaconda2\\lib\\site-packages\\twitterscraper\\query.py\", line 93, in query_tweets_once\n",
      "    pos is None\n",
      "  File \"C:\\ProgramData\\Anaconda2\\lib\\site-packages\\twitterscraper\\query.py\", line 53, in query_single_page\n",
      "    except requests.exception.ConnectionError as e:\n",
      "AttributeError: 'module' object has no attribute 'exception'\n",
      "ERROR:root:An unknown error occurred! Returning tweets gathered so far.\n",
      "Traceback (most recent call last):\n",
      "  File \"C:\\ProgramData\\Anaconda2\\lib\\site-packages\\twitterscraper\\query.py\", line 93, in query_tweets_once\n",
      "    pos is None\n",
      "  File \"C:\\ProgramData\\Anaconda2\\lib\\site-packages\\twitterscraper\\query.py\", line 53, in query_single_page\n",
      "    except requests.exception.ConnectionError as e:\n",
      "AttributeError: 'module' object has no attribute 'exception'\n",
      "ERROR:root:An unknown error occurred! Returning tweets gathered so far.\n",
      "Traceback (most recent call last):\n",
      "  File \"C:\\ProgramData\\Anaconda2\\lib\\site-packages\\twitterscraper\\query.py\", line 93, in query_tweets_once\n",
      "    pos is None\n",
      "  File \"C:\\ProgramData\\Anaconda2\\lib\\site-packages\\twitterscraper\\query.py\", line 53, in query_single_page\n",
      "    except requests.exception.ConnectionError as e:\n",
      "AttributeError: 'module' object has no attribute 'exception'\n",
      "ERROR:root:An unknown error occurred! Returning tweets gathered so far.\n",
      "Traceback (most recent call last):\n",
      "  File \"C:\\ProgramData\\Anaconda2\\lib\\site-packages\\twitterscraper\\query.py\", line 93, in query_tweets_once\n",
      "    pos is None\n",
      "  File \"C:\\ProgramData\\Anaconda2\\lib\\site-packages\\twitterscraper\\query.py\", line 53, in query_single_page\n",
      "    except requests.exception.ConnectionError as e:\n",
      "AttributeError: 'module' object has no attribute 'exception'\n",
      "ERROR:root:An unknown error occurred! Returning tweets gathered so far.\n",
      "Traceback (most recent call last):\n",
      "  File \"C:\\ProgramData\\Anaconda2\\lib\\site-packages\\twitterscraper\\query.py\", line 93, in query_tweets_once\n",
      "    pos is None\n",
      "  File \"C:\\ProgramData\\Anaconda2\\lib\\site-packages\\twitterscraper\\query.py\", line 53, in query_single_page\n",
      "    except requests.exception.ConnectionError as e:\n",
      "AttributeError: 'module' object has no attribute 'exception'\n",
      "ERROR:root:An unknown error occurred! Returning tweets gathered so far.\n",
      "Traceback (most recent call last):\n",
      "  File \"C:\\ProgramData\\Anaconda2\\lib\\site-packages\\twitterscraper\\query.py\", line 93, in query_tweets_once\n",
      "    pos is None\n",
      "  File \"C:\\ProgramData\\Anaconda2\\lib\\site-packages\\twitterscraper\\query.py\", line 53, in query_single_page\n",
      "    except requests.exception.ConnectionError as e:\n",
      "AttributeError: 'module' object has no attribute 'exception'\n",
      "ERROR:root:An unknown error occurred! Returning tweets gathered so far.\n",
      "Traceback (most recent call last):\n",
      "  File \"C:\\ProgramData\\Anaconda2\\lib\\site-packages\\twitterscraper\\query.py\", line 93, in query_tweets_once\n",
      "    pos is None\n",
      "  File \"C:\\ProgramData\\Anaconda2\\lib\\site-packages\\twitterscraper\\query.py\", line 53, in query_single_page\n",
      "    except requests.exception.ConnectionError as e:\n",
      "AttributeError: 'module' object has no attribute 'exception'\n",
      "ERROR:root:An unknown error occurred! Returning tweets gathered so far.\n",
      "Traceback (most recent call last):\n",
      "  File \"C:\\ProgramData\\Anaconda2\\lib\\site-packages\\twitterscraper\\query.py\", line 93, in query_tweets_once\n",
      "    pos is None\n",
      "  File \"C:\\ProgramData\\Anaconda2\\lib\\site-packages\\twitterscraper\\query.py\", line 53, in query_single_page\n",
      "    except requests.exception.ConnectionError as e:\n",
      "AttributeError: 'module' object has no attribute 'exception'\n",
      "ERROR:root:An unknown error occurred! Returning tweets gathered so far.\n",
      "Traceback (most recent call last):\n",
      "  File \"C:\\ProgramData\\Anaconda2\\lib\\site-packages\\twitterscraper\\query.py\", line 93, in query_tweets_once\n",
      "    pos is None\n",
      "  File \"C:\\ProgramData\\Anaconda2\\lib\\site-packages\\twitterscraper\\query.py\", line 53, in query_single_page\n",
      "    except requests.exception.ConnectionError as e:\n",
      "AttributeError: 'module' object has no attribute 'exception'\n",
      "ERROR:root:An unknown error occurred! Returning tweets gathered so far.\n",
      "Traceback (most recent call last):\n",
      "  File \"C:\\ProgramData\\Anaconda2\\lib\\site-packages\\twitterscraper\\query.py\", line 93, in query_tweets_once\n",
      "    pos is None\n",
      "  File \"C:\\ProgramData\\Anaconda2\\lib\\site-packages\\twitterscraper\\query.py\", line 53, in query_single_page\n",
      "    except requests.exception.ConnectionError as e:\n",
      "AttributeError: 'module' object has no attribute 'exception'\n",
      "ERROR:root:An unknown error occurred! Returning tweets gathered so far.\n",
      "Traceback (most recent call last):\n",
      "  File \"C:\\ProgramData\\Anaconda2\\lib\\site-packages\\twitterscraper\\query.py\", line 93, in query_tweets_once\n",
      "    pos is None\n",
      "  File \"C:\\ProgramData\\Anaconda2\\lib\\site-packages\\twitterscraper\\query.py\", line 53, in query_single_page\n",
      "    except requests.exception.ConnectionError as e:\n",
      "AttributeError: 'module' object has no attribute 'exception'\n",
      "ERROR:root:An unknown error occurred! Returning tweets gathered so far.\n",
      "Traceback (most recent call last):\n",
      "  File \"C:\\ProgramData\\Anaconda2\\lib\\site-packages\\twitterscraper\\query.py\", line 93, in query_tweets_once\n",
      "    pos is None\n",
      "  File \"C:\\ProgramData\\Anaconda2\\lib\\site-packages\\twitterscraper\\query.py\", line 53, in query_single_page\n",
      "    except requests.exception.ConnectionError as e:\n",
      "AttributeError: 'module' object has no attribute 'exception'\n",
      "ERROR:root:An unknown error occurred! Returning tweets gathered so far.\n",
      "Traceback (most recent call last):\n",
      "  File \"C:\\ProgramData\\Anaconda2\\lib\\site-packages\\twitterscraper\\query.py\", line 93, in query_tweets_once\n",
      "    pos is None\n",
      "  File \"C:\\ProgramData\\Anaconda2\\lib\\site-packages\\twitterscraper\\query.py\", line 53, in query_single_page\n",
      "    except requests.exception.ConnectionError as e:\n",
      "AttributeError: 'module' object has no attribute 'exception'\n",
      "ERROR:root:An unknown error occurred! Returning tweets gathered so far.\n",
      "Traceback (most recent call last):\n",
      "  File \"C:\\ProgramData\\Anaconda2\\lib\\site-packages\\twitterscraper\\query.py\", line 93, in query_tweets_once\n",
      "    pos is None\n",
      "  File \"C:\\ProgramData\\Anaconda2\\lib\\site-packages\\twitterscraper\\query.py\", line 53, in query_single_page\n",
      "    except requests.exception.ConnectionError as e:\n",
      "AttributeError: 'module' object has no attribute 'exception'\n",
      "ERROR:root:An unknown error occurred! Returning tweets gathered so far.\n",
      "Traceback (most recent call last):\n",
      "  File \"C:\\ProgramData\\Anaconda2\\lib\\site-packages\\twitterscraper\\query.py\", line 93, in query_tweets_once\n",
      "    pos is None\n",
      "  File \"C:\\ProgramData\\Anaconda2\\lib\\site-packages\\twitterscraper\\query.py\", line 53, in query_single_page\n",
      "    except requests.exception.ConnectionError as e:\n",
      "AttributeError: 'module' object has no attribute 'exception'\n",
      "ERROR:root:An unknown error occurred! Returning tweets gathered so far.\n",
      "Traceback (most recent call last):\n",
      "  File \"C:\\ProgramData\\Anaconda2\\lib\\site-packages\\twitterscraper\\query.py\", line 93, in query_tweets_once\n",
      "    pos is None\n",
      "  File \"C:\\ProgramData\\Anaconda2\\lib\\site-packages\\twitterscraper\\query.py\", line 53, in query_single_page\n",
      "    except requests.exception.ConnectionError as e:\n",
      "AttributeError: 'module' object has no attribute 'exception'\n",
      "ERROR:root:An unknown error occurred! Returning tweets gathered so far.\n",
      "Traceback (most recent call last):\n",
      "  File \"C:\\ProgramData\\Anaconda2\\lib\\site-packages\\twitterscraper\\query.py\", line 93, in query_tweets_once\n",
      "    pos is None\n",
      "  File \"C:\\ProgramData\\Anaconda2\\lib\\site-packages\\twitterscraper\\query.py\", line 53, in query_single_page\n",
      "    except requests.exception.ConnectionError as e:\n",
      "AttributeError: 'module' object has no attribute 'exception'\n",
      "ERROR:root:An unknown error occurred! Returning tweets gathered so far.\n",
      "Traceback (most recent call last):\n",
      "  File \"C:\\ProgramData\\Anaconda2\\lib\\site-packages\\twitterscraper\\query.py\", line 93, in query_tweets_once\n",
      "    pos is None\n",
      "  File \"C:\\ProgramData\\Anaconda2\\lib\\site-packages\\twitterscraper\\query.py\", line 53, in query_single_page\n",
      "    except requests.exception.ConnectionError as e:\n",
      "AttributeError: 'module' object has no attribute 'exception'\n",
      "ERROR:root:An unknown error occurred! Returning tweets gathered so far.\n",
      "Traceback (most recent call last):\n",
      "  File \"C:\\ProgramData\\Anaconda2\\lib\\site-packages\\twitterscraper\\query.py\", line 93, in query_tweets_once\n",
      "    pos is None\n",
      "  File \"C:\\ProgramData\\Anaconda2\\lib\\site-packages\\twitterscraper\\query.py\", line 53, in query_single_page\n",
      "    except requests.exception.ConnectionError as e:\n",
      "AttributeError: 'module' object has no attribute 'exception'\n",
      "ERROR:root:An unknown error occurred! Returning tweets gathered so far.\n",
      "Traceback (most recent call last):\n",
      "  File \"C:\\ProgramData\\Anaconda2\\lib\\site-packages\\twitterscraper\\query.py\", line 93, in query_tweets_once\n",
      "    pos is None\n",
      "  File \"C:\\ProgramData\\Anaconda2\\lib\\site-packages\\twitterscraper\\query.py\", line 53, in query_single_page\n",
      "    except requests.exception.ConnectionError as e:\n",
      "AttributeError: 'module' object has no attribute 'exception'\n",
      "ERROR:root:An unknown error occurred! Returning tweets gathered so far.\n",
      "Traceback (most recent call last):\n",
      "  File \"C:\\ProgramData\\Anaconda2\\lib\\site-packages\\twitterscraper\\query.py\", line 93, in query_tweets_once\n",
      "    pos is None\n",
      "  File \"C:\\ProgramData\\Anaconda2\\lib\\site-packages\\twitterscraper\\query.py\", line 53, in query_single_page\n",
      "    except requests.exception.ConnectionError as e:\n",
      "AttributeError: 'module' object has no attribute 'exception'\n",
      "ERROR:root:An unknown error occurred! Returning tweets gathered so far.\n",
      "Traceback (most recent call last):\n",
      "  File \"C:\\ProgramData\\Anaconda2\\lib\\site-packages\\twitterscraper\\query.py\", line 93, in query_tweets_once\n",
      "    pos is None\n",
      "  File \"C:\\ProgramData\\Anaconda2\\lib\\site-packages\\twitterscraper\\query.py\", line 53, in query_single_page\n",
      "    except requests.exception.ConnectionError as e:\n",
      "AttributeError: 'module' object has no attribute 'exception'\n",
      "ERROR:root:An unknown error occurred! Returning tweets gathered so far.\n",
      "Traceback (most recent call last):\n",
      "  File \"C:\\ProgramData\\Anaconda2\\lib\\site-packages\\twitterscraper\\query.py\", line 93, in query_tweets_once\n",
      "    pos is None\n",
      "  File \"C:\\ProgramData\\Anaconda2\\lib\\site-packages\\twitterscraper\\query.py\", line 53, in query_single_page\n",
      "    except requests.exception.ConnectionError as e:\n",
      "AttributeError: 'module' object has no attribute 'exception'\n",
      "ERROR:root:An unknown error occurred! Returning tweets gathered so far.\n",
      "Traceback (most recent call last):\n",
      "  File \"C:\\ProgramData\\Anaconda2\\lib\\site-packages\\twitterscraper\\query.py\", line 93, in query_tweets_once\n",
      "    pos is None\n",
      "  File \"C:\\ProgramData\\Anaconda2\\lib\\site-packages\\twitterscraper\\query.py\", line 53, in query_single_page\n",
      "    except requests.exception.ConnectionError as e:\n",
      "AttributeError: 'module' object has no attribute 'exception'\n",
      "ERROR:root:An unknown error occurred! Returning tweets gathered so far.\n",
      "Traceback (most recent call last):\n",
      "  File \"C:\\ProgramData\\Anaconda2\\lib\\site-packages\\twitterscraper\\query.py\", line 93, in query_tweets_once\n",
      "    pos is None\n",
      "  File \"C:\\ProgramData\\Anaconda2\\lib\\site-packages\\twitterscraper\\query.py\", line 53, in query_single_page\n",
      "    except requests.exception.ConnectionError as e:\n",
      "AttributeError: 'module' object has no attribute 'exception'\n",
      "ERROR:root:An unknown error occurred! Returning tweets gathered so far.\n",
      "Traceback (most recent call last):\n",
      "  File \"C:\\ProgramData\\Anaconda2\\lib\\site-packages\\twitterscraper\\query.py\", line 93, in query_tweets_once\n",
      "    pos is None\n",
      "  File \"C:\\ProgramData\\Anaconda2\\lib\\site-packages\\twitterscraper\\query.py\", line 53, in query_single_page\n",
      "    except requests.exception.ConnectionError as e:\n",
      "AttributeError: 'module' object has no attribute 'exception'\n",
      "ERROR:root:An unknown error occurred! Returning tweets gathered so far.\n",
      "Traceback (most recent call last):\n",
      "  File \"C:\\ProgramData\\Anaconda2\\lib\\site-packages\\twitterscraper\\query.py\", line 93, in query_tweets_once\n",
      "    pos is None\n",
      "  File \"C:\\ProgramData\\Anaconda2\\lib\\site-packages\\twitterscraper\\query.py\", line 53, in query_single_page\n",
      "    except requests.exception.ConnectionError as e:\n",
      "AttributeError: 'module' object has no attribute 'exception'\n",
      "ERROR:root:An unknown error occurred! Returning tweets gathered so far.\n",
      "Traceback (most recent call last):\n",
      "  File \"C:\\ProgramData\\Anaconda2\\lib\\site-packages\\twitterscraper\\query.py\", line 93, in query_tweets_once\n",
      "    pos is None\n",
      "  File \"C:\\ProgramData\\Anaconda2\\lib\\site-packages\\twitterscraper\\query.py\", line 53, in query_single_page\n",
      "    except requests.exception.ConnectionError as e:\n",
      "AttributeError: 'module' object has no attribute 'exception'\n",
      "ERROR:root:An unknown error occurred! Returning tweets gathered so far.\n",
      "Traceback (most recent call last):\n",
      "  File \"C:\\ProgramData\\Anaconda2\\lib\\site-packages\\twitterscraper\\query.py\", line 93, in query_tweets_once\n",
      "    pos is None\n",
      "  File \"C:\\ProgramData\\Anaconda2\\lib\\site-packages\\twitterscraper\\query.py\", line 53, in query_single_page\n",
      "    except requests.exception.ConnectionError as e:\n",
      "AttributeError: 'module' object has no attribute 'exception'\n",
      "ERROR:root:An unknown error occurred! Returning tweets gathered so far.\n",
      "Traceback (most recent call last):\n",
      "  File \"C:\\ProgramData\\Anaconda2\\lib\\site-packages\\twitterscraper\\query.py\", line 93, in query_tweets_once\n",
      "    pos is None\n",
      "  File \"C:\\ProgramData\\Anaconda2\\lib\\site-packages\\twitterscraper\\query.py\", line 53, in query_single_page\n",
      "    except requests.exception.ConnectionError as e:\n",
      "AttributeError: 'module' object has no attribute 'exception'\n",
      "ERROR:root:An unknown error occurred! Returning tweets gathered so far.\n",
      "Traceback (most recent call last):\n",
      "  File \"C:\\ProgramData\\Anaconda2\\lib\\site-packages\\twitterscraper\\query.py\", line 93, in query_tweets_once\n",
      "    pos is None\n",
      "  File \"C:\\ProgramData\\Anaconda2\\lib\\site-packages\\twitterscraper\\query.py\", line 53, in query_single_page\n",
      "    except requests.exception.ConnectionError as e:\n",
      "AttributeError: 'module' object has no attribute 'exception'\n",
      "ERROR:root:An unknown error occurred! Returning tweets gathered so far.\n",
      "Traceback (most recent call last):\n",
      "  File \"C:\\ProgramData\\Anaconda2\\lib\\site-packages\\twitterscraper\\query.py\", line 93, in query_tweets_once\n",
      "    pos is None\n",
      "  File \"C:\\ProgramData\\Anaconda2\\lib\\site-packages\\twitterscraper\\query.py\", line 53, in query_single_page\n",
      "    except requests.exception.ConnectionError as e:\n",
      "AttributeError: 'module' object has no attribute 'exception'\n",
      "ERROR:root:An unknown error occurred! Returning tweets gathered so far.\n",
      "Traceback (most recent call last):\n",
      "  File \"C:\\ProgramData\\Anaconda2\\lib\\site-packages\\twitterscraper\\query.py\", line 93, in query_tweets_once\n",
      "    pos is None\n",
      "  File \"C:\\ProgramData\\Anaconda2\\lib\\site-packages\\twitterscraper\\query.py\", line 53, in query_single_page\n",
      "    except requests.exception.ConnectionError as e:\n",
      "AttributeError: 'module' object has no attribute 'exception'\n",
      "ERROR:root:An unknown error occurred! Returning tweets gathered so far.\n",
      "Traceback (most recent call last):\n",
      "  File \"C:\\ProgramData\\Anaconda2\\lib\\site-packages\\twitterscraper\\query.py\", line 93, in query_tweets_once\n",
      "    pos is None\n",
      "  File \"C:\\ProgramData\\Anaconda2\\lib\\site-packages\\twitterscraper\\query.py\", line 53, in query_single_page\n",
      "    except requests.exception.ConnectionError as e:\n",
      "AttributeError: 'module' object has no attribute 'exception'\n",
      "ERROR:root:An unknown error occurred! Returning tweets gathered so far.\n",
      "Traceback (most recent call last):\n",
      "  File \"C:\\ProgramData\\Anaconda2\\lib\\site-packages\\twitterscraper\\query.py\", line 93, in query_tweets_once\n",
      "    pos is None\n",
      "  File \"C:\\ProgramData\\Anaconda2\\lib\\site-packages\\twitterscraper\\query.py\", line 53, in query_single_page\n",
      "    except requests.exception.ConnectionError as e:\n",
      "AttributeError: 'module' object has no attribute 'exception'\n",
      "ERROR:root:An unknown error occurred! Returning tweets gathered so far.\n",
      "Traceback (most recent call last):\n",
      "  File \"C:\\ProgramData\\Anaconda2\\lib\\site-packages\\twitterscraper\\query.py\", line 93, in query_tweets_once\n",
      "    pos is None\n",
      "  File \"C:\\ProgramData\\Anaconda2\\lib\\site-packages\\twitterscraper\\query.py\", line 53, in query_single_page\n",
      "    except requests.exception.ConnectionError as e:\n",
      "AttributeError: 'module' object has no attribute 'exception'\n",
      "ERROR:root:An unknown error occurred! Returning tweets gathered so far.\n",
      "Traceback (most recent call last):\n",
      "  File \"C:\\ProgramData\\Anaconda2\\lib\\site-packages\\twitterscraper\\query.py\", line 93, in query_tweets_once\n",
      "    pos is None\n",
      "  File \"C:\\ProgramData\\Anaconda2\\lib\\site-packages\\twitterscraper\\query.py\", line 53, in query_single_page\n",
      "    except requests.exception.ConnectionError as e:\n",
      "AttributeError: 'module' object has no attribute 'exception'\n",
      "ERROR:root:An unknown error occurred! Returning tweets gathered so far.\n",
      "Traceback (most recent call last):\n",
      "  File \"C:\\ProgramData\\Anaconda2\\lib\\site-packages\\twitterscraper\\query.py\", line 93, in query_tweets_once\n",
      "    pos is None\n",
      "  File \"C:\\ProgramData\\Anaconda2\\lib\\site-packages\\twitterscraper\\query.py\", line 53, in query_single_page\n",
      "    except requests.exception.ConnectionError as e:\n",
      "AttributeError: 'module' object has no attribute 'exception'\n",
      "ERROR:root:An unknown error occurred! Returning tweets gathered so far.\n",
      "Traceback (most recent call last):\n",
      "  File \"C:\\ProgramData\\Anaconda2\\lib\\site-packages\\twitterscraper\\query.py\", line 93, in query_tweets_once\n",
      "    pos is None\n",
      "  File \"C:\\ProgramData\\Anaconda2\\lib\\site-packages\\twitterscraper\\query.py\", line 53, in query_single_page\n",
      "    except requests.exception.ConnectionError as e:\n",
      "AttributeError: 'module' object has no attribute 'exception'\n",
      "ERROR:root:An unknown error occurred! Returning tweets gathered so far.\n",
      "Traceback (most recent call last):\n",
      "  File \"C:\\ProgramData\\Anaconda2\\lib\\site-packages\\twitterscraper\\query.py\", line 93, in query_tweets_once\n",
      "    pos is None\n",
      "  File \"C:\\ProgramData\\Anaconda2\\lib\\site-packages\\twitterscraper\\query.py\", line 53, in query_single_page\n",
      "    except requests.exception.ConnectionError as e:\n",
      "AttributeError: 'module' object has no attribute 'exception'\n",
      "ERROR:root:An unknown error occurred! Returning tweets gathered so far.\n",
      "Traceback (most recent call last):\n",
      "  File \"C:\\ProgramData\\Anaconda2\\lib\\site-packages\\twitterscraper\\query.py\", line 93, in query_tweets_once\n",
      "    pos is None\n",
      "  File \"C:\\ProgramData\\Anaconda2\\lib\\site-packages\\twitterscraper\\query.py\", line 53, in query_single_page\n",
      "    except requests.exception.ConnectionError as e:\n",
      "AttributeError: 'module' object has no attribute 'exception'\n",
      "ERROR:root:An unknown error occurred! Returning tweets gathered so far.\n",
      "Traceback (most recent call last):\n",
      "  File \"C:\\ProgramData\\Anaconda2\\lib\\site-packages\\twitterscraper\\query.py\", line 93, in query_tweets_once\n",
      "    pos is None\n",
      "  File \"C:\\ProgramData\\Anaconda2\\lib\\site-packages\\twitterscraper\\query.py\", line 53, in query_single_page\n",
      "    except requests.exception.ConnectionError as e:\n",
      "AttributeError: 'module' object has no attribute 'exception'\n",
      "ERROR:root:An unknown error occurred! Returning tweets gathered so far.\n",
      "Traceback (most recent call last):\n",
      "  File \"C:\\ProgramData\\Anaconda2\\lib\\site-packages\\twitterscraper\\query.py\", line 93, in query_tweets_once\n",
      "    pos is None\n",
      "  File \"C:\\ProgramData\\Anaconda2\\lib\\site-packages\\twitterscraper\\query.py\", line 53, in query_single_page\n",
      "    except requests.exception.ConnectionError as e:\n",
      "AttributeError: 'module' object has no attribute 'exception'\n",
      "ERROR:root:An unknown error occurred! Returning tweets gathered so far.\n",
      "Traceback (most recent call last):\n",
      "  File \"C:\\ProgramData\\Anaconda2\\lib\\site-packages\\twitterscraper\\query.py\", line 93, in query_tweets_once\n",
      "    pos is None\n",
      "  File \"C:\\ProgramData\\Anaconda2\\lib\\site-packages\\twitterscraper\\query.py\", line 53, in query_single_page\n",
      "    except requests.exception.ConnectionError as e:\n",
      "AttributeError: 'module' object has no attribute 'exception'\n",
      "ERROR:root:An unknown error occurred! Returning tweets gathered so far.\n",
      "Traceback (most recent call last):\n",
      "  File \"C:\\ProgramData\\Anaconda2\\lib\\site-packages\\twitterscraper\\query.py\", line 93, in query_tweets_once\n",
      "    pos is None\n",
      "  File \"C:\\ProgramData\\Anaconda2\\lib\\site-packages\\twitterscraper\\query.py\", line 53, in query_single_page\n",
      "    except requests.exception.ConnectionError as e:\n",
      "AttributeError: 'module' object has no attribute 'exception'\n",
      "ERROR:root:An unknown error occurred! Returning tweets gathered so far.\n",
      "Traceback (most recent call last):\n",
      "  File \"C:\\ProgramData\\Anaconda2\\lib\\site-packages\\twitterscraper\\query.py\", line 93, in query_tweets_once\n",
      "    pos is None\n",
      "  File \"C:\\ProgramData\\Anaconda2\\lib\\site-packages\\twitterscraper\\query.py\", line 53, in query_single_page\n",
      "    except requests.exception.ConnectionError as e:\n",
      "AttributeError: 'module' object has no attribute 'exception'\n",
      "ERROR:root:An unknown error occurred! Returning tweets gathered so far.\n",
      "Traceback (most recent call last):\n",
      "  File \"C:\\ProgramData\\Anaconda2\\lib\\site-packages\\twitterscraper\\query.py\", line 93, in query_tweets_once\n",
      "    pos is None\n",
      "  File \"C:\\ProgramData\\Anaconda2\\lib\\site-packages\\twitterscraper\\query.py\", line 53, in query_single_page\n",
      "    except requests.exception.ConnectionError as e:\n",
      "AttributeError: 'module' object has no attribute 'exception'\n",
      "ERROR:root:An unknown error occurred! Returning tweets gathered so far.\n",
      "Traceback (most recent call last):\n",
      "  File \"C:\\ProgramData\\Anaconda2\\lib\\site-packages\\twitterscraper\\query.py\", line 93, in query_tweets_once\n",
      "    pos is None\n",
      "  File \"C:\\ProgramData\\Anaconda2\\lib\\site-packages\\twitterscraper\\query.py\", line 53, in query_single_page\n",
      "    except requests.exception.ConnectionError as e:\n",
      "AttributeError: 'module' object has no attribute 'exception'\n",
      "ERROR:root:An unknown error occurred! Returning tweets gathered so far.\n",
      "Traceback (most recent call last):\n",
      "  File \"C:\\ProgramData\\Anaconda2\\lib\\site-packages\\twitterscraper\\query.py\", line 93, in query_tweets_once\n",
      "    pos is None\n",
      "  File \"C:\\ProgramData\\Anaconda2\\lib\\site-packages\\twitterscraper\\query.py\", line 53, in query_single_page\n",
      "    except requests.exception.ConnectionError as e:\n",
      "AttributeError: 'module' object has no attribute 'exception'\n",
      "ERROR:root:An unknown error occurred! Returning tweets gathered so far.\n",
      "Traceback (most recent call last):\n",
      "  File \"C:\\ProgramData\\Anaconda2\\lib\\site-packages\\twitterscraper\\query.py\", line 93, in query_tweets_once\n",
      "    pos is None\n",
      "  File \"C:\\ProgramData\\Anaconda2\\lib\\site-packages\\twitterscraper\\query.py\", line 53, in query_single_page\n",
      "    except requests.exception.ConnectionError as e:\n",
      "AttributeError: 'module' object has no attribute 'exception'\n",
      "ERROR:root:An unknown error occurred! Returning tweets gathered so far.\n",
      "Traceback (most recent call last):\n",
      "  File \"C:\\ProgramData\\Anaconda2\\lib\\site-packages\\twitterscraper\\query.py\", line 93, in query_tweets_once\n",
      "    pos is None\n",
      "  File \"C:\\ProgramData\\Anaconda2\\lib\\site-packages\\twitterscraper\\query.py\", line 53, in query_single_page\n",
      "    except requests.exception.ConnectionError as e:\n",
      "AttributeError: 'module' object has no attribute 'exception'\n",
      "ERROR:root:An unknown error occurred! Returning tweets gathered so far.\n",
      "Traceback (most recent call last):\n",
      "  File \"C:\\ProgramData\\Anaconda2\\lib\\site-packages\\twitterscraper\\query.py\", line 93, in query_tweets_once\n",
      "    pos is None\n",
      "  File \"C:\\ProgramData\\Anaconda2\\lib\\site-packages\\twitterscraper\\query.py\", line 53, in query_single_page\n",
      "    except requests.exception.ConnectionError as e:\n",
      "AttributeError: 'module' object has no attribute 'exception'\n",
      "ERROR:root:An unknown error occurred! Returning tweets gathered so far.\n",
      "Traceback (most recent call last):\n",
      "  File \"C:\\ProgramData\\Anaconda2\\lib\\site-packages\\twitterscraper\\query.py\", line 93, in query_tweets_once\n",
      "    pos is None\n",
      "  File \"C:\\ProgramData\\Anaconda2\\lib\\site-packages\\twitterscraper\\query.py\", line 53, in query_single_page\n",
      "    except requests.exception.ConnectionError as e:\n",
      "AttributeError: 'module' object has no attribute 'exception'\n",
      "ERROR:root:An unknown error occurred! Returning tweets gathered so far.\n",
      "Traceback (most recent call last):\n",
      "  File \"C:\\ProgramData\\Anaconda2\\lib\\site-packages\\twitterscraper\\query.py\", line 93, in query_tweets_once\n",
      "    pos is None\n",
      "  File \"C:\\ProgramData\\Anaconda2\\lib\\site-packages\\twitterscraper\\query.py\", line 53, in query_single_page\n",
      "    except requests.exception.ConnectionError as e:\n",
      "AttributeError: 'module' object has no attribute 'exception'\n",
      "ERROR:root:An unknown error occurred! Returning tweets gathered so far.\n",
      "Traceback (most recent call last):\n",
      "  File \"C:\\ProgramData\\Anaconda2\\lib\\site-packages\\twitterscraper\\query.py\", line 93, in query_tweets_once\n",
      "    pos is None\n",
      "  File \"C:\\ProgramData\\Anaconda2\\lib\\site-packages\\twitterscraper\\query.py\", line 53, in query_single_page\n",
      "    except requests.exception.ConnectionError as e:\n",
      "AttributeError: 'module' object has no attribute 'exception'\n",
      "ERROR:root:An unknown error occurred! Returning tweets gathered so far.\n",
      "Traceback (most recent call last):\n",
      "  File \"C:\\ProgramData\\Anaconda2\\lib\\site-packages\\twitterscraper\\query.py\", line 93, in query_tweets_once\n",
      "    pos is None\n",
      "  File \"C:\\ProgramData\\Anaconda2\\lib\\site-packages\\twitterscraper\\query.py\", line 53, in query_single_page\n",
      "    except requests.exception.ConnectionError as e:\n",
      "AttributeError: 'module' object has no attribute 'exception'\n",
      "ERROR:root:An unknown error occurred! Returning tweets gathered so far.\n",
      "Traceback (most recent call last):\n",
      "  File \"C:\\ProgramData\\Anaconda2\\lib\\site-packages\\twitterscraper\\query.py\", line 93, in query_tweets_once\n",
      "    pos is None\n",
      "  File \"C:\\ProgramData\\Anaconda2\\lib\\site-packages\\twitterscraper\\query.py\", line 53, in query_single_page\n",
      "    except requests.exception.ConnectionError as e:\n",
      "AttributeError: 'module' object has no attribute 'exception'\n",
      "ERROR:root:An unknown error occurred! Returning tweets gathered so far.\n",
      "Traceback (most recent call last):\n",
      "  File \"C:\\ProgramData\\Anaconda2\\lib\\site-packages\\twitterscraper\\query.py\", line 93, in query_tweets_once\n",
      "    pos is None\n",
      "  File \"C:\\ProgramData\\Anaconda2\\lib\\site-packages\\twitterscraper\\query.py\", line 53, in query_single_page\n",
      "    except requests.exception.ConnectionError as e:\n",
      "AttributeError: 'module' object has no attribute 'exception'\n",
      "ERROR:root:An unknown error occurred! Returning tweets gathered so far.\n",
      "Traceback (most recent call last):\n",
      "  File \"C:\\ProgramData\\Anaconda2\\lib\\site-packages\\twitterscraper\\query.py\", line 93, in query_tweets_once\n",
      "    pos is None\n",
      "  File \"C:\\ProgramData\\Anaconda2\\lib\\site-packages\\twitterscraper\\query.py\", line 53, in query_single_page\n",
      "    except requests.exception.ConnectionError as e:\n",
      "AttributeError: 'module' object has no attribute 'exception'\n",
      "ERROR:root:An unknown error occurred! Returning tweets gathered so far.\n",
      "Traceback (most recent call last):\n",
      "  File \"C:\\ProgramData\\Anaconda2\\lib\\site-packages\\twitterscraper\\query.py\", line 93, in query_tweets_once\n",
      "    pos is None\n",
      "  File \"C:\\ProgramData\\Anaconda2\\lib\\site-packages\\twitterscraper\\query.py\", line 53, in query_single_page\n",
      "    except requests.exception.ConnectionError as e:\n",
      "AttributeError: 'module' object has no attribute 'exception'\n",
      "ERROR:root:An unknown error occurred! Returning tweets gathered so far.\n",
      "Traceback (most recent call last):\n",
      "  File \"C:\\ProgramData\\Anaconda2\\lib\\site-packages\\twitterscraper\\query.py\", line 93, in query_tweets_once\n",
      "    pos is None\n",
      "  File \"C:\\ProgramData\\Anaconda2\\lib\\site-packages\\twitterscraper\\query.py\", line 53, in query_single_page\n",
      "    except requests.exception.ConnectionError as e:\n",
      "AttributeError: 'module' object has no attribute 'exception'\n",
      "ERROR:root:An unknown error occurred! Returning tweets gathered so far.\n",
      "Traceback (most recent call last):\n",
      "  File \"C:\\ProgramData\\Anaconda2\\lib\\site-packages\\twitterscraper\\query.py\", line 93, in query_tweets_once\n",
      "    pos is None\n",
      "  File \"C:\\ProgramData\\Anaconda2\\lib\\site-packages\\twitterscraper\\query.py\", line 53, in query_single_page\n",
      "    except requests.exception.ConnectionError as e:\n",
      "AttributeError: 'module' object has no attribute 'exception'\n",
      "ERROR:root:An unknown error occurred! Returning tweets gathered so far.\n",
      "Traceback (most recent call last):\n",
      "  File \"C:\\ProgramData\\Anaconda2\\lib\\site-packages\\twitterscraper\\query.py\", line 93, in query_tweets_once\n",
      "    pos is None\n",
      "  File \"C:\\ProgramData\\Anaconda2\\lib\\site-packages\\twitterscraper\\query.py\", line 53, in query_single_page\n",
      "    except requests.exception.ConnectionError as e:\n",
      "AttributeError: 'module' object has no attribute 'exception'\n",
      "ERROR:root:An unknown error occurred! Returning tweets gathered so far.\n",
      "Traceback (most recent call last):\n",
      "  File \"C:\\ProgramData\\Anaconda2\\lib\\site-packages\\twitterscraper\\query.py\", line 93, in query_tweets_once\n",
      "    pos is None\n",
      "  File \"C:\\ProgramData\\Anaconda2\\lib\\site-packages\\twitterscraper\\query.py\", line 53, in query_single_page\n",
      "    except requests.exception.ConnectionError as e:\n",
      "AttributeError: 'module' object has no attribute 'exception'\n",
      "ERROR:root:An unknown error occurred! Returning tweets gathered so far.\n",
      "Traceback (most recent call last):\n",
      "  File \"C:\\ProgramData\\Anaconda2\\lib\\site-packages\\twitterscraper\\query.py\", line 93, in query_tweets_once\n",
      "    pos is None\n",
      "  File \"C:\\ProgramData\\Anaconda2\\lib\\site-packages\\twitterscraper\\query.py\", line 53, in query_single_page\n",
      "    except requests.exception.ConnectionError as e:\n",
      "AttributeError: 'module' object has no attribute 'exception'\n",
      "ERROR:root:An unknown error occurred! Returning tweets gathered so far.\n",
      "Traceback (most recent call last):\n",
      "  File \"C:\\ProgramData\\Anaconda2\\lib\\site-packages\\twitterscraper\\query.py\", line 93, in query_tweets_once\n",
      "    pos is None\n",
      "  File \"C:\\ProgramData\\Anaconda2\\lib\\site-packages\\twitterscraper\\query.py\", line 53, in query_single_page\n",
      "    except requests.exception.ConnectionError as e:\n",
      "AttributeError: 'module' object has no attribute 'exception'\n",
      "ERROR:root:An unknown error occurred! Returning tweets gathered so far.\n",
      "Traceback (most recent call last):\n",
      "  File \"C:\\ProgramData\\Anaconda2\\lib\\site-packages\\twitterscraper\\query.py\", line 93, in query_tweets_once\n",
      "    pos is None\n",
      "  File \"C:\\ProgramData\\Anaconda2\\lib\\site-packages\\twitterscraper\\query.py\", line 53, in query_single_page\n",
      "    except requests.exception.ConnectionError as e:\n",
      "AttributeError: 'module' object has no attribute 'exception'\n",
      "ERROR:root:An unknown error occurred! Returning tweets gathered so far.\n",
      "Traceback (most recent call last):\n",
      "  File \"C:\\ProgramData\\Anaconda2\\lib\\site-packages\\twitterscraper\\query.py\", line 93, in query_tweets_once\n",
      "    pos is None\n",
      "  File \"C:\\ProgramData\\Anaconda2\\lib\\site-packages\\twitterscraper\\query.py\", line 53, in query_single_page\n",
      "    except requests.exception.ConnectionError as e:\n",
      "AttributeError: 'module' object has no attribute 'exception'\n",
      "ERROR:root:An unknown error occurred! Returning tweets gathered so far.\n",
      "Traceback (most recent call last):\n",
      "  File \"C:\\ProgramData\\Anaconda2\\lib\\site-packages\\twitterscraper\\query.py\", line 93, in query_tweets_once\n",
      "    pos is None\n",
      "  File \"C:\\ProgramData\\Anaconda2\\lib\\site-packages\\twitterscraper\\query.py\", line 53, in query_single_page\n",
      "    except requests.exception.ConnectionError as e:\n",
      "AttributeError: 'module' object has no attribute 'exception'\n",
      "ERROR:root:An unknown error occurred! Returning tweets gathered so far.\n",
      "Traceback (most recent call last):\n",
      "  File \"C:\\ProgramData\\Anaconda2\\lib\\site-packages\\twitterscraper\\query.py\", line 93, in query_tweets_once\n",
      "    pos is None\n",
      "  File \"C:\\ProgramData\\Anaconda2\\lib\\site-packages\\twitterscraper\\query.py\", line 53, in query_single_page\n",
      "    except requests.exception.ConnectionError as e:\n",
      "AttributeError: 'module' object has no attribute 'exception'\n",
      "ERROR:root:An unknown error occurred! Returning tweets gathered so far.\n",
      "Traceback (most recent call last):\n",
      "  File \"C:\\ProgramData\\Anaconda2\\lib\\site-packages\\twitterscraper\\query.py\", line 93, in query_tweets_once\n",
      "    pos is None\n",
      "  File \"C:\\ProgramData\\Anaconda2\\lib\\site-packages\\twitterscraper\\query.py\", line 53, in query_single_page\n",
      "    except requests.exception.ConnectionError as e:\n",
      "AttributeError: 'module' object has no attribute 'exception'\n",
      "ERROR:root:An unknown error occurred! Returning tweets gathered so far.\n",
      "Traceback (most recent call last):\n",
      "  File \"C:\\ProgramData\\Anaconda2\\lib\\site-packages\\twitterscraper\\query.py\", line 93, in query_tweets_once\n",
      "    pos is None\n",
      "  File \"C:\\ProgramData\\Anaconda2\\lib\\site-packages\\twitterscraper\\query.py\", line 53, in query_single_page\n",
      "    except requests.exception.ConnectionError as e:\n",
      "AttributeError: 'module' object has no attribute 'exception'\n",
      "ERROR:root:An unknown error occurred! Returning tweets gathered so far.\n",
      "Traceback (most recent call last):\n",
      "  File \"C:\\ProgramData\\Anaconda2\\lib\\site-packages\\twitterscraper\\query.py\", line 93, in query_tweets_once\n",
      "    pos is None\n",
      "  File \"C:\\ProgramData\\Anaconda2\\lib\\site-packages\\twitterscraper\\query.py\", line 53, in query_single_page\n",
      "    except requests.exception.ConnectionError as e:\n",
      "AttributeError: 'module' object has no attribute 'exception'\n",
      "ERROR:root:An unknown error occurred! Returning tweets gathered so far.\n",
      "Traceback (most recent call last):\n",
      "  File \"C:\\ProgramData\\Anaconda2\\lib\\site-packages\\twitterscraper\\query.py\", line 93, in query_tweets_once\n",
      "    pos is None\n",
      "  File \"C:\\ProgramData\\Anaconda2\\lib\\site-packages\\twitterscraper\\query.py\", line 53, in query_single_page\n",
      "    except requests.exception.ConnectionError as e:\n",
      "AttributeError: 'module' object has no attribute 'exception'\n",
      "ERROR:root:An unknown error occurred! Returning tweets gathered so far.\n",
      "Traceback (most recent call last):\n",
      "  File \"C:\\ProgramData\\Anaconda2\\lib\\site-packages\\twitterscraper\\query.py\", line 93, in query_tweets_once\n",
      "    pos is None\n",
      "  File \"C:\\ProgramData\\Anaconda2\\lib\\site-packages\\twitterscraper\\query.py\", line 53, in query_single_page\n",
      "    except requests.exception.ConnectionError as e:\n",
      "AttributeError: 'module' object has no attribute 'exception'\n",
      "ERROR:root:An unknown error occurred! Returning tweets gathered so far.\n",
      "Traceback (most recent call last):\n",
      "  File \"C:\\ProgramData\\Anaconda2\\lib\\site-packages\\twitterscraper\\query.py\", line 93, in query_tweets_once\n",
      "    pos is None\n",
      "  File \"C:\\ProgramData\\Anaconda2\\lib\\site-packages\\twitterscraper\\query.py\", line 53, in query_single_page\n",
      "    except requests.exception.ConnectionError as e:\n",
      "AttributeError: 'module' object has no attribute 'exception'\n",
      "ERROR:root:An unknown error occurred! Returning tweets gathered so far.\n",
      "Traceback (most recent call last):\n",
      "  File \"C:\\ProgramData\\Anaconda2\\lib\\site-packages\\twitterscraper\\query.py\", line 93, in query_tweets_once\n",
      "    pos is None\n",
      "  File \"C:\\ProgramData\\Anaconda2\\lib\\site-packages\\twitterscraper\\query.py\", line 53, in query_single_page\n",
      "    except requests.exception.ConnectionError as e:\n",
      "AttributeError: 'module' object has no attribute 'exception'\n",
      "ERROR:root:An unknown error occurred! Returning tweets gathered so far.\n",
      "Traceback (most recent call last):\n",
      "  File \"C:\\ProgramData\\Anaconda2\\lib\\site-packages\\twitterscraper\\query.py\", line 93, in query_tweets_once\n",
      "    pos is None\n",
      "  File \"C:\\ProgramData\\Anaconda2\\lib\\site-packages\\twitterscraper\\query.py\", line 53, in query_single_page\n",
      "    except requests.exception.ConnectionError as e:\n",
      "AttributeError: 'module' object has no attribute 'exception'\n",
      "ERROR:root:An unknown error occurred! Returning tweets gathered so far.\n",
      "Traceback (most recent call last):\n",
      "  File \"C:\\ProgramData\\Anaconda2\\lib\\site-packages\\twitterscraper\\query.py\", line 93, in query_tweets_once\n",
      "    pos is None\n",
      "  File \"C:\\ProgramData\\Anaconda2\\lib\\site-packages\\twitterscraper\\query.py\", line 53, in query_single_page\n",
      "    except requests.exception.ConnectionError as e:\n",
      "AttributeError: 'module' object has no attribute 'exception'\n",
      "ERROR:root:An unknown error occurred! Returning tweets gathered so far.\n",
      "Traceback (most recent call last):\n",
      "  File \"C:\\ProgramData\\Anaconda2\\lib\\site-packages\\twitterscraper\\query.py\", line 93, in query_tweets_once\n",
      "    pos is None\n",
      "  File \"C:\\ProgramData\\Anaconda2\\lib\\site-packages\\twitterscraper\\query.py\", line 53, in query_single_page\n",
      "    except requests.exception.ConnectionError as e:\n",
      "AttributeError: 'module' object has no attribute 'exception'\n",
      "ERROR:root:An unknown error occurred! Returning tweets gathered so far.\n",
      "Traceback (most recent call last):\n",
      "  File \"C:\\ProgramData\\Anaconda2\\lib\\site-packages\\twitterscraper\\query.py\", line 93, in query_tweets_once\n",
      "    pos is None\n",
      "  File \"C:\\ProgramData\\Anaconda2\\lib\\site-packages\\twitterscraper\\query.py\", line 53, in query_single_page\n",
      "    except requests.exception.ConnectionError as e:\n",
      "AttributeError: 'module' object has no attribute 'exception'\n",
      "ERROR:root:An unknown error occurred! Returning tweets gathered so far.\n",
      "Traceback (most recent call last):\n",
      "  File \"C:\\ProgramData\\Anaconda2\\lib\\site-packages\\twitterscraper\\query.py\", line 93, in query_tweets_once\n",
      "    pos is None\n",
      "  File \"C:\\ProgramData\\Anaconda2\\lib\\site-packages\\twitterscraper\\query.py\", line 53, in query_single_page\n",
      "    except requests.exception.ConnectionError as e:\n",
      "AttributeError: 'module' object has no attribute 'exception'\n",
      "ERROR:root:An unknown error occurred! Returning tweets gathered so far.\n",
      "Traceback (most recent call last):\n",
      "  File \"C:\\ProgramData\\Anaconda2\\lib\\site-packages\\twitterscraper\\query.py\", line 93, in query_tweets_once\n",
      "    pos is None\n",
      "  File \"C:\\ProgramData\\Anaconda2\\lib\\site-packages\\twitterscraper\\query.py\", line 53, in query_single_page\n",
      "    except requests.exception.ConnectionError as e:\n",
      "AttributeError: 'module' object has no attribute 'exception'\n",
      "ERROR:root:An unknown error occurred! Returning tweets gathered so far.\n",
      "Traceback (most recent call last):\n",
      "  File \"C:\\ProgramData\\Anaconda2\\lib\\site-packages\\twitterscraper\\query.py\", line 93, in query_tweets_once\n",
      "    pos is None\n",
      "  File \"C:\\ProgramData\\Anaconda2\\lib\\site-packages\\twitterscraper\\query.py\", line 53, in query_single_page\n",
      "    except requests.exception.ConnectionError as e:\n",
      "AttributeError: 'module' object has no attribute 'exception'\n",
      "ERROR:root:An unknown error occurred! Returning tweets gathered so far.\n",
      "Traceback (most recent call last):\n",
      "  File \"C:\\ProgramData\\Anaconda2\\lib\\site-packages\\twitterscraper\\query.py\", line 93, in query_tweets_once\n",
      "    pos is None\n",
      "  File \"C:\\ProgramData\\Anaconda2\\lib\\site-packages\\twitterscraper\\query.py\", line 53, in query_single_page\n",
      "    except requests.exception.ConnectionError as e:\n",
      "AttributeError: 'module' object has no attribute 'exception'\n",
      "ERROR:root:An unknown error occurred! Returning tweets gathered so far.\n",
      "Traceback (most recent call last):\n",
      "  File \"C:\\ProgramData\\Anaconda2\\lib\\site-packages\\twitterscraper\\query.py\", line 93, in query_tweets_once\n",
      "    pos is None\n",
      "  File \"C:\\ProgramData\\Anaconda2\\lib\\site-packages\\twitterscraper\\query.py\", line 53, in query_single_page\n",
      "    except requests.exception.ConnectionError as e:\n",
      "AttributeError: 'module' object has no attribute 'exception'\n",
      "ERROR:root:An unknown error occurred! Returning tweets gathered so far.\n",
      "Traceback (most recent call last):\n",
      "  File \"C:\\ProgramData\\Anaconda2\\lib\\site-packages\\twitterscraper\\query.py\", line 93, in query_tweets_once\n",
      "    pos is None\n",
      "  File \"C:\\ProgramData\\Anaconda2\\lib\\site-packages\\twitterscraper\\query.py\", line 53, in query_single_page\n",
      "    except requests.exception.ConnectionError as e:\n",
      "AttributeError: 'module' object has no attribute 'exception'\n",
      "ERROR:root:An unknown error occurred! Returning tweets gathered so far.\n",
      "Traceback (most recent call last):\n",
      "  File \"C:\\ProgramData\\Anaconda2\\lib\\site-packages\\twitterscraper\\query.py\", line 93, in query_tweets_once\n",
      "    pos is None\n",
      "  File \"C:\\ProgramData\\Anaconda2\\lib\\site-packages\\twitterscraper\\query.py\", line 53, in query_single_page\n",
      "    except requests.exception.ConnectionError as e:\n",
      "AttributeError: 'module' object has no attribute 'exception'\n",
      "ERROR:root:An unknown error occurred! Returning tweets gathered so far.\n",
      "Traceback (most recent call last):\n",
      "  File \"C:\\ProgramData\\Anaconda2\\lib\\site-packages\\twitterscraper\\query.py\", line 93, in query_tweets_once\n",
      "    pos is None\n",
      "  File \"C:\\ProgramData\\Anaconda2\\lib\\site-packages\\twitterscraper\\query.py\", line 53, in query_single_page\n",
      "    except requests.exception.ConnectionError as e:\n",
      "AttributeError: 'module' object has no attribute 'exception'\n",
      "ERROR:root:An unknown error occurred! Returning tweets gathered so far.\n",
      "Traceback (most recent call last):\n",
      "  File \"C:\\ProgramData\\Anaconda2\\lib\\site-packages\\twitterscraper\\query.py\", line 93, in query_tweets_once\n",
      "    pos is None\n",
      "  File \"C:\\ProgramData\\Anaconda2\\lib\\site-packages\\twitterscraper\\query.py\", line 53, in query_single_page\n",
      "    except requests.exception.ConnectionError as e:\n",
      "AttributeError: 'module' object has no attribute 'exception'\n",
      "ERROR:root:An unknown error occurred! Returning tweets gathered so far.\n",
      "Traceback (most recent call last):\n",
      "  File \"C:\\ProgramData\\Anaconda2\\lib\\site-packages\\twitterscraper\\query.py\", line 93, in query_tweets_once\n",
      "    pos is None\n",
      "  File \"C:\\ProgramData\\Anaconda2\\lib\\site-packages\\twitterscraper\\query.py\", line 53, in query_single_page\n",
      "    except requests.exception.ConnectionError as e:\n",
      "AttributeError: 'module' object has no attribute 'exception'\n",
      "ERROR:root:An unknown error occurred! Returning tweets gathered so far.\n",
      "Traceback (most recent call last):\n",
      "  File \"C:\\ProgramData\\Anaconda2\\lib\\site-packages\\twitterscraper\\query.py\", line 93, in query_tweets_once\n",
      "    pos is None\n",
      "  File \"C:\\ProgramData\\Anaconda2\\lib\\site-packages\\twitterscraper\\query.py\", line 53, in query_single_page\n",
      "    except requests.exception.ConnectionError as e:\n",
      "AttributeError: 'module' object has no attribute 'exception'\n",
      "ERROR:root:An unknown error occurred! Returning tweets gathered so far.\n",
      "Traceback (most recent call last):\n",
      "  File \"C:\\ProgramData\\Anaconda2\\lib\\site-packages\\twitterscraper\\query.py\", line 93, in query_tweets_once\n",
      "    pos is None\n",
      "  File \"C:\\ProgramData\\Anaconda2\\lib\\site-packages\\twitterscraper\\query.py\", line 53, in query_single_page\n",
      "    except requests.exception.ConnectionError as e:\n",
      "AttributeError: 'module' object has no attribute 'exception'\n",
      "ERROR:root:An unknown error occurred! Returning tweets gathered so far.\n",
      "Traceback (most recent call last):\n",
      "  File \"C:\\ProgramData\\Anaconda2\\lib\\site-packages\\twitterscraper\\query.py\", line 93, in query_tweets_once\n",
      "    pos is None\n",
      "  File \"C:\\ProgramData\\Anaconda2\\lib\\site-packages\\twitterscraper\\query.py\", line 53, in query_single_page\n",
      "    except requests.exception.ConnectionError as e:\n",
      "AttributeError: 'module' object has no attribute 'exception'\n",
      "ERROR:root:An unknown error occurred! Returning tweets gathered so far.\n",
      "Traceback (most recent call last):\n",
      "  File \"C:\\ProgramData\\Anaconda2\\lib\\site-packages\\twitterscraper\\query.py\", line 93, in query_tweets_once\n",
      "    pos is None\n",
      "  File \"C:\\ProgramData\\Anaconda2\\lib\\site-packages\\twitterscraper\\query.py\", line 53, in query_single_page\n",
      "    except requests.exception.ConnectionError as e:\n",
      "AttributeError: 'module' object has no attribute 'exception'\n",
      "ERROR:root:An unknown error occurred! Returning tweets gathered so far.\n",
      "Traceback (most recent call last):\n",
      "  File \"C:\\ProgramData\\Anaconda2\\lib\\site-packages\\twitterscraper\\query.py\", line 93, in query_tweets_once\n",
      "    pos is None\n",
      "  File \"C:\\ProgramData\\Anaconda2\\lib\\site-packages\\twitterscraper\\query.py\", line 53, in query_single_page\n",
      "    except requests.exception.ConnectionError as e:\n",
      "AttributeError: 'module' object has no attribute 'exception'\n",
      "ERROR:root:An unknown error occurred! Returning tweets gathered so far.\n",
      "Traceback (most recent call last):\n",
      "  File \"C:\\ProgramData\\Anaconda2\\lib\\site-packages\\twitterscraper\\query.py\", line 93, in query_tweets_once\n",
      "    pos is None\n",
      "  File \"C:\\ProgramData\\Anaconda2\\lib\\site-packages\\twitterscraper\\query.py\", line 53, in query_single_page\n",
      "    except requests.exception.ConnectionError as e:\n",
      "AttributeError: 'module' object has no attribute 'exception'\n",
      "ERROR:root:An unknown error occurred! Returning tweets gathered so far.\n",
      "Traceback (most recent call last):\n",
      "  File \"C:\\ProgramData\\Anaconda2\\lib\\site-packages\\twitterscraper\\query.py\", line 93, in query_tweets_once\n",
      "    pos is None\n",
      "  File \"C:\\ProgramData\\Anaconda2\\lib\\site-packages\\twitterscraper\\query.py\", line 53, in query_single_page\n",
      "    except requests.exception.ConnectionError as e:\n",
      "AttributeError: 'module' object has no attribute 'exception'\n",
      "ERROR:root:An unknown error occurred! Returning tweets gathered so far.\n",
      "Traceback (most recent call last):\n",
      "  File \"C:\\ProgramData\\Anaconda2\\lib\\site-packages\\twitterscraper\\query.py\", line 93, in query_tweets_once\n",
      "    pos is None\n",
      "  File \"C:\\ProgramData\\Anaconda2\\lib\\site-packages\\twitterscraper\\query.py\", line 53, in query_single_page\n",
      "    except requests.exception.ConnectionError as e:\n",
      "AttributeError: 'module' object has no attribute 'exception'\n",
      "ERROR:root:An unknown error occurred! Returning tweets gathered so far.\n",
      "Traceback (most recent call last):\n",
      "  File \"C:\\ProgramData\\Anaconda2\\lib\\site-packages\\twitterscraper\\query.py\", line 93, in query_tweets_once\n",
      "    pos is None\n",
      "  File \"C:\\ProgramData\\Anaconda2\\lib\\site-packages\\twitterscraper\\query.py\", line 53, in query_single_page\n",
      "    except requests.exception.ConnectionError as e:\n",
      "AttributeError: 'module' object has no attribute 'exception'\n",
      "ERROR:root:An unknown error occurred! Returning tweets gathered so far.\n",
      "Traceback (most recent call last):\n",
      "  File \"C:\\ProgramData\\Anaconda2\\lib\\site-packages\\twitterscraper\\query.py\", line 93, in query_tweets_once\n",
      "    pos is None\n",
      "  File \"C:\\ProgramData\\Anaconda2\\lib\\site-packages\\twitterscraper\\query.py\", line 53, in query_single_page\n",
      "    except requests.exception.ConnectionError as e:\n",
      "AttributeError: 'module' object has no attribute 'exception'\n",
      "ERROR:root:An unknown error occurred! Returning tweets gathered so far.\n",
      "Traceback (most recent call last):\n",
      "  File \"C:\\ProgramData\\Anaconda2\\lib\\site-packages\\twitterscraper\\query.py\", line 93, in query_tweets_once\n",
      "    pos is None\n",
      "  File \"C:\\ProgramData\\Anaconda2\\lib\\site-packages\\twitterscraper\\query.py\", line 53, in query_single_page\n",
      "    except requests.exception.ConnectionError as e:\n",
      "AttributeError: 'module' object has no attribute 'exception'\n",
      "ERROR:root:An unknown error occurred! Returning tweets gathered so far.\n",
      "Traceback (most recent call last):\n",
      "  File \"C:\\ProgramData\\Anaconda2\\lib\\site-packages\\twitterscraper\\query.py\", line 93, in query_tweets_once\n",
      "    pos is None\n",
      "  File \"C:\\ProgramData\\Anaconda2\\lib\\site-packages\\twitterscraper\\query.py\", line 53, in query_single_page\n",
      "    except requests.exception.ConnectionError as e:\n",
      "AttributeError: 'module' object has no attribute 'exception'\n",
      "ERROR:root:An unknown error occurred! Returning tweets gathered so far.\n",
      "Traceback (most recent call last):\n",
      "  File \"C:\\ProgramData\\Anaconda2\\lib\\site-packages\\twitterscraper\\query.py\", line 93, in query_tweets_once\n",
      "    pos is None\n",
      "  File \"C:\\ProgramData\\Anaconda2\\lib\\site-packages\\twitterscraper\\query.py\", line 53, in query_single_page\n",
      "    except requests.exception.ConnectionError as e:\n",
      "AttributeError: 'module' object has no attribute 'exception'\n",
      "ERROR:root:An unknown error occurred! Returning tweets gathered so far.\n",
      "Traceback (most recent call last):\n",
      "  File \"C:\\ProgramData\\Anaconda2\\lib\\site-packages\\twitterscraper\\query.py\", line 93, in query_tweets_once\n",
      "    pos is None\n",
      "  File \"C:\\ProgramData\\Anaconda2\\lib\\site-packages\\twitterscraper\\query.py\", line 53, in query_single_page\n",
      "    except requests.exception.ConnectionError as e:\n",
      "AttributeError: 'module' object has no attribute 'exception'\n",
      "ERROR:root:An unknown error occurred! Returning tweets gathered so far.\n",
      "Traceback (most recent call last):\n",
      "  File \"C:\\ProgramData\\Anaconda2\\lib\\site-packages\\twitterscraper\\query.py\", line 93, in query_tweets_once\n",
      "    pos is None\n",
      "  File \"C:\\ProgramData\\Anaconda2\\lib\\site-packages\\twitterscraper\\query.py\", line 53, in query_single_page\n",
      "    except requests.exception.ConnectionError as e:\n",
      "AttributeError: 'module' object has no attribute 'exception'\n"
     ]
    }
   ],
   "source": [
    "from datetime import date, timedelta\n",
    "from twitterscraper import query_tweets\n",
    "\n",
    "start_date = date(2016, 4, 28)\n",
    "mid_date = date(2016, 4, 29)\n",
    "end_date = date(2017, 4, 18) # Change this incase it breaks\n",
    "\n",
    "delta = timedelta(days=1)\n",
    "\n",
    "while mid_date <= end_date:\n",
    "    since = start_date.strftime(\"%Y-%m-%d\")\n",
    "    until = mid_date.strftime(\"%Y-%m-%d\")\n",
    "    \n",
    "    i = 0\n",
    "    \n",
    "#     time_file = open('timestamp.txt', 'a')\n",
    "#     text_file = open('tweets.txt', 'a')\n",
    "\n",
    "#     print since\n",
    "#     print until\n",
    "    \n",
    "#     for tweet in query_tweets(\"%22i%20feel%22%20since%3A\"+since+\"%20until%3A\"+until):\n",
    "#         i += 1\n",
    "        \n",
    "#         print i\n",
    "        \n",
    "#         if i % 1000 == 0:\n",
    "#         print tweet.timestamp\n",
    "#         print tweet.text.encode('utf-8').strip().replace('\\n',' ').replace('\\t',' ')\n",
    "#             time_file.write('%s \\n' % tweet.timestamp)\n",
    "#             text_file.write('%s \\n' % tweet.text.encode('utf-8').strip().replace('\\n',' ').replace('\\t',' '))\n",
    "    \n",
    "#     time_file.close()\n",
    "#     text_file.close()\n",
    "\n",
    "    test_tweets = query_tweets(\"%22i%20feel%22%20since%3A\"+since+\"%20until%3A\"+until)\n",
    "    \n",
    "    time_file = open('timestamp.txt', 'a')\n",
    "    text_file = open('tweets.txt', 'a')\n",
    "    \n",
    "    for tweet in test_tweets:\n",
    "        i += 1\n",
    "        if i % 1000 == 0:\n",
    "            time_file.write('%s \\n' % tweet.timestamp)\n",
    "            text_file.write('%s \\n' % tweet.text.encode('utf-8').strip().replace('\\n',' ').replace('\\t',' '))\n",
    "    \n",
    "    start_date += delta\n",
    "    mid_date += delta\n",
    "    \n",
    "    time_file.close()\n",
    "    text_file.close()"
   ]
  }
 ],
 "metadata": {
  "kernelspec": {
   "display_name": "Python 2",
   "language": "python",
   "name": "python2"
  },
  "language_info": {
   "codemirror_mode": {
    "name": "ipython",
    "version": 2
   },
   "file_extension": ".py",
   "mimetype": "text/x-python",
   "name": "python",
   "nbconvert_exporter": "python",
   "pygments_lexer": "ipython2",
   "version": "2.7.13"
  }
 },
 "nbformat": 4,
 "nbformat_minor": 2
}
